Workbook

Sheet 0. Database
A1: Centralized Database (USD mm except EPS/shares) — Blue = input
A3: Ticker | B3: Metric | C3: 2013A | D3: 2014A | E3: 2015A | F3: 2016A | G3: 2017A | H3: 2018A | I3: 2019A | J3: 2020A | K3: 2021A | L3: 2022A | M3: 2023A | N3: 2024A | O3: 2025E | P3: 2026E | Q3: 2027E | R3: 2028E | S3: 2029E | T3: 2030E
A4: MSFT (FY(Jun))
A5: MSFT | B5: Revenue | C5: 77849 | D5: 86833 | E5: 93580 | F5: 85320 | G5: 96571 | H5: 110360 | I5: 125843 | J5: 143015 | K5: 168088 | L5: 198270 | M5: 211915 | N5: 245122 | O5: 281724 | P5: 329440.24 | Q5: 387103.71 | R5: 463474.17 | S5: 553714.52 | T5: 652772.62
A6: MSFT | B6: Operating Income | C6: 26764 | D6: 27759 | E6: 18161 | F6: 20182 | G6: 29025 | H6: 35058 | I6: 42959 | J6: 52959 | K6: 69916 | L6: 83383 | M6: 88523 | N6: 109433 | O6: 128528 | P6: 153454.1 | Q6: 179274.53 | R6: 217551.82 | S6: 266239.28 | T6: 318436.19
A7: MSFT | B7: Net Income | C7: 21863 | D7: 22074 | E7: 12193 | F7: 16798 | G7: 25489 | H7: 16571 | I7: 39240 | J7: 44281 | K7: 61271 | L7: 72738 | M7: 72361 | N7: 88136 | O7: 101832 | P7: 129372.86 | Q7: 144971.56 | R7: 175683.92 | S7: 215472.22 | T7: 258948.36
A8: MSFT | B8: EPS | C8: 2.63 | D8: 2.66 | E8: 2.59 | F8: 2.79 | G8: 3.29 | H8: 3.88 | I8: 4.75 | J8: 5.76 | K8: 7.97 | L8: 9.21 | M8: 9.81 | N8: 11.8 | O8: 13.91 | P8: 16.75 | Q8: 19.47 | R8: 23.61 | S8: 28.97 | T8: 34.82
A9: MSFT | B9: Diluted Shares (mm) | C9: 8452.25 | D9: 8385.25 | E9: 8254 | F9: 8012.25 | G9: 7831.25 | H9: 7792.25 | I9: 7752 | J9: 7681.5 | K9: 7607.75 | L9: 7540.5 | M9: 7472.25 | N9: 7468.5 | O9: 7467.75 | P9: 7453.97 | Q9: 7446.49 | R9: 7440.67 | S9: 7436.61 | T9: 7436.22
A10: MSFT | B10: SBC | C10: 2406 | D10: 2446 | E10: 2574 | F10: 2668 | G10: 3266 | H10: 3940 | I10: 4652 | J10: 5289 | K10: 6118 | L10: 7502 | M10: 9611 | N10: 10734 | O10: 11974 | P10: 12189 | Q10: 10478.4 | R10: 11434.24 | S10: 12826.56 | T10: 14871.62
A11: MSFT | B11: D&A | C11: 3339 | D11: 4245 | E11: 5400 | F11: 5878 | G11: 7800 | H11: 9900 | I11: 11600 | J11: 12300 | K11: 10900 | L11: 14600 | M11: 13500 | N11: 20000 | O11: 28000 | P11: 39638.96 | Q11: 62441.96 | R11: 94995.43 | S11: 131504.45 | T11: 167239.58
A12: MSFT | B12: Capex | C12: 4257 | D12: 5485 | E12: 5944 | F12: 8932 | G12: 10200 | H12: 13600 | I12: 16900 | J12: 19000 | K12: 24200 | L12: 29200 | M12: 31900 | N12: 55700 | O12: 88200 | P12: 145871.3 | Q12: 245263.45 | R12: 286760.35 | S12: 300210.91 | T12: 304616.04
A13: MSFT | B13: CFO | C13: 28833 | D13: 32231 | E13: 29080 | F13: 33325 | G13: 39507 | H13: 43884 | I13: 52185 | J13: 60675 | K13: 76740 | L13: 89035 | M13: 87582 | N13: 118548 | O13: 136162 | P13: 174558.18 | Q13: 232097.78 | R13: 294570.35 | S13: 359672.36 | T13: 438548.9
A14: MSFT | B14: FCF | C14: 24576 | D14: 26746 | E14: 23136 | F14: 24393 | G14: 29307 | H14: 30284 | I14: 35285 | J14: 41675 | K14: 52540 | L14: 59835 | M14: 55682 | N14: 62848 | O14: 47962 | P14: 28686.88 | Q14: -13165.67 | R14: 7810 | S14: 59461.45 | T14: 133932.86
A15: MSFT | B15: Buybacks | C15: 5360 | D15: 7316 | E15: 14443 | F15: 15969 | G15: 11788 | H15: 10721 | I15: 19543 | J15: 22968 | K15: 27385 | L15: 32696 | M15: 22245 | N15: 17254 | O15: 18420 | P15: 22499.7 | Q15: 19070.28 | R15: 19500.41 | S15: 20126.95 | T15: 21047.23
A16: MSFT | B16: Intell Cloud | C16: 0 | D16: 0 | E16: 0 | F16: 0 | G16: 0 | H16: 0 | I16: 0 | J16: 0 | K16: 0 | L16: 0 | M16: 72314 | N16: 87464 | O16: 106265 | P16: 136688.31 | Q16: 180358.14 | R16: 235873.55 | S16: 304531.45 | T16: 384276.13
... A18: MSFT | B18: Useful Life(yr) | C18: 3.16 | D18: 2.69 | E18: 2.81 | F18: 2.83 | G18: 2.71 | H18: 2.73 | I18: 2.74 | J18: 3.08 | K18: 4.33 | L18: 4.12 | M18: 6.1 | N18: 5.59 | O18: 5.26 | P18: 4.89 | Q18: 4.36 | R18: 4.38 | S18: 4.6 | T18: 4.7
A20: AMZN (CY)
A21: AMZN | B21: Revenue | C21: 74453 | D21: 88988.4 | E21: 107006.6 | F21: 135987 | G21: 177866 | H21: 232887 | I21: 280522 | J21: 386064 | K21: 469822 | L21: 513983 | M21: 574785 | N21: 637959 | O21: 716924 | P21: 827599.51 | Q21: 946630.91 | R21: 1063340.6 | S21: 1183117.7 | T21: 1305415.5
A22: AMZN | B22: Operating Income | C22: 745 | D22: 178.4 | E22: 2232.6 | F22: 4186 | G22: 4107 | H22: 12420 | I22: 14540 | J22: 22899 | K22: 24879 | L22: 12248 | M22: 36852 | N22: 68593 | O22: 79975 | P22: 109001.86 | Q22: 146127.4 | R22: 183469.22 | S22: 223208.87 | T22: 264582.39
A23: AMZN | B23: Net Income | C23: 273 | D23: -240.6 | E23: 596.1 | F23: 2371 | G23: 3033 | H23: 10073 | I23: 11588 | J23: 21331 | K23: 33364 | L23: -2722 | M23: 30425 | N23: 59248 | O23: 77670 | P23: 98333.72 | Q23: 116218.4 | R23: 145016.4 | S23: 177176.2 | T23: 211925.99
A24: AMZN | B24: EPS | C24: 0.03 | D24: -0.03 | E24: 0.06 | F24: 0.24 | G24: 0.31 | H24: 1.01 | I24: 1.15 | J24: 2.08 | K24: 3.25 | L24: -0.26 | M24: 2.88 | N24: 5.53 | O24: 7.17 | P24: 9.02 | Q24: 10.58 | R24: 13.11 | S24: 15.92 | T24: 18.92
A25: AMZN | B25: Diluted Shares (mm) | C25: 9340 | D25: 9440 | E25: 9620 | F25: 9720 | G25: 9910 | H25: 10020 | I25: 10100 | J25: 10254 | K25: 10274.5 | L25: 10296.5 | M25: 10568.69 | N25: 10721 | O25: 10827 | P25: 10907.55 | Q25: 10986.16 | R25: 11059.39 | S25: 11131.13 | T25: 11201.4
A26: AMZN | B26: SBC | C26: -1134 | D26: -1497 | E26: -2120 | F26: -2975 | G26: -4214 | H26: -5418 | I26: -6864 | J26: -9208 | K26: -12757 | L26: -19621 | M26: -24023 | N26: -22077.4 | O26: -19467 | P26: -18863.32 | Q26: -17920.15 | R26: -18816.16 | S26: -19756.97 | T26: -20744.82
A27: AMZN | B27: D&A | C27: 3253 | D27: 4745 | E27: 6281 | F27: 8117 | G27: 11478 | H27: 15341 | I27: 21789 | J27: 25251 | K27: 34296 | L27: 41461 | M27: 48663 | N27: 52795 | O27: 65756 | P27: 81175.82 | Q27: 90716.93 | R27: 120533.23 | S27: 150703.05 | T27: 175451.44
A28: AMZN | B28: Capex | C28: 3443 | D28: 4892 | E28: 4588 | F28: 6736 | G28: 10057 | H28: 11322 | I28: 12690 | J28: 35046 | K28: 55396 | L28: 58321 | M28: 48133 | N28: 77658 | O28: 128320 | P28: 200104.98 | Q28: 270141.72 | R28: 283648.81 | S28: 297831.25 | T28: 312722.81
A29: AMZN | B29: CFO | C29: 5474 | D29: 6841.4 | E29: 11920.1 | F29: 17271 | G29: 18434 | H29: 30724 | I29: 38515 | J29: 66064 | K29: 46327 | L29: 46752 | M29: 84946 | N29: 115877 | O29: 139514 | P29: 181004.31 | Q29: 224443.7 | R29: 281471.71 | S29: 342814.42 | T29: 401080.41
A30: AMZN | B30: FCF | C30: 2031 | D30: 1949.4 | E30: 7332.1 | F30: 10535 | G30: 8377 | H30: 19402 | I30: 25825 | J30: 31018 | K30: -9069 | L30: -11569 | M30: 36813 | N30: 38219 | O30: 11194 | P30: -19100.67 | Q30: -45698.02 | R30: -2177.1 | S30: 44983.17 | T30: 88357.6
A31: AMZN | B31: Buybacks | C31: 0 | D31: 0 | E31: 0 | F31: 0 | G31: 0 | H31: 0 | I31: 0 | J31: 0 | K31: 0 | L31: 6000 | M31: 0 | N31: 0 | O31: 0 | P31: 0 | Q31: 0 | R31: 0 | S31: 0 | T31: 0
A32: AMZN | B32: AWS Rev | C32: 3107.57 | D32: 4644 | E32: 7880 | F32: 12219 | G32: 17458 | H32: 25656 | I32: 35026 | J32: 45370 | K32: 62202 | L32: 80096 | M32: 90757 | N32: 107556 | O32: 128725 | P32: 171284.9 | Q32: 225587.94 | R32: 274421.67 | S32: 323817.58 | T32: 374009.3
A33: AMZN | B33: AWS OI | D33: 458 | E33: 1508 | F33: 3109 | G33: 4331 | H33: 7296 | I33: 9201 | J33: 13531 | K33: 18532 | L33: 22841 | M33: 24631 | N33: 39834 | O33: 45606 | P33: 61254.41 | Q33: 81248.3 | R33: 100888.47 | S33: 121477.03 | T33: 143111.04
A35: GOOGL (CY)
A36: GOOGL | B36: Revenue | C36: 55519 | D36: 66001 | E36: 74989 | F36: 90272 | G36: 110855 | H36: 136819 | I36: 161857 | J36: 182527 | K36: 257637 | L36: 282836 | M36: 307394 | N36: 350018 | O36: 402836 | P36: 488278.6 | Q36: 591935.74 | R36: 701414.49 | S36: 815276.88 | T36: 921874.95
A37: GOOGL | B37: Operating Income | C37: 15403 | D37: 16496 | E37: 19360 | F37: 23716 | G37: 26146 | H37: 26953 | I37: 34231 | J37: 41224 | K37: 78714 | L37: 74842 | M37: 84293 | N37: 112390 | O37: 129039 | P37: 167318.21 | Q37: 210287.33 | R37: 253779.42 | S37: 298519.7 | T37: 338347.07
A38: GOOGL | B38: Net Income | C38: 12720 | D38: 14136 | E38: 16348 | F38: 19478 | G38: 12662 | H38: 30736 | I38: 34343 | J38: 40269 | K38: 76033 | L38: 59972 | M38: 73795 | N38: 100118 | O38: 132170 | P38: 168543.28 | Q38: 174626.97 | R38: 210753.44 | S38: 249488.6 | T38: 285975.76
A39: GOOGL | B39: EPS | C39: 0.94 | D39: 1.03 | E39: 1.18 | F39: 1.39 | G39: 0.9 | H39: 2.19 | I39: 2.46 | J39: 2.93 | K39: 5.61 | L39: 4.56 | M39: 5.8 | N39: 8.04 | O39: 10.81 | P39: 13.73 | Q39: 14.16 | R39: 17.04 | S39: 20.12 | T39: 22.99
A40: GOOGL | B40: Diluted Shares (mm) | C40: 13552.38 | D40: 13741.41 | E40: 13858.6 | F40: 13974.09 | G40: 14071.67 | H40: 14065.69 | I40: 13971.13 | J40: 13740.56 | K40: 13553 | L40: 13159 | M40: 12722 | N40: 12447 | O40: 12230 | P40: 12275.96 | Q40: 12335.53 | R40: 12366.42 | S40: 12399.99 | T40: 12436.85
A41: GOOGL | B41: SBC | C41: -3268 | D41: -4175 | E41: -4903 | F41: -6703 | G41: -7679 | H41: -9353 | I41: -10794 | J41: -12991 | K41: -15376 | L41: -19362 | M41: -22460 | N41: -22785 | O41: -24953 | P41: -27937.33 | Q41: -30032.63 | R41: -31979.73 | S41: -33657.1 | T41: -35339.95
A42: GOOGL | B42: D&A | C42: 2781 | D42: 3523 | E42: 4132 | F42: 5267 | G42: 6103 | H42: 8164 | I42: 10856 | J42: 12905 | K42: 11555 | L42: 15287 | M42: 13326 | N42: 15311 | O42: 21136 | P42: 42874.7 | Q42: 69582.72 | R42: 98340.16 | S42: 127674.93 | T42: 156155.17
A43: GOOGL | B43: Capex | C43: 7358 | D43: 10959 | E43: 9915 | F43: 10183 | G43: 13184 | H43: 25139 | I43: 23548 | J43: 22281 | K43: 24640 | L43: 31485 | M43: 32251 | N43: 52535 | O43: 91447 | P43: 185234.28 | Q43: 259327.99 | R43: 285260.79 | S43: 299523.83 | T43: 314500.02
A44: GOOGL | B44: CFO | C44: 18584 | D44: 22272 | E44: 25829 | F44: 36036 | G44: 37091 | H44: 47971 | I44: 54520 | J44: 65124 | K44: 91652 | L44: 91495 | M44: 101746 | N44: 125299 | O44: 164713 | P44: 211985.47 | Q44: 282346.21 | R44: 352943.8 | S44: 424226.82 | T44: 490867.35
...

Sheet 1. Summary
B2: AI Capex Cycle: Hyperscaler Deep-Dive (2013-2030)
B3: MSFT | AMZN | GOOGL | META | ORCL + S&P 500 AI EPS Decomposition
B5: CONTENTS
B6: 0. Database — 2013-2030 centralized data. Blue=input. All other sheets reference this.
B7: 1. Summary — This page
B8: 2. Revenue — Total rev, YoY%, Cloud/AI proxy. Derived metrics reference SAME sheet cells (black font).
B9: 3. Capex & D&A — Capex, Capex/Rev, D&A, D&A/Rev. Local formulas reference raw data on same sheet.
B10: 4. FCF & Cash — CFO, FCF margin, FCF/NI, Capex/CFO. All ratios use same-sheet references.
B11: 5. EPS & Margins — OpMargin, Net Margin, EPSYoY. Same-sheet referencing pattern.
B12: 6. Burry Sensitivity — GPU life compression on 2026E EPS. Editable tax rate assumptions.
B13: 7. S&P 500 AI EPS Split — AI vs Non-AI EPS decomposition + dual P/E valuation + 4 stress scenarios.
B14: 8. Charts — 6 visualizations (Capex/Rev, Free Cash FlowMargin, Capex absolute, Rev YoY, OpMargin, D&A/Rev).

Sheet 2. Revenue & Growth
A1: Revenue&AI/CloudSegment Detail (2013-2030E)
A3: A. Total Revenue ($mm)
A4: Company | B4: 2013A | C4: 2014A | D4: 2015A | E4: 2016A | F4: 2017A | G4: 2018A | H4: 2019A | I4: 2020A | J4: 2021A | K4: 2022A | L4: 2023A | M4: 2024A | N4: 2025E | O4: 2026E | P4: 2027E | Q4: 2028E | R4: 2029E | S4: 2030E
A5: MSFT | B5: ='0. Database'!C5 | C5: ='0. Database'!D5 | D5: ='0. Database'!E5 | E5: ='0. Database'!F5 | F5: ='0. Database'!G5 | G5: ='0. Database'!H5 | H5: ='0. Database'!I5 | I5: ='0. Database'!J5 | ... S5: ='0. Database'!T5
A6: AMZN | B6: ='0. Database'!C21 | C6: ='0. Database'!D21 | D6: ='0. Database'!E21 | E6: ='0. Database'!F21 | F6: ='0. Database'!G21 | G6: ='0. Database'!H21 | H6: ='0. Database'!I21 | I6: ='0. Database'!J21 | ... S6: ='0. Database'!T21
A7: GOOGL | B7: ='0. Database'!C36 | C7: ='0. Database'!D36 | D7: ='0. Database'!E36 | E7: ='0. Database'!F36 | F7: ='0. Database'!G36 | G7: ='0. Database'!H36 | H7: ='0. Database'!I36 | I7: ='0. Database'!J36 | ... S7: ='0. Database'!T36
A8: META | B8: ='0. Database'!C53 | C8: ='0. Database'!D53 | D8: ='0. Database'!E53 | E8: ='0. Database'!F53 | F8: ='0. Database'!G53 | G8: ='0. Database'!H53 | H8: ='0. Database'!I53 | I8: ='0. Database'!J53 | ... S8: ='0. Database'!T53
A9: ORCL | B9: ='0. Database'!C71 | C9: ='0. Database'!D71 | D9: ='0. Database'!E71 | E9: ='0. Database'!F71 | F9: ='0. Database'!G71 | G9: ='0. Database'!H71 | H9: ='0. Database'!I71 | I9: ='0. Database'!J71 | ... S9: ='0. Database'!T71
A11: C. Cloud / AI Proxy Revenue ($mm)
A12: Company | B12: 2013A | C12: 2014A | D12: 2015A | E12: 2016A | F12: 2017A | G12: 2018A | H12: 2019A | I12: 2020A | J12: 2021A | K12: 2022A | L12: 2023A | M12: 2024A | N12: 2025E | O12: 2026E | P12: 2027E | Q12: 2028E | R12: 2029E | S12: 2030E
A13: MSFT — Azure
A14: AMZN — AWS | B14: ='0. Database'!C32 | C14: ='0. Database'!D32 | D14: ='0. Database'!E32 | E14: ='0. Database'!F32 | F14: ='0. Database'!G32 | G14: ='0. Database'!H32 | H14: ='0. Database'!I32 | I14: ='0. Database'!J32 | ... S14: ='0. Database'!T32
A15: GOOGL — Cloud | B15: ='0. Database'!C47 | C15: ='0. Database'!D47 | D15: ='0. Database'!E47 | E15: ='0. Database'!F47 | F15: ='0. Database'!G47 | G15: ='0. Database'!H47 | H15: ='0. Database'!I47 | I15: ='0. Database'!J47 | ... S15: ='0. Database'!T47
A16: META — Advertising | B16: ='0. Database'!C64 | C16: ='0. Database'!D64 | D16: ='0. Database'!E64 | E16: ='0. Database'!F64 | F16: ='0. Database'!G64 | G16: ='0. Database'!H64 | H16: ='0. Database'!I64 | I16: ='0. Database'!J64 | ... S16: ='0. Database'!T64
A17: ORCL — CloudTotalRevenue | B17: ='0. Database'!C82 | C17: ='0. Database'!D82 | D17: ='0. Database'!E82 | E17: ='0. Database'!F82 | F17: ='0. Database'!G82 | G17: ='0. Database'!H82 | H17: ='0. Database'!I82 | I17: ='0. Database'!J82 | ... S17: ='0. Database'!T82
A19: B. Revenue YoY %
A20: Company | B20: 2013A | C20: 2014A | D20: 2015A | E20: 2016A | F20: 2017A | G20: 2018A | H20: 2019A | I20: 2020A | J20: 2021A | K20: 2022A | L20: 2023A | M20: 2024A | N20: 2025E | O20: 2026E | P20: 2027E | Q20: 2028E | R20: 2029E | S20: 2030E
A21: MSFT | C21: =IFERROR(C5/B5-1,"") | D21: =IFERROR(D5/C5-1,"") | E21: =IFERROR(E5/D5-1,"") | F21: =IFERROR(F5/E5-1,"") | G21: =IFERROR(G5/F5-1,"") | H21: =IFERROR(H5/G5-1,"") | I21: =IFERROR(I5/H5-1,"") | J21: =IFERROR(J5/I5-1,"") | ... S21: =IFERROR(S5/R5-1,"")
A22: AMZN | C22: =IFERROR(C6/B6-1,"") | D22: =IFERROR(D6/C6-1,"") | E22: =IFERROR(E6/D6-1,"") | F22: =IFERROR(F6/E6-1,"") | G22: =IFERROR(G6/F6-1,"") | H22: =IFERROR(H6/G6-1,"") | I22: =IFERROR(I6/H6-1,"") | J22: =IFERROR(J6/I6-1,"") | ... S22: =IFERROR(S6/R6-1,"")
A23: GOOGL | C23: =IFERROR(C7/B7-1,"") | D23: =IFERROR(D7/C7-1,"") | E23: =IFERROR(E7/D7-1,"") | F23: =IFERROR(F7/E7-1,"") | G23: =IFERROR(G7/F7-1,"") | H23: =IFERROR(H7/G7-1,"") | I23: =IFERROR(I7/H7-1,"") | J23: =IFERROR(J7/I7-1,"") | ... S23: =IFERROR(S7/R7-1,"")
A24: META | C24: =IFERROR(C8/B8-1,"") | D24: =IFERROR(D8/C8-1,"") | E24: =IFERROR(E8/D8-1,"") | F24: =IFERROR(F8/E8-1,"") | G24: =IFERROR(G8/F8-1,"") | H24: =IFERROR(H8/G8-1,"") | I24: =IFERROR(I8/H8-1,"") | J24: =IFERROR(J8/I8-1,"") | ... S24: =IFERROR(S8/R8-1,"")
A25: ORCL | C25: =IFERROR(C9/B9-1,"") | D25: =IFERROR(D9/C9-1,"") | E25: =IFERROR(E9/D9-1,"") | F25: =IFERROR(F9/E9-1,"") | G25: =IFERROR(G9/F9-1,"") | H25: =IFERROR(H9/G9-1,"") | I25: =IFERROR(I9/H9-1,"") | J25: =IFERROR(J9/I9-1,"") | ... S25: =IFERROR(S9/R9-1,"")

Sheet 3. Capex & D&A
A1: Capex&D&A (2013-2030E)
A3: A. Capex ($mm)
A4: Company | B4: 2013A | C4: 2014A | D4: 2015A | E4: 2016A | F4: 2017A | G4: 2018A | H4: 2019A | I4: 2020A | J4: 2021A | K4: 2022A | L4: 2023A | M4: 2024A | N4: 2025E | O4: 2026E | P4: 2027E | Q4: 2028E | R4: 2029E | S4: 2030E
A5: MSFT | B5: ='0. Database'!C12 | C5: ='0. Database'!D12 | D5: ='0. Database'!E12 | E5: ='0. Database'!F12 | F5: ='0. Database'!G12 | G5: ='0. Database'!H12 | H5: ='0. Database'!I12 | I5: ='0. Database'!J12 | ... S5: ='0. Database'!T12
A6: AMZN | B6: ='0. Database'!C28 | C6: ='0. Database'!D28 | D6: ='0. Database'!E28 | E6: ='0. Database'!F28 | F6: ='0. Database'!G28 | G6: ='0. Database'!H28 | H6: ='0. Database'!I28 | I6: ='0. Database'!J28 | ... S6: ='0. Database'!T28
A7: GOOGL | B7: ='0. Database'!C43 | C7: ='0. Database'!D43 | D7: ='0. Database'!E43 | E7: ='0. Database'!F43 | F7: ='0. Database'!G43 | G7: ='0. Database'!H43 | H7: ='0. Database'!I43 | I7: ='0. Database'!J43 | ... S7: ='0. Database'!T43
A8: META | B8: ='0. Database'!C60 | C8: ='0. Database'!D60 | D8: ='0. Database'!E60 | E8: ='0. Database'!F60 | F8: ='0. Database'!G60 | G8: ='0. Database'!H60 | H8: ='0. Database'!I60 | I8: ='0. Database'!J60 | ... S8: ='0. Database'!T60
A9: ORCL | B9: ='0. Database'!C78 | C9: ='0. Database'!D78 | D9: ='0. Database'!E78 | E9: ='0. Database'!F78 | F9: ='0. Database'!G78 | G9: ='0. Database'!H78 | H9: ='0. Database'!I78 | I9: ='0. Database'!J78 | ... S9: ='0. Database'!T78
A11: D. D&A ($mm)
A12: Company | B12: 2013A | C12: 2014A | D12: 2015A | E12: 2016A | F12: 2017A | G12: 2018A | H12: 2019A | I12: 2020A | J12: 2021A | K12: 2022A | L12: 2023A | M12: 2024A | N12: 2025E | O12: 2026E | P12: 2027E | Q12: 2028E | R12: 2029E | S12: 2030E
A13: MSFT | B13: ='0. Database'!C11 | C13: ='0. Database'!D11 | D13: ='0. Database'!E11 | E13: ='0. Database'!F11 | F13: ='0. Database'!G11 | G13: ='0. Database'!H11 | H13: ='0. Database'!I11 | I13: ='0. Database'!J11 | ... S13: ='0. Database'!T11
A14: AMZN | B14: ='0. Database'!C27 | C14: ='0. Database'!D27 | D14: ='0. Database'!E27 | E14: ='0. Database'!F27 | F14: ='0. Database'!G27 | G14: ='0. Database'!H27 | H14: ='0. Database'!I27 | I14: ='0. Database'!J27 | ... S14: ='0. Database'!T27
A15: GOOGL | B15: ='0. Database'!C42 | C15: ='0. Database'!D42 | D15: ='0. Database'!E42 | E15: ='0. Database'!F42 | F15: ='0. Database'!G42 | G15: ='0. Database'!H42 | H15: ='0. Database'!I42 | I15: ='0. Database'!J42 | ... S15: ='0. Database'!T42
A16: META | B16: ='0. Database'!C59 | C16: ='0. Database'!D59 | D16: ='0. Database'!E59 | E16: ='0. Database'!F59 | F16: ='0. Database'!G59 | G16: ='0. Database'!H59 | H16: ='0. Database'!I59 | I16: ='0. Database'!J59 | ... S16: ='0. Database'!T59
A17: ORCL | B17: ='0. Database'!C77 | C17: ='0. Database'!D77 | D17: ='0. Database'!E77 | E17: ='0. Database'!F77 | F17: ='0. Database'!G77 | G17: ='0. Database'!H77 | H17: ='0. Database'!I77 | I17: ='0. Database'!J77 | ... S17: ='0. Database'!T77
A19: (Revenue — for ratios)
A20: Company | B20: 2013A | C20: 2014A | D20: 2015A | E20: 2016A | F20: 2017A | G20: 2018A | H20: 2019A | I20: 2020A | J20: 2021A | K20: 2022A | L20: 2023A | M20: 2024A | N20: 2025E | O20: 2026E | P20: 2027E | Q20: 2028E | R20: 2029E | S20: 2030E
A21: MSFT | B21: ='0. Database'!C5 | C21: ='0. Database'!D5 | D21: ='0. Database'!E5 | E21: ='0. Database'!F5 | F21: ='0. Database'!G5 | G21: ='0. Database'!H5 | H21: ='0. Database'!I5 | I21: ='0. Database'!J5 | ... S21: ='0. Database'!T5
A22: AMZN | B22: ='0. Database'!C21 | C22: ='0. Database'!D21 | D22: ='0. Database'!E21 | E22: ='0. Database'!F21 | F22: ='0. Database'!G21 | G22: ='0. Database'!H21 | H22: ='0. Database'!I21 | I22: ='0. Database'!J21 | ... S22: ='0. Database'!T21
A23: GOOGL | B23: ='0. Database'!C36 | C23: ='0. Database'!D36 | D23: ='0. Database'!E36 | E23: ='0. Database'!F36 | F23: ='0. Database'!G36 | G23: ='0. Database'!H36 | H23: ='0. Database'!I36 | I23: ='0. Database'!J36 | ... S23: ='0. Database'!T36
A24: META | B24: ='0. Database'!C53 | C24: ='0. Database'!D53 | D24: ='0. Database'!E53 | E24: ='0. Database'!F53 | F24: ='0. Database'!G53 | G24: ='0. Database'!H53 | H24: ='0. Database'!I53 | I24: ='0. Database'!J53 | ... S24: ='0. Database'!T53
A25: ORCL | B25: ='0. Database'!C71 | C25: ='0. Database'!D71 | D25: ='0. Database'!E71 | E25: ='0. Database'!F71 | F25: ='0. Database'!G71 | G25: ='0. Database'!H71 | H25: ='0. Database'!I71 | I25: ='0. Database'!J71 | ... S25: ='0. Database'!T71
A27: B. CapexYoY %
A28: Company | B28: 2013A | C28: 2014A | D28: 2015A | E28: 2016A | F28: 2017A | G28: 2018A | H28: 2019A | I28: 2020A | J28: 2021A | K28: 2022A | L28: 2023A | M28: 2024A | N28: 2025E | O28: 2026E | P28: 2027E | Q28: 2028E | R28: 2029E | S28: 2030E
A29: MSFT | C29: =IFERROR(C5/B5-1,"") | D29: =IFERROR(D5/C5-1,"") | E29: =IFERROR(E5/D5-1,"") | F29: =IFERROR(F5/E5-1,"") | G29: =IFERROR(G5/F5-1,"") | H29: =IFERROR(H5/G5-1,"") | I29: =IFERROR(I5/H5-1,"") | J29: =IFERROR(J5/I5-1,"") | ... S29: =IFERROR(S5/R5-1,"")
A30: AMZN | C30: =IFERROR(C6/B6-1,"") | D30: =IFERROR(D6/C6-1,"") | E30: =IFERROR(E6/D6-1,"") | F30: =IFERROR(F6/E6-1,"") | G30: =IFERROR(G6/F6-1,"") | H30: =IFERROR(H6/G6-1,"") | I30: =IFERROR(I6/H6-1,"") | J30: =IFERROR(J6/I6-1,"") | ... S30: =IFERROR(S6/R6-1,"")
A31: GOOGL | C31: =IFERROR(C7/B7-1,"") | D31: =IFERROR(D7/C7-1,"") | E31: =IFERROR(E7/D7-1,"") | F31: =IFERROR(F7/E7-1,"") | G31: =IFERROR(G7/F7-1,"") | H31: =IFERROR(H7/G7-1,"") | I31: =IFERROR(I7/H7-1,"") | J31: =IFERROR(J7/I7-1,"") | ... S31: =IFERROR(S7/R7-1,"")
A32: META | C32: =IFERROR(C8/B8-1,"") | D32: =IFERROR(D8/C8-1,"") | E32: =IFERROR(E8/D8-1,"") | F32: =IFERROR(F8/E8-1,"") | G32: =IFERROR(G8/F8-1,"") | H32: =IFERROR(H8/G8-1,"") | I32: =IFERROR(I8/H8-1,"") | J32: =IFERROR(J8/I8-1,"") | ... S32: =IFERROR(S8/R8-1,"")
A33: ORCL | C33: =IFERROR(C9/B9-1,"") | D33: =IFERROR(D9/C9-1,"") | E33: =IFERROR(E9/D9-1,"") | F33: =IFERROR(F9/E9-1,"") | G33: =IFERROR(G9/F9-1,"") | H33: =IFERROR(H9/G9-1,"") | I33: =IFERROR(I9/H9-1,"") | J33: =IFERROR(J9/I9-1,"") | ... S33: =IFERROR(S9/R9-1,"")
A35: C. Capex / Revenue %
A36: Company | B36: 2013A | C36: 2014A | D36: 2015A | E36: 2016A | F36: 2017A | G36: 2018A | H36: 2019A | I36: 2020A | J36: 2021A | K36: 2022A | L36: 2023A | M36: 2024A | N36: 2025E | O36: 2026E | P36: 2027E | Q36: 2028E | R36: 2029E | S36: 2030E
A37: MSFT | B37: =IFERROR(B5/B21,"") | C37: =IFERROR(C5/C21,"") | D37: =IFERROR(D5/D21,"") | E37: =IFERROR(E5/E21,"") | F37: =IFERROR(F5/F21,"") | G37: =IFERROR(G5/G21,"") | H37: =IFERROR(H5/H21,"") | I37: =IFERROR(I5/I21,"") | ... S37: =IFERROR(S5/S21,"")
A38: AMZN | B38: =IFERROR(B6/B22,"") | C38: =IFERROR(C6/C22,"") | D38: =IFERROR(D6/D22,"") | E38: =IFERROR(E6/E22,"") | F38: =IFERROR(F6/F22,"") | G38: =IFERROR(G6/G22,"") | H38: =IFERROR(H6/H22,"") | I38: =IFERROR(I6/I22,"") | ... S38: =IFERROR(S6/S22,"")
A39: GOOGL | B39: =IFERROR(B7/B23,"") | C39: =IFERROR(C7/C23,"") | D39: =IFERROR(D7/D23,"") | E39: =IFERROR(E7/E23,"") | F39: =IFERROR(F7/F23,"") | G39: =IFERROR(G7/G23,"") | H39: =IFERROR(H7/H23,"") | I39: =IFERROR(I7/I23,"") | ... S39: =IFERROR(S7/S23,"")
A40: META | B40: =IFERROR(B8/B24,"") | C40: =IFERROR(C8/C24,"") | D40: =IFERROR(D8/D24,"") | E40: =IFERROR(E8/E24,"") | F40: =IFERROR(F8/F24,"") | G40: =IFERROR(G8/G24,"") | H40: =IFERROR(H8/H24,"") | I40: =IFERROR(I8/I24,"") | ... S40: =IFERROR(S8/S24,"")
A41: ORCL | B41: =IFERROR(B9/B25,"") | C41: =IFERROR(C9/C25,"") | D41: =IFERROR(D9/D25,"") | E41: =IFERROR(E9/E25,"") | F41: =IFERROR(F9/F25,"") | G41: =IFERROR(G9/G25,"") | H41: =IFERROR(H9/H25,"") | I41: =IFERROR(I9/I25,"") | ... S41: =IFERROR(S9/S25,"")
A43: E. D&A / Revenue %
A44: Company | B44: 2013A | C44: 2014A | D44: 2015A | E44: 2016A | F44: 2017A | G44: 2018A | H44: 2019A | I44: 2020A | J44: 2021A | K44: 2022A | L44: 2023A | M44: 2024A | N44: 2025E | O44: 2026E | P44: 2027E | Q44: 2028E | R44: 2029E | S44: 2030E
A45: MSFT | B45: =IFERROR(B13/B21,"") | C45: =IFERROR(C13/C21,"") | D45: =IFERROR(D13/D21,"") | E45: =IFERROR(E13/E21,"") | F45: =IFERROR(F13/F21,"") | G45: =IFERROR(G13/G21,"") | H45: =IFERROR(H13/H21,"") | I45: =IFERROR(I13/I21,"") | ... S45: =IFERROR(S13/S21,"")
A46: AMZN | B46: =IFERROR(B14/B22,"") | C46: =IFERROR(C14/C22,"") | D46: =IFERROR(D14/D22,"") | E46: =IFERROR(E14/E22,"") | F46: =IFERROR(F14/F22,"") | G46: =IFERROR(G14/G22,"") | H46: =IFERROR(H14/H22,"") | I46: =IFERROR(I14/I22,"") | ... S46: =IFERROR(S14/S22,"")
...

Sheet 4. FCF & Cash
A1: Free Cash Flow&Cash Quality (2013-2030E)
A3: A. CFO ($mm)
A4: Company | B4: 2013A | C4: 2014A | D4: 2015A | E4: 2016A | F4: 2017A | G4: 2018A | H4: 2019A | I4: 2020A | J4: 2021A | K4: 2022A | L4: 2023A | M4: 2024A | N4: 2025E | O4: 2026E | P4: 2027E | Q4: 2028E | R4: 2029E | S4: 2030E
A5: MSFT | B5: ='0. Database'!C13 | C5: ='0. Database'!D13 | D5: ='0. Database'!E13 | E5: ='0. Database'!F13 | F5: ='0. Database'!G13 | G5: ='0. Database'!H13 | H5: ='0. Database'!I13 | I5: ='0. Database'!J13 | ... S5: ='0. Database'!T13
A6: AMZN | B6: ='0. Database'!C29 | C6: ='0. Database'!D29 | D6: ='0. Database'!E29 | E6: ='0. Database'!F29 | F6: ='0. Database'!G29 | G6: ='0. Database'!H29 | H6: ='0. Database'!I29 | I6: ='0. Database'!J29 | ... S6: ='0. Database'!T29
A7: GOOGL | B7: ='0. Database'!C44 | C7: ='0. Database'!D44 | D7: ='0. Database'!E44 | E7: ='0. Database'!F44 | F7: ='0. Database'!G44 | G7: ='0. Database'!H44 | H7: ='0. Database'!I44 | I7: ='0. Database'!J44 | ... S7: ='0. Database'!T44
A8: META | B8: ='0. Database'!C61 | C8: ='0. Database'!D61 | D8: ='0. Database'!E61 | E8: ='0. Database'!F61 | F8: ='0. Database'!G61 | G8: ='0. Database'!H61 | H8: ='0. Database'!I61 | I8: ='0. Database'!J61 | ... S8: ='0. Database'!T61
A9: ORCL | B9: ='0. Database'!C79 | C9: ='0. Database'!D79 | D9: ='0. Database'!E79 | E9: ='0. Database'!F79 | F9: ='0. Database'!G79 | G9: ='0. Database'!H79 | H9: ='0. Database'!I79 | I9: ='0. Database'!J79 | ... S9: ='0. Database'!T79
A11: B. FCF ($mm)
A12: Company | B12: 2013A | C12: 2014A | D12: 2015A | E12: 2016A | F12: 2017A | G12: 2018A | H12: 2019A | I12: 2020A | J12: 2021A | K12: 2022A | L12: 2023A | M12: 2024A | N12: 2025E | O12: 2026E | P12: 2027E | Q12: 2028E | R12: 2029E | S12: 2030E
A13: MSFT | B13: ='0. Database'!C14 | C13: ='0. Database'!D14 | D13: ='0. Database'!E14 | E13: ='0. Database'!F14 | F13: ='0. Database'!G14 | G13: ='0. Database'!H14 | H13: ='0. Database'!I14 | I13: ='0. Database'!J14 | ... S13: ='0. Database'!T14
A14: AMZN | B14: ='0. Database'!C30 | C14: ='0. Database'!D30 | D14: ='0. Database'!E30 | E14: ='0. Database'!F30 | F14: ='0. Database'!G30 | G14: ='0. Database'!H30 | H14: ='0. Database'!I30 | I14: ='0. Database'!J30 | ... S14: ='0. Database'!T30
A15: GOOGL | B15: ='0. Database'!C45 | C15: ='0. Database'!D45 | D15: ='0. Database'!E45 | E15: ='0. Database'!F45 | F15: ='0. Database'!G45 | G15: ='0. Database'!H45 | H15: ='0. Database'!I45 | I15: ='0. Database'!J45 | ... S15: ='0. Database'!T45
A16: META | B16: ='0. Database'!C62 | C16: ='0. Database'!D62 | D16: ='0. Database'!E62 | E16: ='0. Database'!F62 | F16: ='0. Database'!G62 | G16: ='0. Database'!H62 | H16: ='0. Database'!I62 | I16: ='0. Database'!J62 | ... S16: ='0. Database'!T62
A17: ORCL | B17: ='0. Database'!C80 | C17: ='0. Database'!D80 | D17: ='0. Database'!E80 | E17: ='0. Database'!F80 | F17: ='0. Database'!G80 | G17: ='0. Database'!H80 | H17: ='0. Database'!I80 | I17: ='0. Database'!J80 | ... S17: ='0. Database'!T80
A19: E. Buybacks ($mm)
A20: Company | B20: 2013A | C20: 2014A | D20: 2015A | E20: 2016A | F20: 2017A | G20: 2018A | H20: 2019A | I20: 2020A | J20: 2021A | K20: 2022A | L20: 2023A | M20: 2024A | N20: 2025E | O20: 2026E | P20: 2027E | Q20: 2028E | R20: 2029E | S20: 2030E
A21: MSFT | B21: ='0. Database'!C15 | C21: ='0. Database'!D15 | D21: ='0. Database'!E15 | E21: ='0. Database'!F15 | F21: ='0. Database'!G15 | G21: ='0. Database'!H15 | H21: ='0. Database'!I15 | I21: ='0. Database'!J15 | ... S21: ='0. Database'!T15
A22: AMZN | B22: ='0. Database'!C31 | C22: ='0. Database'!D31 | D22: ='0. Database'!E31 | E22: ='0. Database'!F31 | F22: ='0. Database'!G31 | G22: ='0. Database'!H31 | H22: ='0. Database'!I31 | I22: ='0. Database'!J31 | ... S22: ='0. Database'!T31
A23: GOOGL | B23: ='0. Database'!C46 | C23: ='0. Database'!D46 | D23: ='0. Database'!E46 | E23: ='0. Database'!F46 | F23: ='0. Database'!G46 | G23: ='0. Database'!H46 | H23: ='0. Database'!I46 | I23: ='0. Database'!J46 | ... S23: ='0. Database'!T46
A24: META | B24: ='0. Database'!C63 | C24: ='0. Database'!D63 | D24: ='0. Database'!E63 | E24: ='0. Database'!F63 | F24: ='0. Database'!G63 | G24: ='0. Database'!H63 | H24: ='0. Database'!I63 | I24: ='0. Database'!J63 | ... S24: ='0. Database'!T63
A25: ORCL | B25: ='0. Database'!C81 | C25: ='0. Database'!D81 | D25: ='0. Database'!E81 | E25: ='0. Database'!F81 | F25: ='0. Database'!G81 | G25: ='0. Database'!H81 | H25: ='0. Database'!I81 | I25: ='0. Database'!J81 | ... S25: ='0. Database'!T81
A27: (Revenue)
A28: Company | B28: 2013A | C28: 2014A | D28: 2015A | E28: 2016A | F28: 2017A | G28: 2018A | H28: 2019A | I28: 2020A | J28: 2021A | K28: 2022A | L28: 2023A | M28: 2024A | N28: 2025E | O28: 2026E | P28: 2027E | Q28: 2028E | R28: 2029E | S28: 2030E
A29: MSFT | B29: ='0. Database'!C5 | C29: ='0. Database'!D5 | D29: ='0. Database'!E5 | E29: ='0. Database'!F5 | F29: ='0. Database'!G5 | G29: ='0. Database'!H5 | H29: ='0. Database'!I5 | I29: ='0. Database'!J5 | ... S29: ='0. Database'!T5
A30: AMZN | B30: ='0. Database'!C21 | C30: ='0. Database'!D21 | D30: ='0. Database'!E21 | E30: ='0. Database'!F21 | F30: ='0. Database'!G21 | G30: ='0. Database'!H21 | H30: ='0. Database'!I21 | I30: ='0. Database'!J21 | ... S30: ='0. Database'!T21
A31: GOOGL | B31: ='0. Database'!C36 | C31: ='0. Database'!D36 | D31: ='0. Database'!E36 | E31: ='0. Database'!F36 | F31: ='0. Database'!G36 | G31: ='0. Database'!H36 | H31: ='0. Database'!I36 | I31: ='0. Database'!J36 | ... S31: ='0. Database'!T36
A32: META | B32: ='0. Database'!C53 | C32: ='0. Database'!D53 | D32: ='0. Database'!E53 | E32: ='0. Database'!F53 | F32: ='0. Database'!G53 | G32: ='0. Database'!H53 | H32: ='0. Database'!I53 | I32: ='0. Database'!J53 | ... S32: ='0. Database'!T53
A33: ORCL | B33: ='0. Database'!C71 | C33: ='0. Database'!D71 | D33: ='0. Database'!E71 | E33: ='0. Database'!F71 | F33: ='0. Database'!G71 | G33: ='0. Database'!H71 | H33: ='0. Database'!I71 | I33: ='0. Database'!J71 | ... S33: ='0. Database'!T71
A35: (NI)
A36: Company | B36: 2013A | C36: 2014A | D36: 2015A | E36: 2016A | F36: 2017A | G36: 2018A | H36: 2019A | I36: 2020A | J36: 2021A | K36: 2022A | L36: 2023A | M36: 2024A | N36: 2025E | O36: 2026E | P36: 2027E | Q36: 2028E | R36: 2029E | S36: 2030E
A37: MSFT | B37: ='0. Database'!C7 | C37: ='0. Database'!D7 | D37: ='0. Database'!E7 | E37: ='0. Database'!F7 | F37: ='0. Database'!G7 | G37: ='0. Database'!H7 | H37: ='0. Database'!I7 | I37: ='0. Database'!J7 | ... S37: ='0. Database'!T7
A38: AMZN | B38: ='0. Database'!C23 | C38: ='0. Database'!D23 | D38: ='0. Database'!E23 | E38: ='0. Database'!F23 | F38: ='0. Database'!G23 | G38: ='0. Database'!H23 | H38: ='0. Database'!I23 | I38: ='0. Database'!J23 | ... S38: ='0. Database'!T23
A39: GOOGL | B39: ='0. Database'!C38 | C39: ='0. Database'!D38 | D39: ='0. Database'!E38 | E39: ='0. Database'!F38 | F39: ='0. Database'!G38 | G39: ='0. Database'!H38 | H39: ='0. Database'!I38 | I39: ='0. Database'!J38 | ... S39: ='0. Database'!T38
A40: META | B40: ='0. Database'!C55 | C40: ='0. Database'!D55 | D40: ='0. Database'!E55 | E40: ='0. Database'!F55 | F40: ='0. Database'!G55 | G40: ='0. Database'!H55 | H40: ='0. Database'!I55 | I40: ='0. Database'!J55 | ... S40: ='0. Database'!T55
A41: ORCL | B41: ='0. Database'!C73 | C41: ='0. Database'!D73 | D41: ='0. Database'!E73 | E41: ='0. Database'!F73 | F41: ='0. Database'!G73 | G41: ='0. Database'!H73 | H41: ='0. Database'!I73 | I41: ='0. Database'!J73 | ... S41: ='0. Database'!T73
A43: (Capex)
A44: Company | B44: 2013A | C44: 2014A | D44: 2015A | E44: 2016A | F44: 2017A | G44: 2018A | H44: 2019A | I44: 2020A | J44: 2021A | K44: 2022A | L44: 2023A | M44: 2024A | N44: 2025E | O44: 2026E | P44: 2027E | Q44: 2028E | R44: 2029E | S44: 2030E
A45: MSFT | B45: ='0. Database'!C12 | C45: ='0. Database'!D12 | D45: ='0. Database'!E12 | E45: ='0. Database'!F12 | F45: ='0. Database'!G12 | G45: ='0. Database'!H12 | H45: ='0. Database'!I12 | I45: ='0. Database'!J12 | ... S45: ='0. Database'!T12
A46: AMZN | B46: ='0. Database'!C28 | C46: ='0. Database'!D28 | D46: ='0. Database'!E28 | E46: ='0. Database'!F28 | F46: ='0. Database'!G28 | G46: ='0. Database'!H28 | H46: ='0. Database'!I28 | I46: ='0. Database'!J28 | ... S46: ='0. Database'!T28
...

Sheet 5. EPS & Margins
A1: EPS、Operating IncomeMargin&Profitability (2013-2030E)
A3: A. Operating Income ($mm)
A4: Company | B4: 2013A | C4: 2014A | D4: 2015A | E4: 2016A | F4: 2017A | G4: 2018A | H4: 2019A | I4: 2020A | J4: 2021A | K4: 2022A | L4: 2023A | M4: 2024A | N4: 2025E | O4: 2026E | P4: 2027E | Q4: 2028E | R4: 2029E | S4: 2030E
A5: MSFT | B5: ='0. Database'!C6 | C5: ='0. Database'!D6 | D5: ='0. Database'!E6 | E5: ='0. Database'!F6 | F5: ='0. Database'!G6 | G5: ='0. Database'!H6 | H5: ='0. Database'!I6 | I5: ='0. Database'!J6 | ... S5: ='0. Database'!T6
A6: AMZN | B6: ='0. Database'!C22 | C6: ='0. Database'!D22 | D6: ='0. Database'!E22 | E6: ='0. Database'!F22 | F6: ='0. Database'!G22 | G6: ='0. Database'!H22 | H6: ='0. Database'!I22 | I6: ='0. Database'!J22 | ... S6: ='0. Database'!T22
A7: GOOGL | B7: ='0. Database'!C37 | C7: ='0. Database'!D37 | D7: ='0. Database'!E37 | E7: ='0. Database'!F37 | F7: ='0. Database'!G37 | G7: ='0. Database'!H37 | H7: ='0. Database'!I37 | I7: ='0. Database'!J37 | ... S7: ='0. Database'!T37
A8: META | B8: ='0. Database'!C54 | C8: ='0. Database'!D54 | D8: ='0. Database'!E54 | E8: ='0. Database'!F54 | F8: ='0. Database'!G54 | G8: ='0. Database'!H54 | H8: ='0. Database'!I54 | I8: ='0. Database'!J54 | ... S8: ='0. Database'!T54
A9: ORCL | B9: ='0. Database'!C72 | C9: ='0. Database'!D72 | D9: ='0. Database'!E72 | E9: ='0. Database'!F72 | F9: ='0. Database'!G72 | G9: ='0. Database'!H72 | H9: ='0. Database'!I72 | I9: ='0. Database'!J72 | ... S9: ='0. Database'!T72
A11: C. Net Income ($mm)
A12: Company | B12: 2013A | C12: 2014A | D12: 2015A | E12: 2016A | F12: 2017A | G12: 2018A | H12: 2019A | I12: 2020A | J12: 2021A | K12: 2022A | L12: 2023A | M12: 2024A | N12: 2025E | O12: 2026E | P12: 2027E | Q12: 2028E | R12: 2029E | S12: 2030E
A13: MSFT | B13: ='0. Database'!C7 | C13: ='0. Database'!D7 | D13: ='0. Database'!E7 | E13: ='0. Database'!F7 | F13: ='0. Database'!G7 | G13: ='0. Database'!H7 | H13: ='0. Database'!I7 | I13: ='0. Database'!J7 | ... S13: ='0. Database'!T7
A14: AMZN | B14: ='0. Database'!C23 | C14: ='0. Database'!D23 | D14: ='0. Database'!E23 | E14: ='0. Database'!F23 | F14: ='0. Database'!G23 | G14: ='0. Database'!H23 | H14: ='0. Database'!I23 | I14: ='0. Database'!J23 | ... S14: ='0. Database'!T23
A15: GOOGL | B15: ='0. Database'!C38 | C15: ='0. Database'!D38 | D15: ='0. Database'!E38 | E15: ='0. Database'!F38 | F15: ='0. Database'!G38 | G15: ='0. Database'!H38 | H15: ='0. Database'!I38 | I15: ='0. Database'!J38 | ... S15: ='0. Database'!T38
A16: META | B16: ='0. Database'!C55 | C16: ='0. Database'!D55 | D16: ='0. Database'!E55 | E16: ='0. Database'!F55 | F16: ='0. Database'!G55 | G16: ='0. Database'!H55 | H16: ='0. Database'!I55 | I16: ='0. Database'!J55 | ... S16: ='0. Database'!T55
A17: ORCL | B17: ='0. Database'!C73 | C17: ='0. Database'!D73 | D17: ='0. Database'!E73 | E17: ='0. Database'!F73 | F17: ='0. Database'!G73 | G17: ='0. Database'!H73 | H17: ='0. Database'!I73 | I17: ='0. Database'!J73 | ... S17: ='0. Database'!T73
A19: E. EPS ($)
A20: Company | B20: 2013A | C20: 2014A | D20: 2015A | E20: 2016A | F20: 2017A | G20: 2018A | H20: 2019A | I20: 2020A | J20: 2021A | K20: 2022A | L20: 2023A | M20: 2024A | N20: 2025E | O20: 2026E | P20: 2027E | Q20: 2028E | R20: 2029E | S20: 2030E
A21: MSFT | B21: ='0. Database'!C8 | C21: ='0. Database'!D8 | D21: ='0. Database'!E8 | E21: ='0. Database'!F8 | F21: ='0. Database'!G8 | G21: ='0. Database'!H8 | H21: ='0. Database'!I8 | I21: ='0. Database'!J8 | ... S21: ='0. Database'!T8
A22: AMZN | B22: ='0. Database'!C24 | C22: ='0. Database'!D24 | D22: ='0. Database'!E24 | E22: ='0. Database'!F24 | F22: ='0. Database'!G24 | G22: ='0. Database'!H24 | H22: ='0. Database'!I24 | I22: ='0. Database'!J24 | ... S22: ='0. Database'!T24
A23: GOOGL | B23: ='0. Database'!C39 | C23: ='0. Database'!D39 | D23: ='0. Database'!E39 | E23: ='0. Database'!F39 | F23: ='0. Database'!G39 | G23: ='0. Database'!H39 | H23: ='0. Database'!I39 | I23: ='0. Database'!J39 | ... S23: ='0. Database'!T39
A24: META | B24: ='0. Database'!C56 | C24: ='0. Database'!D56 | D24: ='0. Database'!E56 | E24: ='0. Database'!F56 | F24: ='0. Database'!G56 | G24: ='0. Database'!H56 | H24: ='0. Database'!I56 | I24: ='0. Database'!J56 | ... S24: ='0. Database'!T56
A25: ORCL | B25: ='0. Database'!C74 | C25: ='0. Database'!D74 | D25: ='0. Database'!E74 | E25: ='0. Database'!F74 | F25: ='0. Database'!G74 | G25: ='0. Database'!H74 | H25: ='0. Database'!I74 | I25: ='0. Database'!J74 | ... S25: ='0. Database'!T74
A27: G. Diluted Shares (mm)
A28: Company | B28: 2013A | C28: 2014A | D28: 2015A | E28: 2016A | F28: 2017A | G28: 2018A | H28: 2019A | I28: 2020A | J28: 2021A | K28: 2022A | L28: 2023A | M28: 2024A | N28: 2025E | O28: 2026E | P28: 2027E | Q28: 2028E | R28: 2029E | S28: 2030E
A29: MSFT | B29: ='0. Database'!C9 | C29: ='0. Database'!D9 | D29: ='0. Database'!E9 | E29: ='0. Database'!F9 | F29: ='0. Database'!G9 | G29: ='0. Database'!H9 | H29: ='0. Database'!I9 | I29: ='0. Database'!J9 | ... S29: ='0. Database'!T9
A30: AMZN | B30: ='0. Database'!C25 | C30: ='0. Database'!D25 | D30: ='0. Database'!E25 | E30: ='0. Database'!F25 | F30: ='0. Database'!G25 | G30: ='0. Database'!H25 | H30: ='0. Database'!I25 | I30: ='0. Database'!J25 | ... S30: ='0. Database'!T25
A31: GOOGL | B31: ='0. Database'!C40 | C31: ='0. Database'!D40 | D31: ='0. Database'!E40 | E31: ='0. Database'!F40 | F31: ='0. Database'!G40 | G31: ='0. Database'!H40 | H31: ='0. Database'!I40 | I31: ='0. Database'!J40 | ... S31: ='0. Database'!T40
A32: META | B32: ='0. Database'!C57 | C32: ='0. Database'!D57 | D32: ='0. Database'!E57 | E32: ='0. Database'!F57 | F32: ='0. Database'!G57 | G32: ='0. Database'!H57 | H32: ='0. Database'!I57 | I32: ='0. Database'!J57 | ... S32: ='0. Database'!T57
A33: ORCL | B33: ='0. Database'!C75 | C33: ='0. Database'!D75 | D33: ='0. Database'!E75 | E33: ='0. Database'!F75 | F33: ='0. Database'!G75 | G33: ='0. Database'!H75 | H33: ='0. Database'!I75 | I33: ='0. Database'!J75 | ... S33: ='0. Database'!T75
A35: H. SBC ($mm)
A36: Company | B36: 2013A | C36: 2014A | D36: 2015A | E36: 2016A | F36: 2017A | G36: 2018A | H36: 2019A | I36: 2020A | J36: 2021A | K36: 2022A | L36: 2023A | M36: 2024A | N36: 2025E | O36: 2026E | P36: 2027E | Q36: 2028E | R36: 2029E | S36: 2030E
A37: MSFT | B37: ='0. Database'!C10 | C37: ='0. Database'!D10 | D37: ='0. Database'!E10 | E37: ='0. Database'!F10 | F37: ='0. Database'!G10 | G37: ='0. Database'!H10 | H37: ='0. Database'!I10 | I37: ='0. Database'!J10 | ... S37: ='0. Database'!T10
A38: AMZN | B38: ='0. Database'!C26 | C38: ='0. Database'!D26 | D38: ='0. Database'!E26 | E38: ='0. Database'!F26 | F38: ='0. Database'!G26 | G38: ='0. Database'!H26 | H38: ='0. Database'!I26 | I38: ='0. Database'!J26 | ... S38: ='0. Database'!T26
A39: GOOGL | B39: ='0. Database'!C41 | C39: ='0. Database'!D41 | D39: ='0. Database'!E41 | E39: ='0. Database'!F41 | F39: ='0. Database'!G41 | G39: ='0. Database'!H41 | H39: ='0. Database'!I41 | I39: ='0. Database'!J41 | ... S39: ='0. Database'!T41
A40: META | B40: ='0. Database'!C58 | C40: ='0. Database'!D58 | D40: ='0. Database'!E58 | E40: ='0. Database'!F58 | F40: ='0. Database'!G58 | G40: ='0. Database'!H58 | H40: ='0. Database'!I58 | I40: ='0. Database'!J58 | ... S40: ='0. Database'!T58
A41: ORCL | B41: ='0. Database'!C76 | C41: ='0. Database'!D76 | D41: ='0. Database'!E76 | E41: ='0. Database'!F76 | F41: ='0. Database'!G76 | G41: ='0. Database'!H76 | H41: ='0. Database'!I76 | I41: ='0. Database'!J76 | ... S41: ='0. Database'!T76
A43: (Revenue)
A44: Company | B44: 2013A | C44: 2014A | D44: 2015A | E44: 2016A | F44: 2017A | G44: 2018A | H44: 2019A | I44: 2020A | J44: 2021A | K44: 2022A | L44: 2023A | M44: 2024A | N44: 2025E | O44: 2026E | P44: 2027E | Q44: 2028E | R44: 2029E | S44: 2030E
A45: MSFT | B45: ='0. Database'!C5 | C45: ='0. Database'!D5 | D45: ='0. Database'!E5 | E45: ='0. Database'!F5 | F45: ='0. Database'!G5 | G45: ='0. Database'!H5 | H45: ='0. Database'!I5 | I45: ='0. Database'!J5 | ... S45: ='0. Database'!T5
A46: AMZN | B46: ='0. Database'!C21 | C46: ='0. Database'!D21 | D46: ='0. Database'!E21 | E46: ='0. Database'!F21 | F46: ='0. Database'!G21 | G46: ='0. Database'!H21 | H46: ='0. Database'!I21 | I46: ='0. Database'!J21 | ... S46: ='0. Database'!T21
...

Sheet 6. Depreciation Sensitivity
A1: D&AAnalysis: Based on MSFT Actual PP&E Breakdown's Proxy
A3: A. MSFT Actual PP&E/Capex Breakdown (Source: 's Capex sheet — ✅ Hard Data)
A4: MSFT Capex Sheet actual PP&E analysis. Company-level asset breakdown.
A5: Metric (MSFT FY) | B5: FY2020A | C5: FY2021A | D5: FY2022A | E5: FY2023A | F5: FY2024A | G5: FY2025A | H5: FY2026E | I5: FY2027E | J5: FY2028E | K5: FY2029E | L5: FY2030E
A6: IT Equipment Capex ($mm) | B6: 7438 | C6: 9989 | D6: 9381 | E6: 14330 | F6: 18819 | G6: 41432 | H6: 85947 | I6: 144612 | J6: 166321 | K6: 174122 | L6: 176677
A7: Buildings Capex ($mm) | B7: 4377 | C7: 6197 | D7: 7805 | E7: 10301 | F7: 13768 | G7: 36747 | H7: 50201 | I7: 83886 | J7: 100380 | K7: 105090 | L7: 106632
A8: Finance Leases Capex ($mm) | B8: 3330 | C8: 3736 | D8: 3281 | E8: 3150 | F8: 11710 | G8: 21628 | H8: 32878 | I8: 42085 | J8: 37876 | K8: 30301 | L8: 21211
A9: Capex ($mm) | B9: 396 | C9: 2380 | D9: 2525 | E9: 2053 | F9: 3823 | G9: 10020 | H9: 9745 | I9: 16765 | J9: 20059 | K9: 20999 | L9: 21308
A10: Total Capex ($mm) | B10: 19000 | C10: 24200 | D10: 29200 | E10: 31900 | F10: 55700 | G10: 88200 | H10: 145871 | I10: 245263 | J10: 286760 | K10: 300211 | L10: 304616
A11: IT Equipment % of Capex | B11: 0.39 | C11: 0.41 | D11: 0.32 | E11: 0.45 | F11: 0.34 | G11: 0.47 | H11: 0.59 | I11: 0.59 | J11: 0.58 | K11: 0.58 | L11: 0.58
A12: IT Equipment D&A ($mm) | E12: 2231 | F12: 10063 | G12: 14563 | H12: 23911 | I12: 43743 | J12: 68286 | K12: 94877 | L12: 121252
A13: Buildings D&A ($mm) | E13: 680 | F13: 3304 | G13: 5132 | H13: 8149 | I13: 12605 | J13: 18775 | K13: 25426 | L13: 32434
A14: Total D&A ($mm) | B14: 10700 | C14: 9300 | D14: 12600 | E14: 11000 | F14: 15200 | G14: 22000 | H14: 34839 | I14: 59542 | J14: 92995 | K14: 129654 | L14: 165840
A15: IT D&A % of TotalD&A | E15: 0.2 | F15: 0.66 | G15: 0.66 | H15: 0.69 | I15: 0.73 | J15: 0.73 | K15: 0.73 | L15: 0.73
A16: IT EquipmentUseful Life | B16: 6 | C16: 6 | D16: 6 | E16: 6 | F16: 6 | G16: 6 | H16: 6 | I16: 6 | J16: 6 | K16: 6 | L16: 6
A17: BuildingsUseful Life | B17: 15 | C17: 15 | D17: 15 | E17: 15 | F17: 15 | G17: 15 | H17: 15 | I17: 15 | J17: 15 | K17: 15 | L17: 15
A19: 📌 Key Finding: IT Equipment pre-AI 's ~35% jumped to AI 's 59%. IT contributes 66-73% 'sTotalD&A (because IT 6Year vs Buildings 15Year). This is Burry thesis attack surface.
A21: B. IT EquipmentShare ofEstimation: MSFT Hard Data → 4 Proxy (⚠️ Estimate (directionally correct but unverifiable))
A22: Company | B22: IT EquipmentShare of Capex | C22: Estimation Basis (Confidence) | D22: IT Equipment Useful Life | E22: Buildings+ Share ofCapex% | F22: Buildings Useful Life | G22: (/)% | H22: Useful Life
A23: MSFT | B23: 0.59 | C23: ✅ Hard Data: Capex sheet Row 90 = 50.1% gross PP&E; capex share 59% | D23: 6 | E23: 0.36 | F23: 15 | G23: 0.05 | H23: 10
A24: AMZN | B24: 0.42 | C24: ⚠️ : 10-K Equipment $185B //; AWS ~40-45% (Behind the Balance SheetAnalysis) | D24: 5 | E24: 0.35 | F24: 18 | G24: 0.23 | H24: 8
A25: GOOGL | B25: 0.57 | C25: ⚠️ : MBI Deep Dives IT assets ~45% of PP&E; capex share (TPUIT) | D25: 6 | E25: 0.35 | F25: 20 | G25: 0.08 | H25: 10
A26: META | B26: 0.62 | C26: ⚠️ : Company, /; 1.3M GPU; server+networkPP&E (MBI) | D26: 5.5 | E26: 0.33 | F26: 22 | G26: 0.05 | H26: 10
A27: ORCL | B27: 0.5 | C27: ⚠️ : OCI, buildings; But+GPU; ITShare of | D27: 5.5 | E27: 0.4 | F27: 20 | G27: 0.1 | H27: 10
A30: C. 2026E / 2027E Base Data (From Database Sheet)
A31: Company | B31: 2026E Capex ($mm) | C31: 2026E D&A ($mm) | D31: 2026E NI ($mm) | E31: 2026E EPS ($) | F31: Shares (mm) | G31: Tax Rate (Editable) | H31: Depr Base = Capex×wtd life | I31: 2027E Capex ($mm) | J31: 2027E D&A ($mm) | K31: 2027E NI ($mm) | L31: 2027E EPS ($) | M31: 2027E Shares (mm) | N31: 2027E Base = D&A×wtdLife
A32: MSFT | B32: ='0. Database'!P12 | C32: ='0. Database'!P11 | D32: ='0. Database'!P7 | E32: ='0. Database'!P8 | F32: ='0. Database'!P9 | G32: 0.18 | H32: =$C$32*($B$23*$D$23+$E$23*$F$23+$G$23*$H$23) | I32: ='0. Database'!Q12 | J32: ='0. Database'!Q11 | K32: ='0. Database'!Q7 | L32: ='0. Database'!Q8
A33: AMZN | B33: ='0. Database'!P28 | C33: ='0. Database'!P27 | D33: ='0. Database'!P23 | E33: ='0. Database'!P24 | F33: ='0. Database'!P25 | G33: 0.2 | H33: =$C$33*($B$24*$D$24+$E$24*$F$24+$G$24*$H$24) | I33: ='0. Database'!Q28 | J33: ='0. Database'!Q27 | K33: ='0. Database'!Q23 | L33: ='0. Database'!Q24
A34: GOOGL | B34: ='0. Database'!P43 | C34: ='0. Database'!P42 | D34: ='0. Database'!P38 | E34: ='0. Database'!P39 | F34: ='0. Database'!P40 | G34: 0.16 | H34: =$C$34*($B$25*$D$25+$E$25*$F$25+$G$25*$H$25) | I34: ='0. Database'!Q43 | J34: ='0. Database'!Q42 | K34: ='0. Database'!Q38 | L34: ='0. Database'!Q39
A35: META | B35: ='0. Database'!P60 | C35: ='0. Database'!P59 | D35: ='0. Database'!P55 | E35: ='0. Database'!P56 | F35: ='0. Database'!P57 | G35: 0.13 | H35: =$C$35*($B$26*$D$26+$E$26*$F$26+$G$26*$H$26) | I35: ='0. Database'!Q60 | J35: ='0. Database'!Q59 | K35: ='0. Database'!Q55 | L35: ='0. Database'!Q56
A36: ORCL | B36: ='0. Database'!P78 | C36: ='0. Database'!P77 | D36: ='0. Database'!P73 | E36: ='0. Database'!P74 | F36: ='0. Database'!P75 | G36: 0.2 | H36: =$C$36*($B$27*$D$27+$E$27*$F$27+$G$27*$H$27) | I36: ='0. Database'!Q78 | J36: ='0. Database'!Q77 | K36: ='0. Database'!Q73 | L36: ='0. Database'!Q74
A39: D. Core Sensitivity: Compress Only IT Equipment (Buildings/) — Straight-Line
A40: Logic: D&A = ITD&A + Buildings + . ITBurry.
A41: IT Equipment = 6 Year (Buildings/)
A42: Company | B42: ITD&A ($mm) | C42: BuildingsD&A (,$mm) | D42: D&A (,$mm) | E42: New Total D&A ($mm) | F42: Current D&A ($mm) | G42: ΔD&A ($mm) | H42: Δ ($mm) | I42: Adj NI ($mm) | J42: Adj EPS ($) | K42: EPS Change%
A43: MSFT | B43: =$H$32*$B$23/6 | C43: =$H$32*$E$23/$F$23 | D43: =$H$32*$G$23/$H$23 | E43: =$B$43+$C$43+$D$43 | F43: =$C$32 | G43: =$E$43-$C$32 | H43: =$G$43*(1-$G$32) | I43: =$D$32-$H$43 | J43: =$I$43/$F$32 | K43: =IFERROR($J$43/$E$32-1,"")
A44: AMZN | B44: =$H$33*$B$24/6 | C44: =$H$33*$E$24/$F$24 | D44: =$H$33*$G$24/$H$24 | E44: =$B$44+$C$44+$D$44 | F44: =$C$33 | G44: =$E$44-$C$33 | H44: =$G$44*(1-$G$33) | I44: =$D$33-$H$44 | J44: =$I$44/$F$33 | K44: =IFERROR($J$44/$E$33-1,"")
A45: GOOGL | B45: =$H$34*$B$25/6 | C45: =$H$34*$E$25/$F$25 | D45: =$H$34*$G$25/$H$25 | E45: =$B$45+$C$45+$D$45 | F45: =$C$34 | G45: =$E$45-$C$34 | H45: =$G$45*(1-$G$34) | I45: =$D$34-$H$45 | J45: =$I$45/$F$34 | K45: =IFERROR($J$45/$E$34-1,"")
A46: META | B46: =$H$35*$B$26/6 | C46: =$H$35*$E$26/$F$26 | D46: =$H$35*$G$26/$H$26 | E46: =$B$46+$C$46+$D$46 | F46: =$C$35 | G46: =$E$46-$C$35 | H46: =$G$46*(1-$G$35) | I46: =$D$35-$H$46 | J46: =$I$46/$F$35 | K46: =IFERROR($J$46/$E$35-1,"")
A47: ORCL | B47: =$H$36*$B$27/6 | C47: =$H$36*$E$27/$F$27 | D47: =$H$36*$G$27/$H$27 | E47: =$B$47+$C$47+$D$47 | F47: =$C$36 | G47: =$E$47-$C$36 | H47: =$G$47*(1-$G$36) | I47: =$D$36-$H$47 | J47: =$I$47/$F$36 | K47: =IFERROR($J$47/$E$36-1,"")
...

Sheet 7. SP500 AI EPS Split
A1: S&P 500: AI vs Non-AI EPSBreakdown + Dual P/E Valuation
A3: A. S&P 500 Actual Operating EPS + sell-side Cash Spending Framework
A4: EPS: FactSet actual (2018-2024), sell-side/consensus estimates (2025+). Capex/Buybacks: sell-side data (May 7 2026 report). Yellow = editable.
A5: Metric | B5: 2018A | C5: 2019A | D5: 2020A | E5: 2021A | F5: 2022A | G5: 2023A | H5: 2024A | I5: 2025A | J5: 2026E | K5: 2027E | L5: 2028E | M5: 2029E | N5: 2030E
A6: S&P 500 Operating EPS ($) | B6: 162 | C6: 164 | D6: 140 | E6: 209 | F6: 219 | G6: 221 | H6: 246 | I6: 275 | J6: 309 | K6: 342 | L6: 370 | M6: 396 | N6: 420
A7: S&P 500Capex ($B) — sell-side data | B7: 644 | C7: 697 | D7: 591 | E7: 739 | F7: 892 | G7: 958 | H7: 1077 | I7: 1296 | J7: 1724 | K7: 2103 | L7: 2400 | M7: 2600 | N7: 2750
A8: AICapex ($B) — 5 cos | B8: 50 | C8: 55 | D8: 60 | E8: 86 | F8: 158 | G8: 154 | H8: 237 | I8: 412 | J8: 755 | K8: 892 | L8: 950 | M8: 980 | N8: 1000
A9: S&P 500 Buybacks ($B) — sell-side data | B9: 770 | C9: 729 | D9: 520 | E9: 919 | F9: 950 | G9: 823 | H9: 982 | I9: 1066 | J9: 1098 | K9: 1153 | L9: 1200 | M9: 1250 | N9: 1300
A10: Share ofCapex% | B10: 50 | C10: 55 | D10: 60 | E10: 86 | F10: 158 | G10: 154 | H10: 237 | I10: 412 | J10: 755 | K10: 892 | L10: 950 | M10: 980 | N10: 1000
A12: B. AI-Driven EPS Estimation: Hyperscaler Capex → Supply Chain Profit → S&P 500 EPS
A13: Logic: Hyperscaler capex = revenue for NVDA/AVGO/MU/ANET/etc. Their net margin × capex = AI-driven NI. Divide by S&P 500 share count ≈ AI EPS.
A14: Metric | B14: 2018A | C14: 2019A | D14: 2020A | E14: 2021A | F14: 2022A | G14: 2023A | H14: 2024A | I14: 2025A | J14: 2026E | K14: 2027E | L14: 2028E | M14: 2029E | N14: 2030E
A15: % of Hyp Capex → S&P 500 co revenue (editable) | B15: 0.55 | C15: 0.55 | D15: 0.55 | E15: 0.55 | F15: 0.55 | G15: 0.55 | H15: 0.55 | I15: 0.6 | J15: 0.65 | K15: 0.65 | L15: 0.65 | M15: 0.63 | N15: 0.6
A16: Wtd avg net margin of AI supply chain (editable) | B16: 0.2 | C16: 0.2 | D16: 0.2 | E16: 0.22 | F16: 0.25 | G16: 0.3 | H16: 0.35 | I16: 0.4 | J16: 0.45 | K16: 0.42 | L16: 0.38 | M16: 0.35 | N16: 0.33
A17: AI Revenue to S&P 500 cos ($B) | B17: =B8*B15 | C17: =C8*C15 | D17: =D8*D15 | E17: =E8*E15 | F17: =F8*F15 | G17: =G8*G15 | H17: =H8*H15 | I17: =I8*I15 | ... N17: =N8*N15
A18: AI Net Income to S&P 500 cos ($B) | B18: =B17*B16 | C18: =C17*C16 | D18: =D17*D16 | E18: =E17*E16 | F18: =F17*F16 | G18: =G17*G16 | H18: =H17*H16 | I18: =I17*I16 | ... N18: =N17*N16
A19: S&P 500TotalNet Income ($B) ≈ EPS × 7.7B shares | B19: =B6*7.7 | C19: =C6*7.7 | D19: =D6*7.7 | E19: =E6*7.7 | F19: =F6*7.7 | G19: =G6*7.7 | H19: =H6*7.7 | I19: =I6*7.7 | ... N19: =N6*7.7
A20: AI-Driven EPS ($) = AI NI / 7.7B shares | B20: =B18/7.7 | C20: =C18/7.7 | D20: =D18/7.7 | E20: =E18/7.7 | F20: =F18/7.7 | G20: =G18/7.7 | H20: =H18/7.7 | I20: =I18/7.7 | ... N20: =N18/7.7
A21: Non-AI EPS ($) = Total - AI | B21: =B6-B20 | C21: =C6-C20 | D21: =D6-D20 | E21: =E6-E20 | F21: =F6-F20 | G21: =G6-G20 | H21: =H6-H20 | I21: =I6-I20 | ... N21: =N6-N20
A22: AI % of Total EPS | B22: =IFERROR(B20/B6,"") | C22: =IFERROR(C20/C6,"") | D22: =IFERROR(D20/D6,"") | E22: =IFERROR(E20/E6,"") | F22: =IFERROR(F20/F6,"") | G22: =IFERROR(G20/G6,"") | H22: =IFERROR(H20/H6,"") | I22: =IFERROR(I20/I6,"") | ... N22: =IFERROR(N20/N6,"")
A23: AI EPS YoY % | C23: =IFERROR(C20/B20-1,"") | D23: =IFERROR(D20/C20-1,"") | E23: =IFERROR(E20/D20-1,"") | F23: =IFERROR(F20/E20-1,"") | G23: =IFERROR(G20/F20-1,"") | H23: =IFERROR(H20/G20-1,"") | I23: =IFERROR(I20/H20-1,"") | J23: =IFERROR(J20/I20-1,"") | ... N23: =IFERROR(N20/M20-1,"")
A25: C. Dual P/E Valuation — Separate Multiples for AI vs Non-AI EPS
A26: AI P/E (editable) — hist avg ~18x | B26: 18
A27: AI P/E (editable) — NVDA ~30-40x fwd | B27: 35
A29: Valuation Component | B29: 2024A | C29: 2025A | D29: 2026E | E29: 2027E | F29: 2028E | G29: 2029E | H29: 2030E
A30: AI = Non-AI EPS × P/E | B30: =H21*$B$26 | C30: =I21*$B$26 | D30: =J21*$B$26 | E30: =K21*$B$26 | F30: =L21*$B$26 | G30: =M21*$B$26 | H30: =N21*$B$26
A31: AI = AI EPS × P/E | B31: =H20*$B$27 | C31: =I20*$B$27 | D31: =J20*$B$27 | E31: =K20*$B$27 | F31: =L20*$B$27 | G31: =M20*$B$27 | H31: =N20*$B$27
A32: Implied S&P 500 Level | B32: =B30+B31 | C32: =C30+C31 | D32: =D30+D31 | E32: =E30+E31 | F32: =F30+F31 | G32: =G30+G31 | H32: =H30+H31
A33: Blended P/E (implied) | B33: =IFERROR(B32/H6,"") | C33: =IFERROR(C32/I6,"") | D33: =IFERROR(D32/J6,"") | E33: =IFERROR(E32/K6,"") | F33: =IFERROR(F32/L6,"") | G33: =IFERROR(G32/M6,"") | H33: =IFERROR(H32/N6,"")
A35: D. Scenario Grid: 2026E Implied S&P 500 Under Different P/E Assumptions
A36: Reads: 'If Non-AI trades at Xpe and AI trades at Ype, 2026E S&P 500 = Z'. Uses AI/Non-AI EPS from Section B. Change yellow cells above to update.
A37: AI P/E ↓ AI P/E → | B37: 22x | C37: 20x | D37: 18x | E37: 16x | F37: 14x
A38: 40x | B38: =J21*22+J20*40 | C38: =J21*20+J20*40 | D38: =J21*18+J20*40 | E38: =J21*16+J20*40 | F38: =J21*14+J20*40
A39: 35x | B39: =J21*22+J20*35 | C39: =J21*20+J20*35 | D39: =J21*18+J20*35 | E39: =J21*16+J20*35 | F39: =J21*14+J20*35
A40: 30x | B40: =J21*22+J20*30 | C40: =J21*20+J20*30 | D40: =J21*18+J20*30 | E40: =J21*16+J20*30 | F40: =J21*14+J20*30
A41: 25x | B41: =J21*22+J20*25 | C41: =J21*20+J20*25 | D41: =J21*18+J20*25 | E41: =J21*16+J20*25 | F41: =J21*14+J20*25
A42: 20x | B42: =J21*22+J20*20 | C42: =J21*20+J20*20 | D42: =J21*18+J20*20 | E42: =J21*16+J20*20 | F42: =J21*14+J20*20
A43: 15x | B43: =J21*22+J20*15 | C43: =J21*20+J20*15 | D43: =J21*18+J20*15 | E43: =J21*16+J20*15 | F43: =J21*14+J20*15
A44: 10x | B44: =J21*22+J20*10 | C44: =J21*20+J20*10 | D44: =J21*18+J20*10 | E44: =J21*16+J20*10 | F44: =J21*14+J20*10
A46: E. Stress Test: What Happens to S&P 500 if AI Capex Slows?
...

Sheet 8. Charts
A1: Visual Summary (2013-2030)
A3: Capex/Revenue %
B4: 2013 | C4: 2014 | D4: 2015 | E4: 2016 | F4: 2017 | G4: 2018 | H4: 2019 | I4: 2020 | J4: 2021 | K4: 2022 | L4: 2023 | M4: 2024 | N4: 2025 | O4: 2026 | P4: 2027 | Q4: 2028 | R4: 2029 | S4: 2030
A5: MSFT | B5: =IFERROR('0. Database'!C12/'0. Database'!C5,NA()) | C5: =IFERROR('0. Database'!D12/'0. Database'!D5,NA()) | D5: =IFERROR('0. Database'!E12/'0. Database'!E5,NA()) | E5: =IFERROR('0. Database'!F12/'0. Database'!F5,NA()) | F5: =IFERROR('0. Database'!G12/'0. Database'!G5,NA()) | G5: =IFERROR('0. Database'!H12/'0. Database'!H5,NA()) | H5: =IFERROR('0. Database'!I12/'0. Database'!I5,NA()) | I5: =IFERROR('0. Database'!J12/'0. Database'!J5,NA()) | ... S5: =IFERROR('0. Database'!T12/'0. Database'!T5,NA())
A6: AMZN | B6: =IFERROR('0. Database'!C28/'0. Database'!C21,NA()) | C6: =IFERROR('0. Database'!D28/'0. Database'!D21,NA()) | D6: =IFERROR('0. Database'!E28/'0. Database'!E21,NA()) | E6: =IFERROR('0. Database'!F28/'0. Database'!F21,NA()) | F6: =IFERROR('0. Database'!G28/'0. Database'!G21,NA()) | G6: =IFERROR('0. Database'!H28/'0. Database'!H21,NA()) | H6: =IFERROR('0. Database'!I28/'0. Database'!I21,NA()) | I6: =IFERROR('0. Database'!J28/'0. Database'!J21,NA()) | ... S6: =IFERROR('0. Database'!T28/'0. Database'!T21,NA())
A7: GOOGL | B7: =IFERROR('0. Database'!C43/'0. Database'!C36,NA()) | C7: =IFERROR('0. Database'!D43/'0. Database'!D36,NA()) | D7: =IFERROR('0. Database'!E43/'0. Database'!E36,NA()) | E7: =IFERROR('0. Database'!F43/'0. Database'!F36,NA()) | F7: =IFERROR('0. Database'!G43/'0. Database'!G36,NA()) | G7: =IFERROR('0. Database'!H43/'0. Database'!H36,NA()) | H7: =IFERROR('0. Database'!I43/'0. Database'!I36,NA()) | I7: =IFERROR('0. Database'!J43/'0. Database'!J36,NA()) | ... S7: =IFERROR('0. Database'!T43/'0. Database'!T36,NA())
A8: META | B8: =IFERROR('0. Database'!C60/'0. Database'!C53,NA()) | C8: =IFERROR('0. Database'!D60/'0. Database'!D53,NA()) | D8: =IFERROR('0. Database'!E60/'0. Database'!E53,NA()) | E8: =IFERROR('0. Database'!F60/'0. Database'!F53,NA()) | F8: =IFERROR('0. Database'!G60/'0. Database'!G53,NA()) | G8: =IFERROR('0. Database'!H60/'0. Database'!H53,NA()) | H8: =IFERROR('0. Database'!I60/'0. Database'!I53,NA()) | I8: =IFERROR('0. Database'!J60/'0. Database'!J53,NA()) | ... S8: =IFERROR('0. Database'!T60/'0. Database'!T53,NA())
A9: ORCL | B9: =IFERROR('0. Database'!C78/'0. Database'!C82,NA()) | C9: =IFERROR('0. Database'!D78/'0. Database'!D82,NA()) | D9: =IFERROR('0. Database'!E78/'0. Database'!E82,NA()) | E9: =IFERROR('0. Database'!F78/'0. Database'!F82,NA()) | F9: =IFERROR('0. Database'!G78/'0. Database'!G82,NA()) | G9: =IFERROR('0. Database'!H78/'0. Database'!H82,NA()) | H9: =IFERROR('0. Database'!I78/'0. Database'!I82,NA()) | I9: =IFERROR('0. Database'!J78/'0. Database'!J82,NA()) | ... S9: =IFERROR('0. Database'!T78/'0. Database'!T82,NA())
A28: FCF Margin %
B29: 2013 | C29: 2014 | D29: 2015 | E29: 2016 | F29: 2017 | G29: 2018 | H29: 2019 | I29: 2020 | J29: 2021 | K29: 2022 | L29: 2023 | M29: 2024 | N29: 2025 | O29: 2026 | P29: 2027 | Q29: 2028 | R29: 2029 | S29: 2030
A30: MSFT
A31: AMZN
A32: GOOGL
A33: META
A34: ORCL
A53: Capex ($mm)
B54: 2013 | C54: 2014 | D54: 2015 | E54: 2016 | F54: 2017 | G54: 2018 | H54: 2019 | I54: 2020 | J54: 2021 | K54: 2022 | L54: 2023 | M54: 2024 | N54: 2025 | O54: 2026 | P54: 2027 | Q54: 2028 | R54: 2029 | S54: 2030
A55: MSFT | B55: =IFERROR('0. Database'!C12,NA()) | C55: =IFERROR('0. Database'!D12,NA()) | D55: =IFERROR('0. Database'!E12,NA()) | E55: =IFERROR('0. Database'!F12,NA()) | F55: =IFERROR('0. Database'!G12,NA()) | G55: =IFERROR('0. Database'!H12,NA()) | H55: =IFERROR('0. Database'!I12,NA()) | I55: =IFERROR('0. Database'!J12,NA()) | ... S55: =IFERROR('0. Database'!T12,NA())
A56: AMZN | B56: =IFERROR('0. Database'!C28,NA()) | C56: =IFERROR('0. Database'!D28,NA()) | D56: =IFERROR('0. Database'!E28,NA()) | E56: =IFERROR('0. Database'!F28,NA()) | F56: =IFERROR('0. Database'!G28,NA()) | G56: =IFERROR('0. Database'!H28,NA()) | H56: =IFERROR('0. Database'!I28,NA()) | I56: =IFERROR('0. Database'!J28,NA()) | ... S56: =IFERROR('0. Database'!T28,NA())
A57: GOOGL | B57: =IFERROR('0. Database'!C43,NA()) | C57: =IFERROR('0. Database'!D43,NA()) | D57: =IFERROR('0. Database'!E43,NA()) | E57: =IFERROR('0. Database'!F43,NA()) | F57: =IFERROR('0. Database'!G43,NA()) | G57: =IFERROR('0. Database'!H43,NA()) | H57: =IFERROR('0. Database'!I43,NA()) | I57: =IFERROR('0. Database'!J43,NA()) | ... S57: =IFERROR('0. Database'!T43,NA())
A58: META | B58: =IFERROR('0. Database'!C60,NA()) | C58: =IFERROR('0. Database'!D60,NA()) | D58: =IFERROR('0. Database'!E60,NA()) | E58: =IFERROR('0. Database'!F60,NA()) | F58: =IFERROR('0. Database'!G60,NA()) | G58: =IFERROR('0. Database'!H60,NA()) | H58: =IFERROR('0. Database'!I60,NA()) | I58: =IFERROR('0. Database'!J60,NA()) | ... S58: =IFERROR('0. Database'!T60,NA())
A59: ORCL | B59: =IFERROR('0. Database'!C78,NA()) | C59: =IFERROR('0. Database'!D78,NA()) | D59: =IFERROR('0. Database'!E78,NA()) | E59: =IFERROR('0. Database'!F78,NA()) | F59: =IFERROR('0. Database'!G78,NA()) | G59: =IFERROR('0. Database'!H78,NA()) | H59: =IFERROR('0. Database'!I78,NA()) | I59: =IFERROR('0. Database'!J78,NA()) | ... S59: =IFERROR('0. Database'!T78,NA())
A78: Revenue YoY %
B79: 2013 | C79: 2014 | D79: 2015 | E79: 2016 | F79: 2017 | G79: 2018 | H79: 2019 | I79: 2020 | J79: 2021 | K79: 2022 | L79: 2023 | M79: 2024 | N79: 2025 | O79: 2026 | P79: 2027 | Q79: 2028 | R79: 2029 | S79: 2030
A80: MSFT | C80: =IFERROR('0. Database'!D5/'0. Database'!C5-1,NA()) | D80: =IFERROR('0. Database'!E5/'0. Database'!D5-1,NA()) | E80: =IFERROR('0. Database'!F5/'0. Database'!E5-1,NA()) | F80: =IFERROR('0. Database'!G5/'0. Database'!F5-1,NA()) | G80: =IFERROR('0. Database'!H5/'0. Database'!G5-1,NA()) | H80: =IFERROR('0. Database'!I5/'0. Database'!H5-1,NA()) | I80: =IFERROR('0. Database'!J5/'0. Database'!I5-1,NA()) | J80: =IFERROR('0. Database'!K5/'0. Database'!J5-1,NA()) | ... S80: =IFERROR('0. Database'!T5/'0. Database'!S5-1,NA())
A81: AMZN | C81: =IFERROR('0. Database'!D21/'0. Database'!C21-1,NA()) | D81: =IFERROR('0. Database'!E21/'0. Database'!D21-1,NA()) | E81: =IFERROR('0. Database'!F21/'0. Database'!E21-1,NA()) | F81: =IFERROR('0. Database'!G21/'0. Database'!F21-1,NA()) | G81: =IFERROR('0. Database'!H21/'0. Database'!G21-1,NA()) | H81: =IFERROR('0. Database'!I21/'0. Database'!H21-1,NA()) | I81: =IFERROR('0. Database'!J21/'0. Database'!I21-1,NA()) | J81: =IFERROR('0. Database'!K21/'0. Database'!J21-1,NA()) | ... S81: =IFERROR('0. Database'!T21/'0. Database'!S21-1,NA())
