Workbook

Sheet 0. Database
A1: Centralized Database (USD mm except EPS/shares) — Blue = input
A3: Ticker | B3: Metric | C3: 2013A | D3: 2014A | E3: 2015A | F3: 2016A | G3: 2017A | H3: 2018A | I3: 2019A | J3: 2020A | K3: 2021A | L3: 2022A | M3: 2023A | N3: 2024A | O3: 2025E | P3: 2026E | Q3: 2027E | R3: 2028E | S3: 2029E | T3: 2030E
A4: MSFT (FY(Jun))
A5: MSFT | B5: Revenue | C5: 77849 | D5: 86833 | E5: 93580 | F5: 91963 | G5: 96657 | H5: 110360 | I5: 125843 | J5: 143015 | K5: 168088 | L5: 198270 | M5: 211915 | N5: 245122 | O5: 281724 | P5: 329213.24 | Q5: 383408.94 | R5: 450123.14 | S5: 533860.75 | T5: 624709.64
A6: MSFT | B6: Operating Income | C6: 26764 | D6: 27759 | E6: 13359 | F6: 11756 | G6: 11389 | H6: 12924 | I6: 16219 | J6: 18724 | K6: 24351 | L6: 29687 | M6: 50074 | N6: 59661 | O6: 69773 | P6: 79541.62 | Q6: 85628.96 | R6: 69877.51 | S6: 101371.29 | T6: 108509.49
A7: MSFT | B7: Net Income | C7: 21863 | D7: 22074 | E7: 12193 | F7: 16798 | G7: 25489 | H7: 16571 | I7: 39240 | J7: 44281 | K7: 61271 | L7: 72738 | M7: 72361 | N7: 88136 | O7: 101832 | P7: 129372.86 | Q7: 144971.56 | R7: 175683.92 | S7: 215472.22 | T7: 258948.36
A8: MSFT | B8: EPS | C8: 2.58 | D8: 2.63 | E8: 1.48 | F8: 2.1 | G8: 2.71 | H8: 2.13 | I8: 5.06 | J8: 5.76 | K8: 8.05 | L8: 9.65 | M8: 9.68 | N8: 11.8 | O8: 13.64 | P8: 17.28 | Q8: 19.42 | R8: 22.81 | S8: 27 | T8: 31.49
A9: MSFT | B9: Diluted Shares (mm) | C9: 8375 | D9: 8299 | E9: 8177 | F9: 7925 | G9: 7746 | H9: 7700 | I9: 7673 | J9: 7610 | K9: 7547 | L9: 7496 | M9: 7446 | N9: 7431 | O9: 7433 | P9: 7425.9 | Q9: 7410.77 | R9: 7384.08 | S9: 7370.87 | T9: 7345.29
A10: MSFT | B10: SBC | C10: 2406 | D10: 2446 | E10: 2574 | F10: 2668 | G10: 3266 | H10: 3940 | I10: 4652 | J10: 5289 | K10: 6118 | L10: 7502 | M10: 9611 | N10: 10734 | O10: 11974 | P10: 12189 | Q10: 10478.4 | R10: 11434.24 | S10: 12826.56 | T10: 14871.62
A11: MSFT | B11: D&A | C11: 3755 | D11: 5212 | E11: 5957 | F11: 6622 | G11: 8778 | H11: 10261 | I11: 11682 | J11: 12796 | K11: 11686 | L11: 14460 | M11: 13861 | N11: 22287 | O11: 34153 | P11: 42005.11 | Q11: 55415.31 | R11: 73946.23 | S11: 97100.11 | T11: 127810.23
A12: MSFT | B12: Capex | C12: 4257 | D12: 5485 | E12: 5944 | F12: 8932 | G12: 10200 | H12: 13600 | I12: 16900 | J12: 19000 | K12: 24200 | L12: 29200 | M12: 31900 | N12: 55700 | O12: 88200 | P12: 145871.3 | Q12: 245263.45 | R12: 286760.35 | S12: 300210.91 | T12: 304616.04
A13: MSFT | B13: CFO | C13: 28833 | D13: 32231 | E13: 29080 | F13: 33325 | G13: 39507 | H13: 43884 | I13: 52185 | J13: 60675 | K13: 76740 | L13: 89035 | M13: 87582 | N13: 118548 | O13: 136162 | P13: 174558.18 | Q13: 232097.78 | R13: 294570.35 | S13: 359672.36 | T13: 438548.9
A14: MSFT | B14: FCF | C14: 24576 | D14: 26746 | E14: 23136 | F14: 24393 | G14: 29307 | H14: 30284 | I14: 35285 | J14: 41675 | K14: 52540 | L14: 59835 | M14: 55682 | N14: 62848 | O14: 47962 | P14: 28686.88 | Q14: -13165.67 | R14: 7810 | S14: 59461.45 | T14: 133932.86
A15: MSFT | B15: Buybacks | C15: 5360 | D15: 7316 | E15: 14443 | F15: 15969 | G15: 11788 | H15: 10721 | I15: 19543 | J15: 22968 | K15: 27385 | L15: 32696 | M15: 22245 | N15: 17254 | O15: 18420 | P15: 22499.7 | Q15: 19070.28 | R15: 19500.41 | S15: 20126.95 | T15: 21047.23
A16: MSFT | B16: Intell Cloud | C16: 0 | D16: 0 | E16: 0 | F16: 0 | G16: 0 | H16: 0 | I16: 0 | J16: 0 | K16: 0 | L16: 0 | M16: 72314 | N16: 87464 | O16: 106265 | P16: 136688.31 | Q16: 180358.14 | R16: 235873.55 | S16: 304531.45 | T16: 384276.13
... A18: MSFT | B18: Useful Life(yr) | C18: 3.16 | D18: 2.69 | E18: 2.81 | F18: 2.83 | G18: 2.71 | H18: 2.73 | I18: 2.74 | J18: 3.08 | K18: 4.33 | L18: 4.12 | M18: 6.1 | N18: 5.59 | O18: 5.26 | P18: 4.89 | Q18: 4.36 | R18: 4.38 | S18: 4.6 | T18: 4.7
A20: AMZN (CY)
A21: AMZN | B21: Revenue | C21: 74452 | D21: 88988 | E21: 107006 | F21: 135987 | G21: 177866 | H21: 232887 | I21: 280522 | J21: 386064 | K21: 469822 | L21: 513983 | M21: 574785 | N21: 637959 | O21: 716924 | P21: 824745.86 | Q21: 933246.82 | R21: 1035581.9 | S21: 1167156.7 | T21: 1303433.7
A22: AMZN | B22: Operating Income | C22: 673 | D22: 458 | E22: 1507 | F22: 3108 | G22: 4331 | H22: 7296 | I22: 9201 | J22: 13531 | K22: 18532 | L22: 22841 | M22: 24631 | N22: 39834 | O22: 45606 | P22: 58892.45 | Q22: 76144.3 | R22: 98372.18 | S22: 123330.71 | T22: 152115.05
A23: AMZN | B23: Net Income | C23: 273 | D23: -240.6 | E23: 596.1 | F23: 2371 | G23: 3033 | H23: 10073 | I23: 11588 | J23: 21331 | K23: 33364 | L23: -2722 | M23: 30425 | N23: 59248 | O23: 77670 | P23: 98333.72 | Q23: 116218.4 | R23: 145016.4 | S23: 177176.2 | T23: 211925.99
A24: AMZN | B24: EPS | C24: 0.03 | D24: -0.03 | E24: 0.06 | F24: 0.25 | G24: 0.23 | H24: 1.01 | I24: 1.15 | J24: 2.09 | K24: 2.33 | L24: 0.72 | M24: 2.84 | N24: 5.53 | O24: 7.17 | P24: 8.79 | Q24: 10.03 | R24: 12.92 | S24: 14.34 | T24: 17.13
A25: AMZN | B25: Diluted Shares (mm) | C25: 9140 | D25: 9240 | E25: 9340 | F25: 9480 | G25: 9600 | H25: 9740 | I25: 9880 | J25: 10000 | K25: 10120 | L25: 10189 | M25: 10304 | N25: 10473 | O25: 10656 | P25: 10862.95 | Q25: 10969.88 | R25: 11057.54 | S25: 11153.52 | T25: 11258.12
A26: AMZN | B26: SBC | C26: -1134 | D26: -1497 | E26: -2120 | F26: -2975 | G26: -4214 | H26: -5418 | I26: -6864 | J26: -9208 | K26: -12757 | L26: -19621 | M26: -24023 | N26: -22077.4 | O26: -19467 | P26: -18863.32 | Q26: -17920.15 | R26: -18816.16 | S26: -19756.97 | T26: -20744.82
A27: AMZN | B27: D&A | C27: 3253 | D27: 4746 | E27: 6281 | F27: 8116 | G27: 11478 | H27: 15341 | I27: 21789 | J27: 25180 | K27: 34433 | L27: 41921 | M27: 48663 | N27: 52795 | O27: 65756 | P27: 84391.58 | Q27: 107181.82 | R27: 131811.18 | S27: 145951.12 | T27: 164275.19
A28: AMZN | B28: Capex | C28: 3443 | D28: 4892 | E28: 4588 | F28: 6736 | G28: 10057 | H28: 11322 | I28: 12690 | J28: 35046 | K28: 55396 | L28: 58321 | M28: 48133 | N28: 77658 | O28: 128320 | P28: 200104.98 | Q28: 270141.72 | R28: 283648.81 | S28: 297831.25 | T28: 312722.81
A29: AMZN | B29: CFO | C29: 5474 | D29: 6841.4 | E29: 11920.1 | F29: 17271 | G29: 18434 | H29: 30724 | I29: 38515 | J29: 66064 | K29: 46327 | L29: 46752 | M29: 84946 | N29: 115877 | O29: 139514 | P29: 181004.31 | Q29: 224443.7 | R29: 281471.71 | S29: 342814.42 | T29: 401080.41
A30: AMZN | B30: FCF | C30: 2031 | D30: 1949.4 | E30: 7332.1 | F30: 10535 | G30: 8377 | H30: 19402 | I30: 25825 | J30: 31018 | K30: -9069 | L30: -11569 | M30: 36813 | N30: 38219 | O30: 11194 | P30: -19100.67 | Q30: -45698.02 | R30: -2177.1 | S30: 44983.17 | T30: 88357.6
A31: AMZN | B31: Buybacks | C31: 0 | D31: 0 | E31: 0 | F31: 0 | G31: 0 | H31: 0 | I31: 0 | J31: 0 | K31: 0 | L31: 6000 | M31: 0 | N31: 0 | O31: 0 | P31: 0 | Q31: 0 | R31: 0 | S31: 0 | T31: 0
A32: AMZN | B32: AWS Rev | C32: 3107.57 | D32: 4644 | E32: 7880 | F32: 12219 | G32: 17458 | H32: 25656 | I32: 35026 | J32: 45370 | K32: 62202 | L32: 80096 | M32: 90757 | N32: 107556 | O32: 128725 | P32: 171284.9 | Q32: 225587.94 | R32: 274421.67 | S32: 323817.58 | T32: 374009.3
A33: AMZN | B33: AWS OI | D33: 458 | E33: 1508 | F33: 3109 | G33: 4331 | H33: 7296 | I33: 9201 | J33: 13531 | K33: 18532 | L33: 22841 | M33: 24631 | N33: 39834 | O33: 45606 | P33: 61254.41 | Q33: 81248.3 | R33: 100888.47 | S33: 121477.03 | T33: 143111.04
A35: GOOGL (CY)
A36: GOOGL | B36: Revenue | C36: 55519 | D36: 66001 | E36: 74989 | F36: 90272 | G36: 110855 | H36: 136819 | I36: 161857 | J36: 182527 | K36: 257637 | L36: 282836 | M36: 307394 | N36: 350018 | O36: 402836 | P36: 486455.79 | Q36: 578508.88 | R36: 684008.77 | S36: 805409.01 | T36: 941245.16
A37: GOOGL | B37: Operating Income | C37: 16260 | D37: 18965 | E37: 23319 | F37: 27055 | G37: 32456 | H37: 43137 | I37: 48999 | J37: 54606 | K37: 91855 | L37: 82699 | M37: 95858 | N37: 121263 | O37: 139404 | P37: 166048.71 | Q37: 188404.24 | R37: 207483.23 | S37: 229196.58 | T37: 258679.36
A38: GOOGL | B38: Net Income | C38: 12720 | D38: 14136 | E38: 16348 | F38: 19478 | G38: 12662 | H38: 30736 | I38: 34343 | J38: 40269 | K38: 76033 | L38: 59972 | M38: 73795 | N38: 100118 | O38: 132170 | P38: 168543.28 | Q38: 174626.97 | R38: 210753.44 | S38: 249488.6 | T38: 285975.76
A39: GOOGL | B39: EPS | C39: 0.9 | D39: 1.01 | E39: 1.14 | F39: 1.39 | G39: 1.6 | H39: 2.19 | I39: 2.33 | J39: 2.93 | K39: 5.61 | L39: 4.56 | M39: 5.8 | N39: 8.04 | O39: 10.81 | P39: 14.19 | Q39: 14.69 | R39: 17.35 | S39: 21.25 | T39: 26.04
A40: GOOGL | B40: Diluted Shares (mm) | C40: 13313.88 | D40: 13518.7 | E40: 13692.52 | F40: 13842.18 | G40: 13858.02 | H40: 13902.8 | I40: 13851.92 | J40: 13616.32 | K40: 13353 | L40: 13063 | M40: 12630 | N40: 12319 | O40: 12116 | P40: 12096.35 | Q40: 12055.53 | R40: 12150.69 | S40: 12227.42 | T40: 12193.09
A41: GOOGL | B41: SBC | C41: -3268 | D41: -4175 | E41: -4903 | F41: -6703 | G41: -7679 | H41: -9353 | I41: -10794 | J41: -12991 | K41: -15376 | L41: -19362 | M41: -22460 | N41: -22785 | O41: -24953 | P41: -27937.33 | Q41: -30032.63 | R41: -31979.73 | S41: -33657.1 | T41: -35339.95
A42: GOOGL | B42: D&A | C42: 2781 | D42: 3523 | E42: 4132 | F42: 5267 | G42: 6103 | H42: 8164 | I42: 10856 | J42: 12905 | K42: 11555 | L42: 15287 | M42: 13326 | N42: 15311 | O42: 21136 | P42: 42874.7 | Q42: 69582.72 | R42: 98340.16 | S42: 127674.93 | T42: 156155.17
A43: GOOGL | B43: Capex | C43: 7358 | D43: 10959 | E43: 9915 | F43: 10183 | G43: 13184 | H43: 25139 | I43: 23548 | J43: 22281 | K43: 24640 | L43: 31485 | M43: 32251 | N43: 52535 | O43: 91447 | P43: 185234.28 | Q43: 259327.99 | R43: 285260.79 | S43: 299523.83 | T43: 314500.02
A44: GOOGL | B44: CFO | C44: 18584 | D44: 22272 | E44: 25829 | F44: 36036 | G44: 37091 | H44: 47971 | I44: 54520 | J44: 65124 | K44: 91652 | L44: 91495 | M44: 101746 | N44: 125299 | O44: 164713 | P44: 211985.47 | Q44: 282346.21 | R44: 352943.8 | S44: 424226.82 | T44: 490867.35
...

Sheet 1. Summary
B2: AI Capex Cycle: Hyperscaler Deep-Dive (2013-2030)
B3: MSFT | AMZN | GOOGL | META | ORCL + S&P 500 AI EPS Decomposition
B5: CONTENTS
B6: 0. Database — 2013-2030 centralized data. Blue=input. All other sheets reference this.
B7: 1. Summary — This page
B8: 2. Revenue — Total rev, YoY%, Cloud/AI proxy. Derived metrics reference SAME sheet cells (black font).
B9: 3. Capex & D&A — Capex, Capex/Rev, D&A, D&A/Rev. Local formulas reference raw data on same sheet.
B10: 4. FCF & Cash — CFO, FCF margin, FCF/NI, Capex/CFO. All ratios use same-sheet references.
B11: 5. EPS & Margins — OpMargin, Net Margin, EPSYoY. Same-sheet referencing pattern.
B12: 6. Burry Sensitivity — GPU life compression on 2026E EPS. Editable tax rate assumptions.
B13: 7. S&P 500 AI EPS Split — AI vs Non-AI EPS decomposition + dual P/E valuation + 4 stress scenarios.
B14: 8. Charts — 6 visualizations (Capex/Rev, Free Cash FlowMargin, Capex absolute, Rev YoY, OpMargin, D&A/Rev).

Sheet 2. Revenue & Growth
A1: Revenue&AI/CloudSegment Detail (2013-2030E)
A3: A. Total Revenue ($mm)
A4: Company | B4: 2013A | C4: 2014A | D4: 2015A | E4: 2016A | F4: 2017A | G4: 2018A | H4: 2019A | I4: 2020A | J4: 2021A | K4: 2022A | L4: 2023A | M4: 2024A | N4: 2025E | O4: 2026E | P4: 2027E | Q4: 2028E | R4: 2029E | S4: 2030E
A5: MSFT | B5: ='0. Database'!C5 -> 77849 | C5: ='0. Database'!D5 -> 86833 | D5: ='0. Database'!E5 -> 93580 | E5: ='0. Database'!F5 -> 91963 | F5: ='0. Database'!G5 -> 96657 | G5: ='0. Database'!H5 -> 110360 | H5: ='0. Database'!I5 -> 125843 | I5: ='0. Database'!J5 -> 143015 | ... S5: ='0. Database'!T5 -> 624709.64
A6: AMZN | B6: ='0. Database'!C21 -> 74452 | C6: ='0. Database'!D21 -> 88988 | D6: ='0. Database'!E21 -> 107006 | E6: ='0. Database'!F21 -> 135987 | F6: ='0. Database'!G21 -> 177866 | G6: ='0. Database'!H21 -> 232887 | H6: ='0. Database'!I21 -> 280522 | I6: ='0. Database'!J21 -> 386064 | ... S6: ='0. Database'!T21 -> 1303433.7
A7: GOOGL | B7: ='0. Database'!C36 -> 55519 | C7: ='0. Database'!D36 -> 66001 | D7: ='0. Database'!E36 -> 74989 | E7: ='0. Database'!F36 -> 90272 | F7: ='0. Database'!G36 -> 110855 | G7: ='0. Database'!H36 -> 136819 | H7: ='0. Database'!I36 -> 161857 | I7: ='0. Database'!J36 -> 182527 | ... S7: ='0. Database'!T36 -> 941245.16
A8: META | B8: ='0. Database'!C53 -> 7872 | C8: ='0. Database'!D53 -> 12466 | D8: ='0. Database'!E53 -> 17928 | E8: ='0. Database'!F53 -> 27638 | F8: ='0. Database'!G53 -> 40653 | G8: ='0. Database'!H53 -> 55838 | H8: ='0. Database'!I53 -> 70697 | I8: ='0. Database'!J53 -> 85965 | ... S8: ='0. Database'!T53 -> 456699.5
A9: ORCL | B9: ='0. Database'!C71 -> 37253 | C9: ='0. Database'!D71 -> 38306 | D9: ='0. Database'!E71 -> 38253 | E9: ='0. Database'!F71 -> 37057 | F9: ='0. Database'!G71 -> 37899 | G9: ='0. Database'!H71 -> 39878 | H9: ='0. Database'!I71 -> 39526 | I9: ='0. Database'!J71 -> 39068 | ... S9: ='0. Database'!T71 -> 223043.24
A11: C. Cloud / AI Proxy Revenue ($mm)
A12: Company | B12: 2013A | C12: 2014A | D12: 2015A | E12: 2016A | F12: 2017A | G12: 2018A | H12: 2019A | I12: 2020A | J12: 2021A | K12: 2022A | L12: 2023A | M12: 2024A | N12: 2025E | O12: 2026E | P12: 2027E | Q12: 2028E | R12: 2029E | S12: 2030E
A13: MSFT — Azure
A14: AMZN — AWS | B14: ='0. Database'!C32 -> 3107.57 | C14: ='0. Database'!D32 -> 4644 | D14: ='0. Database'!E32 -> 7880 | E14: ='0. Database'!F32 -> 12219 | F14: ='0. Database'!G32 -> 17458 | G14: ='0. Database'!H32 -> 25656 | H14: ='0. Database'!I32 -> 35026 | I14: ='0. Database'!J32 -> 45370 | ... S14: ='0. Database'!T32 -> 374009.3
A15: GOOGL — Cloud | B15: ='0. Database'!C47 -> 0 | C15: ='0. Database'!D47 -> 0 | D15: ='0. Database'!E47 -> 0 | E15: ='0. Database'!F47 -> 0 | F15: ='0. Database'!G47 -> 4056 | G15: ='0. Database'!H47 -> 5838 | H15: ='0. Database'!I47 -> 8918 | I15: ='0. Database'!J47 -> 13059 | ... S15: ='0. Database'!T47 -> 343551.74
A16: META — Advertising | B16: ='0. Database'!C64 -> 6986 | C16: ='0. Database'!D64 -> 11492 | D16: ='0. Database'!E64 -> 17080 | E16: ='0. Database'!F64 -> 26885 | F16: ='0. Database'!G64 -> 39942 | G16: ='0. Database'!H64 -> 55012 | H16: ='0. Database'!I64 -> 69654.5 | I16: ='0. Database'!J64 -> 84169 | ... S16: ='0. Database'!T64 -> 444912.31
A17: ORCL — CloudTotalRevenue | B17: ='0. Database'!C82 -> 1365 | C17: ='0. Database'!D82 -> 38306 | D17: ='0. Database'!E82 -> 38253 | E17: ='0. Database'!F82 -> 37057 | F17: ='0. Database'!G82 -> 37899 | G17: ='0. Database'!H82 -> 39878 | H17: ='0. Database'!I82 -> 39526 | I17: ='0. Database'!J82 -> 39068 | ... S17: ='0. Database'!T82 -> 223043.24
A19: B. Revenue YoY %
A20: Company | B20: 2013A | C20: 2014A | D20: 2015A | E20: 2016A | F20: 2017A | G20: 2018A | H20: 2019A | I20: 2020A | J20: 2021A | K20: 2022A | L20: 2023A | M20: 2024A | N20: 2025E | O20: 2026E | P20: 2027E | Q20: 2028E | R20: 2029E | S20: 2030E
A21: MSFT | C21: =IFERROR(C5/B5-1,"") -> 0.1154029 | D21: =IFERROR(D5/C5-1,"") -> 0.077700874 | E21: =IFERROR(E5/D5-1,"") -> -0.017279333 | F21: =IFERROR(F5/E5-1,"") -> 0.051042267 | G21: =IFERROR(G5/F5-1,"") -> 0.14176935 | H21: =IFERROR(H5/G5-1,"") -> 0.1402954 | I21: =IFERROR(I5/H5-1,"") -> 0.13645574 | J21: =IFERROR(J5/I5-1,"") -> 0.17531727 | ... S21: =IFERROR(S5/R5-1,"") -> 0.17017338
A22: AMZN | C22: =IFERROR(C6/B6-1,"") -> 0.19523989 | D22: =IFERROR(D6/C6-1,"") -> 0.20247674 | E22: =IFERROR(E6/D6-1,"") -> 0.27083528 | F22: =IFERROR(F6/E6-1,"") -> 0.30796326 | G22: =IFERROR(G6/F6-1,"") -> 0.30933962 | H22: =IFERROR(H6/G6-1,"") -> 0.20454126 | I22: =IFERROR(I6/H6-1,"") -> 0.37623431 | J22: =IFERROR(J6/I6-1,"") -> 0.21695367 | ... S22: =IFERROR(S6/R6-1,"") -> 0.11675976
A23: GOOGL | C23: =IFERROR(C7/B7-1,"") -> 0.18880023 | D23: =IFERROR(D7/C7-1,"") -> 0.13617975 | E23: =IFERROR(E7/D7-1,"") -> 0.20380322 | F23: =IFERROR(F7/E7-1,"") -> 0.2280109 | G23: =IFERROR(G7/F7-1,"") -> 0.23421587 | H23: =IFERROR(H7/G7-1,"") -> 0.1830009 | I23: =IFERROR(I7/H7-1,"") -> 0.12770532 | J23: =IFERROR(J7/I7-1,"") -> 0.41150076 | ... S23: =IFERROR(S7/R7-1,"") -> 0.16865487
A24: META | C24: =IFERROR(C8/B8-1,"") -> 0.5835874 | D24: =IFERROR(D8/C8-1,"") -> 0.43815177 | E24: =IFERROR(E8/D8-1,"") -> 0.54161089 | F24: =IFERROR(F8/E8-1,"") -> 0.47090962 | G24: =IFERROR(G8/F8-1,"") -> 0.37352717 | H24: =IFERROR(H8/G8-1,"") -> 0.2661091 | I24: =IFERROR(I8/H8-1,"") -> 0.2159639 | J24: =IFERROR(J8/I8-1,"") -> 0.37182574 | ... S24: =IFERROR(S8/R8-1,"") -> 0.13136368
A25: ORCL | C25: =IFERROR(C9/B9-1,"") -> 0.02826618 | D25: =IFERROR(D9/C9-1,"") -> -0.0013835953 | E25: =IFERROR(E9/D9-1,"") -> -0.031265522 | F25: =IFERROR(F9/E9-1,"") -> 0.022721753 | G25: =IFERROR(G9/F9-1,"") -> 0.052217737 | H25: =IFERROR(H9/G9-1,"") -> -0.0088269221 | I25: =IFERROR(I9/H9-1,"") -> -0.01158731 | J25: =IFERROR(J9/I9-1,"") -> 0.036167708 | ... S25: =IFERROR(S9/R9-1,"") -> 0.21755399

Sheet 3. Capex & D&A
A1: Capex&D&A (2013-2030E)
A3: A. Capex ($mm)
A4: Company | B4: 2013A | C4: 2014A | D4: 2015A | E4: 2016A | F4: 2017A | G4: 2018A | H4: 2019A | I4: 2020A | J4: 2021A | K4: 2022A | L4: 2023A | M4: 2024A | N4: 2025E | O4: 2026E | P4: 2027E | Q4: 2028E | R4: 2029E | S4: 2030E
A5: MSFT | B5: ='0. Database'!C12 -> 4257 | C5: ='0. Database'!D12 -> 5485 | D5: ='0. Database'!E12 -> 5944 | E5: ='0. Database'!F12 -> 8932 | F5: ='0. Database'!G12 -> 10200 | G5: ='0. Database'!H12 -> 13600 | H5: ='0. Database'!I12 -> 16900 | I5: ='0. Database'!J12 -> 19000 | ... S5: ='0. Database'!T12 -> 304616.04
A6: AMZN | B6: ='0. Database'!C28 -> 3443 | C6: ='0. Database'!D28 -> 4892 | D6: ='0. Database'!E28 -> 4588 | E6: ='0. Database'!F28 -> 6736 | F6: ='0. Database'!G28 -> 10057 | G6: ='0. Database'!H28 -> 11322 | H6: ='0. Database'!I28 -> 12690 | I6: ='0. Database'!J28 -> 35046 | ... S6: ='0. Database'!T28 -> 312722.81
A7: GOOGL | B7: ='0. Database'!C43 -> 7358 | C7: ='0. Database'!D43 -> 10959 | D7: ='0. Database'!E43 -> 9915 | E7: ='0. Database'!F43 -> 10183 | F7: ='0. Database'!G43 -> 13184 | G7: ='0. Database'!H43 -> 25139 | H7: ='0. Database'!I43 -> 23548 | I7: ='0. Database'!J43 -> 22281 | ... S7: ='0. Database'!T43 -> 314500.02
A8: META | B8: ='0. Database'!C60 -> 1362 | C8: ='0. Database'!D60 -> 1831 | D8: ='0. Database'!E60 -> 2523 | E8: ='0. Database'!F60 -> 4491 | F8: ='0. Database'!G60 -> 6732 | G8: ='0. Database'!H60 -> 13980 | H8: ='0. Database'!I60 -> 15102 | I8: ='0. Database'!J60 -> 15115 | ... S8: ='0. Database'!T60 -> 208540.35
A9: ORCL | B9: ='0. Database'!C78 -> 650 | C9: ='0. Database'!D78 -> 580 | D9: ='0. Database'!E78 -> 1391 | E9: ='0. Database'!F78 -> 1189 | F9: ='0. Database'!G78 -> 2021 | G9: ='0. Database'!H78 -> 1736 | H9: ='0. Database'!I78 -> 1660 | I9: ='0. Database'!J78 -> 1564 | ... S9: ='0. Database'!T78 -> 66459.86
A11: D. D&A ($mm)
A12: Company | B12: 2013A | C12: 2014A | D12: 2015A | E12: 2016A | F12: 2017A | G12: 2018A | H12: 2019A | I12: 2020A | J12: 2021A | K12: 2022A | L12: 2023A | M12: 2024A | N12: 2025E | O12: 2026E | P12: 2027E | Q12: 2028E | R12: 2029E | S12: 2030E
A13: MSFT | B13: ='0. Database'!C11 -> 3755 | C13: ='0. Database'!D11 -> 5212 | D13: ='0. Database'!E11 -> 5957 | E13: ='0. Database'!F11 -> 6622 | F13: ='0. Database'!G11 -> 8778 | G13: ='0. Database'!H11 -> 10261 | H13: ='0. Database'!I11 -> 11682 | I13: ='0. Database'!J11 -> 12796 | ... S13: ='0. Database'!T11 -> 127810.23
A14: AMZN | B14: ='0. Database'!C27 -> 3253 | C14: ='0. Database'!D27 -> 4746 | D14: ='0. Database'!E27 -> 6281 | E14: ='0. Database'!F27 -> 8116 | F14: ='0. Database'!G27 -> 11478 | G14: ='0. Database'!H27 -> 15341 | H14: ='0. Database'!I27 -> 21789 | I14: ='0. Database'!J27 -> 25180 | ... S14: ='0. Database'!T27 -> 164275.19
A15: GOOGL | B15: ='0. Database'!C42 -> 2781 | C15: ='0. Database'!D42 -> 3523 | D15: ='0. Database'!E42 -> 4132 | E15: ='0. Database'!F42 -> 5267 | F15: ='0. Database'!G42 -> 6103 | G15: ='0. Database'!H42 -> 8164 | H15: ='0. Database'!I42 -> 10856 | I15: ='0. Database'!J42 -> 12905 | ... S15: ='0. Database'!T42 -> 156155.17
A16: META | B16: ='0. Database'!C59 -> 1011 | C16: ='0. Database'!D59 -> 1243 | D16: ='0. Database'!E59 -> 1945 | E16: ='0. Database'!F59 -> 2342 | F16: ='0. Database'!G59 -> 3025 | G16: ='0. Database'!H59 -> 4315 | H16: ='0. Database'!I59 -> 5741 | I16: ='0. Database'!J59 -> 6862 | ... S16: ='0. Database'!T59 -> 87724.37
A17: ORCL | B17: ='0. Database'!C77 -> 2931 | C17: ='0. Database'!D77 -> 2908 | D17: ='0. Database'!E77 -> 2861 | E17: ='0. Database'!F77 -> 2509 | F17: ='0. Database'!G77 -> 2451 | G17: ='0. Database'!H77 -> 2785 | H17: ='0. Database'!I77 -> 2919 | I17: ='0. Database'!J77 -> 2968 | ... S17: ='0. Database'!T77 -> 37972.18
A19: (Revenue — for ratios)
A20: Company | B20: 2013A | C20: 2014A | D20: 2015A | E20: 2016A | F20: 2017A | G20: 2018A | H20: 2019A | I20: 2020A | J20: 2021A | K20: 2022A | L20: 2023A | M20: 2024A | N20: 2025E | O20: 2026E | P20: 2027E | Q20: 2028E | R20: 2029E | S20: 2030E
A21: MSFT | B21: ='0. Database'!C5 -> 77849 | C21: ='0. Database'!D5 -> 86833 | D21: ='0. Database'!E5 -> 93580 | E21: ='0. Database'!F5 -> 91963 | F21: ='0. Database'!G5 -> 96657 | G21: ='0. Database'!H5 -> 110360 | H21: ='0. Database'!I5 -> 125843 | I21: ='0. Database'!J5 -> 143015 | ... S21: ='0. Database'!T5 -> 624709.64
A22: AMZN | B22: ='0. Database'!C21 -> 74452 | C22: ='0. Database'!D21 -> 88988 | D22: ='0. Database'!E21 -> 107006 | E22: ='0. Database'!F21 -> 135987 | F22: ='0. Database'!G21 -> 177866 | G22: ='0. Database'!H21 -> 232887 | H22: ='0. Database'!I21 -> 280522 | I22: ='0. Database'!J21 -> 386064 | ... S22: ='0. Database'!T21 -> 1303433.7
A23: GOOGL | B23: ='0. Database'!C36 -> 55519 | C23: ='0. Database'!D36 -> 66001 | D23: ='0. Database'!E36 -> 74989 | E23: ='0. Database'!F36 -> 90272 | F23: ='0. Database'!G36 -> 110855 | G23: ='0. Database'!H36 -> 136819 | H23: ='0. Database'!I36 -> 161857 | I23: ='0. Database'!J36 -> 182527 | ... S23: ='0. Database'!T36 -> 941245.16
A24: META | B24: ='0. Database'!C53 -> 7872 | C24: ='0. Database'!D53 -> 12466 | D24: ='0. Database'!E53 -> 17928 | E24: ='0. Database'!F53 -> 27638 | F24: ='0. Database'!G53 -> 40653 | G24: ='0. Database'!H53 -> 55838 | H24: ='0. Database'!I53 -> 70697 | I24: ='0. Database'!J53 -> 85965 | ... S24: ='0. Database'!T53 -> 456699.5
A25: ORCL | B25: ='0. Database'!C71 -> 37253 | C25: ='0. Database'!D71 -> 38306 | D25: ='0. Database'!E71 -> 38253 | E25: ='0. Database'!F71 -> 37057 | F25: ='0. Database'!G71 -> 37899 | G25: ='0. Database'!H71 -> 39878 | H25: ='0. Database'!I71 -> 39526 | I25: ='0. Database'!J71 -> 39068 | ... S25: ='0. Database'!T71 -> 223043.24
A27: B. CapexYoY %
A28: Company | B28: 2013A | C28: 2014A | D28: 2015A | E28: 2016A | F28: 2017A | G28: 2018A | H28: 2019A | I28: 2020A | J28: 2021A | K28: 2022A | L28: 2023A | M28: 2024A | N28: 2025E | O28: 2026E | P28: 2027E | Q28: 2028E | R28: 2029E | S28: 2030E
A29: MSFT | C29: =IFERROR(C5/B5-1,"") -> 0.28846606 | D29: =IFERROR(D5/C5-1,"") -> 0.083682771 | E29: =IFERROR(E5/D5-1,"") -> 0.50269179 | F29: =IFERROR(F5/E5-1,"") -> 0.14196149 | G29: =IFERROR(G5/F5-1,"") -> 0.33333333 | H29: =IFERROR(H5/G5-1,"") -> 0.24264706 | I29: =IFERROR(I5/H5-1,"") -> 0.12426036 | J29: =IFERROR(J5/I5-1,"") -> 0.27368421 | ... S29: =IFERROR(S5/R5-1,"") -> 0.014673451
A30: AMZN | C30: =IFERROR(C6/B6-1,"") -> 0.42085391 | D30: =IFERROR(D6/C6-1,"") -> -0.062142273 | E30: =IFERROR(E6/D6-1,"") -> 0.46817786 | F30: =IFERROR(F6/E6-1,"") -> 0.49302257 | G30: =IFERROR(G6/F6-1,"") -> 0.12578304 | H30: =IFERROR(H6/G6-1,"") -> 0.12082671 | I30: =IFERROR(I6/H6-1,"") -> 1.7617021 | J30: =IFERROR(J6/I6-1,"") -> 0.58066541 | ... S30: =IFERROR(S6/R6-1,"") -> 0.049999992
A31: GOOGL | C31: =IFERROR(C7/B7-1,"") -> 0.48939929 | D31: =IFERROR(D7/C7-1,"") -> -0.095264166 | E31: =IFERROR(E7/D7-1,"") -> 0.027029753 | F31: =IFERROR(F7/E7-1,"") -> 0.29470686 | G31: =IFERROR(G7/F7-1,"") -> 0.90678095 | H31: =IFERROR(H7/G7-1,"") -> -0.063288118 | I31: =IFERROR(I7/H7-1,"") -> -0.053804994 | J31: =IFERROR(J7/I7-1,"") -> 0.10587496 | ... S31: =IFERROR(S7/R7-1,"") -> 0.049999995
A32: META | C32: =IFERROR(C8/B8-1,"") -> 0.34434655 | D32: =IFERROR(D8/C8-1,"") -> 0.37793555 | E32: =IFERROR(E8/D8-1,"") -> 0.78002378 | F32: =IFERROR(F8/E8-1,"") -> 0.498998 | G32: =IFERROR(G8/F8-1,"") -> 1.0766488 | H32: =IFERROR(H8/G8-1,"") -> 0.080257511 | I32: =IFERROR(I8/H8-1,"") -> 0.00086081314 | J32: =IFERROR(J8/I8-1,"") -> 0.2283824 | ... S32: =IFERROR(S8/R8-1,"") -> 0.059999996
A33: ORCL | C33: =IFERROR(C9/B9-1,"") -> -0.10769231 | D33: =IFERROR(D9/C9-1,"") -> 1.3982759 | E33: =IFERROR(E9/D9-1,"") -> -0.14521927 | F33: =IFERROR(F9/E9-1,"") -> 0.69974769 | G33: =IFERROR(G9/F9-1,"") -> -0.1410193 | H33: =IFERROR(H9/G9-1,"") -> -0.043778802 | I33: =IFERROR(I9/H9-1,"") -> -0.057831325 | J33: =IFERROR(J9/I9-1,"") -> 0.36508951 | ... S33: =IFERROR(S9/R9-1,"") -> -0.18
A35: C. Capex / Revenue %
A36: Company | B36: 2013A | C36: 2014A | D36: 2015A | E36: 2016A | F36: 2017A | G36: 2018A | H36: 2019A | I36: 2020A | J36: 2021A | K36: 2022A | L36: 2023A | M36: 2024A | N36: 2025E | O36: 2026E | P36: 2027E | Q36: 2028E | R36: 2029E | S36: 2030E
A37: MSFT | B37: =IFERROR(B5/B21,"") -> 0.054682783 | C37: =IFERROR(C5/C21,"") -> 0.063167229 | D37: =IFERROR(D5/D21,"") -> 0.063517846 | E37: =IFERROR(E5/E21,"") -> 0.097126018 | F37: =IFERROR(F5/F21,"") -> 0.10552779 | G37: =IFERROR(G5/G21,"") -> 0.12323306 | H37: =IFERROR(H5/H21,"") -> 0.13429432 | I37: =IFERROR(I5/I21,"") -> 0.1328532 | ... S37: =IFERROR(S5/S21,"") -> 0.4876122
A38: AMZN | B38: =IFERROR(B6/B22,"") -> 0.04624456 | C38: =IFERROR(C6/C22,"") -> 0.054973704 | D38: =IFERROR(D6/D22,"") -> 0.0428761 | E38: =IFERROR(E6/E22,"") -> 0.049534147 | F38: =IFERROR(F6/F22,"") -> 0.056542566 | G38: =IFERROR(G6/G22,"") -> 0.048615852 | H38: =IFERROR(H6/H22,"") -> 0.045237094 | I38: =IFERROR(I6/I22,"") -> 0.090777695 | ... S38: =IFERROR(S6/S22,"") -> 0.2399223
A39: GOOGL | B39: =IFERROR(B7/B23,"") -> 0.13253121 | C39: =IFERROR(C7/C23,"") -> 0.16604294 | D39: =IFERROR(D7/D23,"") -> 0.13221939 | E39: =IFERROR(E7/E23,"") -> 0.11280353 | F39: =IFERROR(F7/F23,"") -> 0.11893013 | G39: =IFERROR(G7/G23,"") -> 0.1837391 | H39: =IFERROR(H7/H23,"") -> 0.14548645 | I39: =IFERROR(I7/I23,"") -> 0.12206961 | ... S39: =IFERROR(S7/S23,"") -> 0.33413189
A40: META | B40: =IFERROR(B8/B24,"") -> 0.17301829 | C40: =IFERROR(C8/C24,"") -> 0.14687951 | D40: =IFERROR(D8/D24,"") -> 0.14072959 | E40: =IFERROR(E8/E24,"") -> 0.16249367 | F40: =IFERROR(F8/F24,"") -> 0.16559663 | G40: =IFERROR(G8/G24,"") -> 0.25036713 | H40: =IFERROR(H8/H24,"") -> 0.21361585 | I40: =IFERROR(I8/I24,"") -> 0.17582737 | ... S40: =IFERROR(S8/S24,"") -> 0.45662487
A41: ORCL | B41: =IFERROR(B9/B25,"") -> 0.017448259 | C41: =IFERROR(C9/C25,"") -> 0.015141231 | D41: =IFERROR(D9/D25,"") -> 0.036363161 | E41: =IFERROR(E9/E25,"") -> 0.032085706 | F41: =IFERROR(F9/F25,"") -> 0.053325945 | G41: =IFERROR(G9/G25,"") -> 0.043532775 | H41: =IFERROR(H9/H25,"") -> 0.041997672 | I41: =IFERROR(I9/I25,"") -> 0.040032763 | ... S41: =IFERROR(S9/S25,"") -> 0.2979685
A43: E. D&A / Revenue %
A44: Company | B44: 2013A | C44: 2014A | D44: 2015A | E44: 2016A | F44: 2017A | G44: 2018A | H44: 2019A | I44: 2020A | J44: 2021A | K44: 2022A | L44: 2023A | M44: 2024A | N44: 2025E | O44: 2026E | P44: 2027E | Q44: 2028E | R44: 2029E | S44: 2030E
A45: MSFT | B45: =IFERROR(B13/B21,"") -> 0.048234402 | C45: =IFERROR(C13/C21,"") -> 0.060023263 | D45: =IFERROR(D13/D21,"") -> 0.063656764 | E45: =IFERROR(E13/E21,"") -> 0.07200722 | F45: =IFERROR(F13/F21,"") -> 0.090815978 | G45: =IFERROR(G13/G21,"") -> 0.092977528 | H45: =IFERROR(H13/H21,"") -> 0.092829955 | I45: =IFERROR(I13/I21,"") -> 0.089473132 | ... S45: =IFERROR(S13/S21,"") -> 0.20459142
A46: AMZN | B46: =IFERROR(B14/B22,"") -> 0.04369258 | C46: =IFERROR(C14/C22,"") -> 0.053333034 | D46: =IFERROR(D14/D22,"") -> 0.058697643 | E46: =IFERROR(E14/E22,"") -> 0.059682176 | F46: =IFERROR(F14/F22,"") -> 0.064531726 | G46: =IFERROR(G14/G22,"") -> 0.065873149 | H46: =IFERROR(H14/H22,"") -> 0.077673052 | I46: =IFERROR(I14/I22,"") -> 0.065222347 | ... S46: =IFERROR(S14/S22,"") -> 0.12603264
...

Sheet 4. FCF & Cash
A1: Free Cash Flow&Cash Quality (2013-2030E)
A3: A. CFO ($mm)
A4: Company | B4: 2013A | C4: 2014A | D4: 2015A | E4: 2016A | F4: 2017A | G4: 2018A | H4: 2019A | I4: 2020A | J4: 2021A | K4: 2022A | L4: 2023A | M4: 2024A | N4: 2025E | O4: 2026E | P4: 2027E | Q4: 2028E | R4: 2029E | S4: 2030E
A5: MSFT | B5: ='0. Database'!C13 -> 28833 | C5: ='0. Database'!D13 -> 32231 | D5: ='0. Database'!E13 -> 29080 | E5: ='0. Database'!F13 -> 33325 | F5: ='0. Database'!G13 -> 39507 | G5: ='0. Database'!H13 -> 43884 | H5: ='0. Database'!I13 -> 52185 | I5: ='0. Database'!J13 -> 60675 | ... S5: ='0. Database'!T13 -> 438548.9
A6: AMZN | B6: ='0. Database'!C29 -> 5474 | C6: ='0. Database'!D29 -> 6841.4 | D6: ='0. Database'!E29 -> 11920.1 | E6: ='0. Database'!F29 -> 17271 | F6: ='0. Database'!G29 -> 18434 | G6: ='0. Database'!H29 -> 30724 | H6: ='0. Database'!I29 -> 38515 | I6: ='0. Database'!J29 -> 66064 | ... S6: ='0. Database'!T29 -> 401080.41
A7: GOOGL | B7: ='0. Database'!C44 -> 18584 | C7: ='0. Database'!D44 -> 22272 | D7: ='0. Database'!E44 -> 25829 | E7: ='0. Database'!F44 -> 36036 | F7: ='0. Database'!G44 -> 37091 | G7: ='0. Database'!H44 -> 47971 | H7: ='0. Database'!I44 -> 54520 | I7: ='0. Database'!J44 -> 65124 | ... S7: ='0. Database'!T44 -> 490867.35
A8: META | B8: ='0. Database'!C61 -> 4222 | C8: ='0. Database'!D61 -> 5507.8 | D8: ='0. Database'!E61 -> 8607 | E8: ='0. Database'!F61 -> 16061 | F8: ='0. Database'!G61 -> 24216 | G8: ='0. Database'!H61 -> 29339 | H8: ='0. Database'!I61 -> 36312.5 | I8: ='0. Database'!J61 -> 38747 | ... S8: ='0. Database'!T61 -> 314478.51
A9: ORCL | B9: ='0. Database'!C79 -> 14225 | C9: ='0. Database'!D79 -> 14921 | D9: ='0. Database'!E79 -> 14336 | E9: ='0. Database'!F79 -> 13560 | F9: ='0. Database'!G79 -> 14125 | G9: ='0. Database'!H79 -> 15386 | H9: ='0. Database'!I79 -> 14551 | I9: ='0. Database'!J79 -> 13139 | ... S9: ='0. Database'!T79 -> 84964.12
A11: B. FCF ($mm)
A12: Company | B12: 2013A | C12: 2014A | D12: 2015A | E12: 2016A | F12: 2017A | G12: 2018A | H12: 2019A | I12: 2020A | J12: 2021A | K12: 2022A | L12: 2023A | M12: 2024A | N12: 2025E | O12: 2026E | P12: 2027E | Q12: 2028E | R12: 2029E | S12: 2030E
A13: MSFT | B13: ='0. Database'!C14 -> 24576 | C13: ='0. Database'!D14 -> 26746 | D13: ='0. Database'!E14 -> 23136 | E13: ='0. Database'!F14 -> 24393 | F13: ='0. Database'!G14 -> 29307 | G13: ='0. Database'!H14 -> 30284 | H13: ='0. Database'!I14 -> 35285 | I13: ='0. Database'!J14 -> 41675 | ... S13: ='0. Database'!T14 -> 133932.86
A14: AMZN | B14: ='0. Database'!C30 -> 2031 | C14: ='0. Database'!D30 -> 1949.4 | D14: ='0. Database'!E30 -> 7332.1 | E14: ='0. Database'!F30 -> 10535 | F14: ='0. Database'!G30 -> 8377 | G14: ='0. Database'!H30 -> 19402 | H14: ='0. Database'!I30 -> 25825 | I14: ='0. Database'!J30 -> 31018 | ... S14: ='0. Database'!T30 -> 88357.6
A15: GOOGL | B15: ='0. Database'!C45 -> 11226 | C15: ='0. Database'!D45 -> 11313 | D15: ='0. Database'!E45 -> 15914 | E15: ='0. Database'!F45 -> 25853 | F15: ='0. Database'!G45 -> 23907 | G15: ='0. Database'!H45 -> 22832 | H15: ='0. Database'!I45 -> 30972 | I15: ='0. Database'!J45 -> 42843 | ... S15: ='0. Database'!T45 -> 176367.33
A16: META | B16: ='0. Database'!C62 -> 2860 | C16: ='0. Database'!D62 -> 3676.8 | D16: ='0. Database'!E62 -> 6084 | E16: ='0. Database'!F62 -> 11570 | F16: ='0. Database'!G62 -> 17484 | G16: ='0. Database'!H62 -> 15359 | H16: ='0. Database'!I62 -> 21210.5 | I16: ='0. Database'!J62 -> 23632 | ... S16: ='0. Database'!T62 -> 105938.16
A17: ORCL | B17: ='0. Database'!C80 -> 13575 | C17: ='0. Database'!D80 -> 14341 | D17: ='0. Database'!E80 -> 12945 | E17: ='0. Database'!F80 -> 12371 | F17: ='0. Database'!G80 -> 12104 | G17: ='0. Database'!H80 -> 13650 | H17: ='0. Database'!I80 -> 12891 | I17: ='0. Database'!J80 -> 11575 | ... S17: ='0. Database'!T80 -> 18504.26
A19: E. Buybacks ($mm)
A20: Company | B20: 2013A | C20: 2014A | D20: 2015A | E20: 2016A | F20: 2017A | G20: 2018A | H20: 2019A | I20: 2020A | J20: 2021A | K20: 2022A | L20: 2023A | M20: 2024A | N20: 2025E | O20: 2026E | P20: 2027E | Q20: 2028E | R20: 2029E | S20: 2030E
A21: MSFT | B21: ='0. Database'!C15 -> 5360 | C21: ='0. Database'!D15 -> 7316 | D21: ='0. Database'!E15 -> 14443 | E21: ='0. Database'!F15 -> 15969 | F21: ='0. Database'!G15 -> 11788 | G21: ='0. Database'!H15 -> 10721 | H21: ='0. Database'!I15 -> 19543 | I21: ='0. Database'!J15 -> 22968 | ... S21: ='0. Database'!T15 -> 21047.23
A22: AMZN | B22: ='0. Database'!C31 -> 0 | C22: ='0. Database'!D31 -> 0 | D22: ='0. Database'!E31 -> 0 | E22: ='0. Database'!F31 -> 0 | F22: ='0. Database'!G31 -> 0 | G22: ='0. Database'!H31 -> 0 | H22: ='0. Database'!I31 -> 0 | I22: ='0. Database'!J31 -> 0 | ... S22: ='0. Database'!T31 -> 0
A23: GOOGL | B23: ='0. Database'!C46 -> 0 | C23: ='0. Database'!D46 -> 0 | D23: ='0. Database'!E46 -> 1827 | E23: ='0. Database'!F46 -> 3693 | F23: ='0. Database'!G46 -> 4846 | G23: ='0. Database'!H46 -> 9075 | H23: ='0. Database'!I46 -> 18396 | I23: ='0. Database'!J46 -> 31149 | ... S23: ='0. Database'!T46 -> 15000
A24: META | B24: ='0. Database'!C63 -> 0 | C24: ='0. Database'!D63 -> 0 | D24: ='0. Database'!E63 -> 0 | E24: ='0. Database'!F63 -> 0 | F24: ='0. Database'!G63 -> 1976 | G24: ='0. Database'!H63 -> 12879 | H24: ='0. Database'!I63 -> 4201 | I24: ='0. Database'!J63 -> 6272 | ... S24: ='0. Database'!T63 -> 6000
A25: ORCL | B25: ='0. Database'!C81 -> 11021 | C25: ='0. Database'!D81 -> 9813 | D25: ='0. Database'!E81 -> 8087 | E25: ='0. Database'!F81 -> 10440 | F25: ='0. Database'!G81 -> 3561 | G25: ='0. Database'!H81 -> 11347 | H25: ='0. Database'!I81 -> 36140 | I25: ='0. Database'!J81 -> 19240 | ... S25: ='0. Database'!T81 -> 0
A27: (Revenue)
A28: Company | B28: 2013A | C28: 2014A | D28: 2015A | E28: 2016A | F28: 2017A | G28: 2018A | H28: 2019A | I28: 2020A | J28: 2021A | K28: 2022A | L28: 2023A | M28: 2024A | N28: 2025E | O28: 2026E | P28: 2027E | Q28: 2028E | R28: 2029E | S28: 2030E
A29: MSFT | B29: ='0. Database'!C5 -> 77849 | C29: ='0. Database'!D5 -> 86833 | D29: ='0. Database'!E5 -> 93580 | E29: ='0. Database'!F5 -> 91963 | F29: ='0. Database'!G5 -> 96657 | G29: ='0. Database'!H5 -> 110360 | H29: ='0. Database'!I5 -> 125843 | I29: ='0. Database'!J5 -> 143015 | ... S29: ='0. Database'!T5 -> 624709.64
A30: AMZN | B30: ='0. Database'!C21 -> 74452 | C30: ='0. Database'!D21 -> 88988 | D30: ='0. Database'!E21 -> 107006 | E30: ='0. Database'!F21 -> 135987 | F30: ='0. Database'!G21 -> 177866 | G30: ='0. Database'!H21 -> 232887 | H30: ='0. Database'!I21 -> 280522 | I30: ='0. Database'!J21 -> 386064 | ... S30: ='0. Database'!T21 -> 1303433.7
A31: GOOGL | B31: ='0. Database'!C36 -> 55519 | C31: ='0. Database'!D36 -> 66001 | D31: ='0. Database'!E36 -> 74989 | E31: ='0. Database'!F36 -> 90272 | F31: ='0. Database'!G36 -> 110855 | G31: ='0. Database'!H36 -> 136819 | H31: ='0. Database'!I36 -> 161857 | I31: ='0. Database'!J36 -> 182527 | ... S31: ='0. Database'!T36 -> 941245.16
A32: META | B32: ='0. Database'!C53 -> 7872 | C32: ='0. Database'!D53 -> 12466 | D32: ='0. Database'!E53 -> 17928 | E32: ='0. Database'!F53 -> 27638 | F32: ='0. Database'!G53 -> 40653 | G32: ='0. Database'!H53 -> 55838 | H32: ='0. Database'!I53 -> 70697 | I32: ='0. Database'!J53 -> 85965 | ... S32: ='0. Database'!T53 -> 456699.5
A33: ORCL | B33: ='0. Database'!C71 -> 37253 | C33: ='0. Database'!D71 -> 38306 | D33: ='0. Database'!E71 -> 38253 | E33: ='0. Database'!F71 -> 37057 | F33: ='0. Database'!G71 -> 37899 | G33: ='0. Database'!H71 -> 39878 | H33: ='0. Database'!I71 -> 39526 | I33: ='0. Database'!J71 -> 39068 | ... S33: ='0. Database'!T71 -> 223043.24
A35: (NI)
A36: Company | B36: 2013A | C36: 2014A | D36: 2015A | E36: 2016A | F36: 2017A | G36: 2018A | H36: 2019A | I36: 2020A | J36: 2021A | K36: 2022A | L36: 2023A | M36: 2024A | N36: 2025E | O36: 2026E | P36: 2027E | Q36: 2028E | R36: 2029E | S36: 2030E
A37: MSFT | B37: ='0. Database'!C7 -> 21863 | C37: ='0. Database'!D7 -> 22074 | D37: ='0. Database'!E7 -> 12193 | E37: ='0. Database'!F7 -> 16798 | F37: ='0. Database'!G7 -> 25489 | G37: ='0. Database'!H7 -> 16571 | H37: ='0. Database'!I7 -> 39240 | I37: ='0. Database'!J7 -> 44281 | ... S37: ='0. Database'!T7 -> 258948.36
A38: AMZN | B38: ='0. Database'!C23 -> 273 | C38: ='0. Database'!D23 -> -240.6 | D38: ='0. Database'!E23 -> 596.1 | E38: ='0. Database'!F23 -> 2371 | F38: ='0. Database'!G23 -> 3033 | G38: ='0. Database'!H23 -> 10073 | H38: ='0. Database'!I23 -> 11588 | I38: ='0. Database'!J23 -> 21331 | ... S38: ='0. Database'!T23 -> 211925.99
A39: GOOGL | B39: ='0. Database'!C38 -> 12720 | C39: ='0. Database'!D38 -> 14136 | D39: ='0. Database'!E38 -> 16348 | E39: ='0. Database'!F38 -> 19478 | F39: ='0. Database'!G38 -> 12662 | G39: ='0. Database'!H38 -> 30736 | H39: ='0. Database'!I38 -> 34343 | I39: ='0. Database'!J38 -> 40269 | ... S39: ='0. Database'!T38 -> 285975.76
A40: META | B40: ='0. Database'!C55 -> 1491 | C40: ='0. Database'!D55 -> 2924.8 | D40: ='0. Database'!E55 -> 3669 | E40: ='0. Database'!F55 -> 10187.2 | F40: ='0. Database'!G55 -> 15919 | G40: ='0. Database'!H55 -> 22112 | H40: ='0. Database'!I55 -> 18484.5 | I40: ='0. Database'!J55 -> 29145 | ... S40: ='0. Database'!T55 -> 127804.37
A41: ORCL | B41: ='0. Database'!C73 -> 10926 | C41: ='0. Database'!D73 -> 10955 | D41: ='0. Database'!E73 -> 9938 | E41: ='0. Database'!F73 -> 8900 | F41: ='0. Database'!G73 -> 9334 | G41: ='0. Database'!H73 -> 3587 | H41: ='0. Database'!I73 -> 11083 | I41: ='0. Database'!J73 -> 10135 | ... S41: ='0. Database'!T73 -> 44104.48
A43: (Capex)
A44: Company | B44: 2013A | C44: 2014A | D44: 2015A | E44: 2016A | F44: 2017A | G44: 2018A | H44: 2019A | I44: 2020A | J44: 2021A | K44: 2022A | L44: 2023A | M44: 2024A | N44: 2025E | O44: 2026E | P44: 2027E | Q44: 2028E | R44: 2029E | S44: 2030E
A45: MSFT | B45: ='0. Database'!C12 -> 4257 | C45: ='0. Database'!D12 -> 5485 | D45: ='0. Database'!E12 -> 5944 | E45: ='0. Database'!F12 -> 8932 | F45: ='0. Database'!G12 -> 10200 | G45: ='0. Database'!H12 -> 13600 | H45: ='0. Database'!I12 -> 16900 | I45: ='0. Database'!J12 -> 19000 | ... S45: ='0. Database'!T12 -> 304616.04
A46: AMZN | B46: ='0. Database'!C28 -> 3443 | C46: ='0. Database'!D28 -> 4892 | D46: ='0. Database'!E28 -> 4588 | E46: ='0. Database'!F28 -> 6736 | F46: ='0. Database'!G28 -> 10057 | G46: ='0. Database'!H28 -> 11322 | H46: ='0. Database'!I28 -> 12690 | I46: ='0. Database'!J28 -> 35046 | ... S46: ='0. Database'!T28 -> 312722.81
...

Sheet 5. EPS & Margins
A1: EPS、Operating IncomeMargin&Profitability (2013-2030E)
A3: A. Operating Income ($mm)
A4: Company | B4: 2013A | C4: 2014A | D4: 2015A | E4: 2016A | F4: 2017A | G4: 2018A | H4: 2019A | I4: 2020A | J4: 2021A | K4: 2022A | L4: 2023A | M4: 2024A | N4: 2025E | O4: 2026E | P4: 2027E | Q4: 2028E | R4: 2029E | S4: 2030E
A5: MSFT | B5: ='0. Database'!C6 -> 26764 | C5: ='0. Database'!D6 -> 27759 | D5: ='0. Database'!E6 -> 13359 | E5: ='0. Database'!F6 -> 11756 | F5: ='0. Database'!G6 -> 11389 | G5: ='0. Database'!H6 -> 12924 | H5: ='0. Database'!I6 -> 16219 | I5: ='0. Database'!J6 -> 18724 | ... S5: ='0. Database'!T6 -> 108509.49
A6: AMZN | B6: ='0. Database'!C22 -> 673 | C6: ='0. Database'!D22 -> 458 | D6: ='0. Database'!E22 -> 1507 | E6: ='0. Database'!F22 -> 3108 | F6: ='0. Database'!G22 -> 4331 | G6: ='0. Database'!H22 -> 7296 | H6: ='0. Database'!I22 -> 9201 | I6: ='0. Database'!J22 -> 13531 | ... S6: ='0. Database'!T22 -> 152115.05
A7: GOOGL | B7: ='0. Database'!C37 -> 16260 | C7: ='0. Database'!D37 -> 18965 | D7: ='0. Database'!E37 -> 23319 | E7: ='0. Database'!F37 -> 27055 | F7: ='0. Database'!G37 -> 32456 | G7: ='0. Database'!H37 -> 43137 | H7: ='0. Database'!I37 -> 48999 | I7: ='0. Database'!J37 -> 54606 | ... S7: ='0. Database'!T37 -> 258679.36
A8: META | B8: ='0. Database'!C54 -> 2804 | C8: ='0. Database'!D54 -> 4994.8 | D8: ='0. Database'!E54 -> 6225 | E8: ='0. Database'!F54 -> 12427 | F8: ='0. Database'!G54 -> 20202 | G8: ='0. Database'!H54 -> 24913 | H8: ='0. Database'!I54 -> 28489 | I8: ='0. Database'!J54 -> 39294 | ... S8: ='0. Database'!T54 -> 192345.26
A9: ORCL | B9: ='0. Database'!C72 -> 14684 | C9: ='0. Database'!D72 -> 14758 | D9: ='0. Database'!E72 -> 13870 | E9: ='0. Database'!F72 -> 12604 | F9: ='0. Database'!G72 -> 12710 | G9: ='0. Database'!H72 -> 13264 | H9: ='0. Database'!I72 -> 13535 | I9: ='0. Database'!J72 -> 13897 | ... S9: ='0. Database'!T72 -> 57952.82
A11: C. Net Income ($mm)
A12: Company | B12: 2013A | C12: 2014A | D12: 2015A | E12: 2016A | F12: 2017A | G12: 2018A | H12: 2019A | I12: 2020A | J12: 2021A | K12: 2022A | L12: 2023A | M12: 2024A | N12: 2025E | O12: 2026E | P12: 2027E | Q12: 2028E | R12: 2029E | S12: 2030E
A13: MSFT | B13: ='0. Database'!C7 -> 21863 | C13: ='0. Database'!D7 -> 22074 | D13: ='0. Database'!E7 -> 12193 | E13: ='0. Database'!F7 -> 16798 | F13: ='0. Database'!G7 -> 25489 | G13: ='0. Database'!H7 -> 16571 | H13: ='0. Database'!I7 -> 39240 | I13: ='0. Database'!J7 -> 44281 | ... S13: ='0. Database'!T7 -> 258948.36
A14: AMZN | B14: ='0. Database'!C23 -> 273 | C14: ='0. Database'!D23 -> -240.6 | D14: ='0. Database'!E23 -> 596.1 | E14: ='0. Database'!F23 -> 2371 | F14: ='0. Database'!G23 -> 3033 | G14: ='0. Database'!H23 -> 10073 | H14: ='0. Database'!I23 -> 11588 | I14: ='0. Database'!J23 -> 21331 | ... S14: ='0. Database'!T23 -> 211925.99
A15: GOOGL | B15: ='0. Database'!C38 -> 12720 | C15: ='0. Database'!D38 -> 14136 | D15: ='0. Database'!E38 -> 16348 | E15: ='0. Database'!F38 -> 19478 | F15: ='0. Database'!G38 -> 12662 | G15: ='0. Database'!H38 -> 30736 | H15: ='0. Database'!I38 -> 34343 | I15: ='0. Database'!J38 -> 40269 | ... S15: ='0. Database'!T38 -> 285975.76
A16: META | B16: ='0. Database'!C55 -> 1491 | C16: ='0. Database'!D55 -> 2924.8 | D16: ='0. Database'!E55 -> 3669 | E16: ='0. Database'!F55 -> 10187.2 | F16: ='0. Database'!G55 -> 15919 | G16: ='0. Database'!H55 -> 22112 | H16: ='0. Database'!I55 -> 18484.5 | I16: ='0. Database'!J55 -> 29145 | ... S16: ='0. Database'!T55 -> 127804.37
A17: ORCL | B17: ='0. Database'!C73 -> 10926 | C17: ='0. Database'!D73 -> 10955 | D17: ='0. Database'!E73 -> 9938 | E17: ='0. Database'!F73 -> 8900 | F17: ='0. Database'!G73 -> 9334 | G17: ='0. Database'!H73 -> 3587 | H17: ='0. Database'!I73 -> 11083 | I17: ='0. Database'!J73 -> 10135 | ... S17: ='0. Database'!T73 -> 44104.48
A19: E. EPS ($)
A20: Company | B20: 2013A | C20: 2014A | D20: 2015A | E20: 2016A | F20: 2017A | G20: 2018A | H20: 2019A | I20: 2020A | J20: 2021A | K20: 2022A | L20: 2023A | M20: 2024A | N20: 2025E | O20: 2026E | P20: 2027E | Q20: 2028E | R20: 2029E | S20: 2030E
A21: MSFT | B21: ='0. Database'!C8 -> 2.58 | C21: ='0. Database'!D8 -> 2.63 | D21: ='0. Database'!E8 -> 1.48 | E21: ='0. Database'!F8 -> 2.1 | F21: ='0. Database'!G8 -> 2.71 | G21: ='0. Database'!H8 -> 2.13 | H21: ='0. Database'!I8 -> 5.06 | I21: ='0. Database'!J8 -> 5.76 | ... S21: ='0. Database'!T8 -> 31.49
A22: AMZN | B22: ='0. Database'!C24 -> 0.03 | C22: ='0. Database'!D24 -> -0.03 | D22: ='0. Database'!E24 -> 0.06 | E22: ='0. Database'!F24 -> 0.25 | F22: ='0. Database'!G24 -> 0.23 | G22: ='0. Database'!H24 -> 1.01 | H22: ='0. Database'!I24 -> 1.15 | I22: ='0. Database'!J24 -> 2.09 | ... S22: ='0. Database'!T24 -> 17.13
A23: GOOGL | B23: ='0. Database'!C39 -> 0.9 | C23: ='0. Database'!D39 -> 1.01 | D23: ='0. Database'!E39 -> 1.14 | E23: ='0. Database'!F39 -> 1.39 | F23: ='0. Database'!G39 -> 1.6 | G23: ='0. Database'!H39 -> 2.19 | H23: ='0. Database'!I39 -> 2.33 | I23: ='0. Database'!J39 -> 2.93 | ... S23: ='0. Database'!T39 -> 26.04
A24: META | B24: ='0. Database'!C56 -> 0.6 | C24: ='0. Database'!D56 -> 1.1 | D24: ='0. Database'!E56 -> 1.29 | E24: ='0. Database'!F56 -> 3.49 | F24: ='0. Database'!G56 -> 6.16 | G24: ='0. Database'!H56 -> 7.57 | H24: ='0. Database'!I56 -> 8.56 | I24: ='0. Database'!J56 -> 9.78 | ... S24: ='0. Database'!T56 -> 57
A25: ORCL | B25: ='0. Database'!C74 -> 2.26 | C25: ='0. Database'!D74 -> 2.38 | D25: ='0. Database'!E74 -> 2.21 | E25: ='0. Database'!F74 -> 2.07 | F25: ='0. Database'!G74 -> 2.21 | G25: ='0. Database'!H74 -> 0.9 | H25: ='0. Database'!I74 -> 2.97 | I25: ='0. Database'!J74 -> 3.08 | ... S25: ='0. Database'!T74 -> 16.76
A27: G. Diluted Shares (mm)
A28: Company | B28: 2013A | C28: 2014A | D28: 2015A | E28: 2016A | F28: 2017A | G28: 2018A | H28: 2019A | I28: 2020A | J28: 2021A | K28: 2022A | L28: 2023A | M28: 2024A | N28: 2025E | O28: 2026E | P28: 2027E | Q28: 2028E | R28: 2029E | S28: 2030E
A29: MSFT | B29: ='0. Database'!C9 -> 8375 | C29: ='0. Database'!D9 -> 8299 | D29: ='0. Database'!E9 -> 8177 | E29: ='0. Database'!F9 -> 7925 | F29: ='0. Database'!G9 -> 7746 | G29: ='0. Database'!H9 -> 7700 | H29: ='0. Database'!I9 -> 7673 | I29: ='0. Database'!J9 -> 7610 | ... S29: ='0. Database'!T9 -> 7345.29
A30: AMZN | B30: ='0. Database'!C25 -> 9140 | C30: ='0. Database'!D25 -> 9240 | D30: ='0. Database'!E25 -> 9340 | E30: ='0. Database'!F25 -> 9480 | F30: ='0. Database'!G25 -> 9600 | G30: ='0. Database'!H25 -> 9740 | H30: ='0. Database'!I25 -> 9880 | I30: ='0. Database'!J25 -> 10000 | ... S30: ='0. Database'!T25 -> 11258.12
A31: GOOGL | B31: ='0. Database'!C40 -> 13313.88 | C31: ='0. Database'!D40 -> 13518.7 | D31: ='0. Database'!E40 -> 13692.52 | E31: ='0. Database'!F40 -> 13842.18 | F31: ='0. Database'!G40 -> 13858.02 | G31: ='0. Database'!H40 -> 13902.8 | H31: ='0. Database'!I40 -> 13851.92 | I31: ='0. Database'!J40 -> 13616.32 | ... S31: ='0. Database'!T40 -> 12193.09
A32: META | B32: ='0. Database'!C57 -> 2420 | C32: ='0. Database'!D57 -> 2614 | D32: ='0. Database'!E57 -> 2803 | E32: ='0. Database'!F57 -> 2863 | F32: ='0. Database'!G57 -> 2901 | G32: ='0. Database'!H57 -> 2890 | H32: ='0. Database'!I57 -> 2854 | I32: ='0. Database'!J57 -> 2851 | ... S32: ='0. Database'!T57 -> 2579.74
A33: ORCL | B33: ='0. Database'!C75 -> 4769 | C33: ='0. Database'!D75 -> 4528 | D33: ='0. Database'!E75 -> 4404 | E33: ='0. Database'!F75 -> 4221 | F33: ='0. Database'!G75 -> 4115 | G33: ='0. Database'!H75 -> 4121 | H33: ='0. Database'!I75 -> 3634 | I33: ='0. Database'!J75 -> 3211 | ... S33: ='0. Database'!T75 -> 3041.61
A35: H. SBC ($mm)
A36: Company | B36: 2013A | C36: 2014A | D36: 2015A | E36: 2016A | F36: 2017A | G36: 2018A | H36: 2019A | I36: 2020A | J36: 2021A | K36: 2022A | L36: 2023A | M36: 2024A | N36: 2025E | O36: 2026E | P36: 2027E | Q36: 2028E | R36: 2029E | S36: 2030E
A37: MSFT | B37: ='0. Database'!C10 -> 2406 | C37: ='0. Database'!D10 -> 2446 | D37: ='0. Database'!E10 -> 2574 | E37: ='0. Database'!F10 -> 2668 | F37: ='0. Database'!G10 -> 3266 | G37: ='0. Database'!H10 -> 3940 | H37: ='0. Database'!I10 -> 4652 | I37: ='0. Database'!J10 -> 5289 | ... S37: ='0. Database'!T10 -> 14871.62
A38: AMZN | B38: ='0. Database'!C26 -> -1134 | C38: ='0. Database'!D26 -> -1497 | D38: ='0. Database'!E26 -> -2120 | E38: ='0. Database'!F26 -> -2975 | F38: ='0. Database'!G26 -> -4214 | G38: ='0. Database'!H26 -> -5418 | H38: ='0. Database'!I26 -> -6864 | I38: ='0. Database'!J26 -> -9208 | ... S38: ='0. Database'!T26 -> -20744.82
A39: GOOGL | B39: ='0. Database'!C41 -> -3268 | C39: ='0. Database'!D41 -> -4175 | D39: ='0. Database'!E41 -> -4903 | E39: ='0. Database'!F41 -> -6703 | F39: ='0. Database'!G41 -> -7679 | G39: ='0. Database'!H41 -> -9353 | H39: ='0. Database'!I41 -> -10794 | I39: ='0. Database'!J41 -> -12991 | ... S39: ='0. Database'!T41 -> -35339.95
A40: META | B40: ='0. Database'!C58 -> -906 | C40: ='0. Database'!D58 -> -1837 | D40: ='0. Database'!E58 -> -2969 | E40: ='0. Database'!F58 -> -3202 | F40: ='0. Database'!G58 -> -3723 | G40: ='0. Database'!H58 -> -4152 | H40: ='0. Database'!I58 -> -4835 | I40: ='0. Database'!J58 -> -6536 | ... S40: ='0. Database'!T58 -> -28834.48
A41: ORCL | B41: ='0. Database'!C76 -> 755 | C41: ='0. Database'!D76 -> 805 | D41: ='0. Database'!E76 -> 933 | E41: ='0. Database'!F76 -> 1037 | F41: ='0. Database'!G76 -> 1350 | G41: ='0. Database'!H76 -> 1607 | H41: ='0. Database'!I76 -> 1653 | I41: ='0. Database'!J76 -> 1590 | ... S41: ='0. Database'!T76 -> 11212.32
A43: (Revenue)
A44: Company | B44: 2013A | C44: 2014A | D44: 2015A | E44: 2016A | F44: 2017A | G44: 2018A | H44: 2019A | I44: 2020A | J44: 2021A | K44: 2022A | L44: 2023A | M44: 2024A | N44: 2025E | O44: 2026E | P44: 2027E | Q44: 2028E | R44: 2029E | S44: 2030E
A45: MSFT | B45: ='0. Database'!C5 -> 77849 | C45: ='0. Database'!D5 -> 86833 | D45: ='0. Database'!E5 -> 93580 | E45: ='0. Database'!F5 -> 91963 | F45: ='0. Database'!G5 -> 96657 | G45: ='0. Database'!H5 -> 110360 | H45: ='0. Database'!I5 -> 125843 | I45: ='0. Database'!J5 -> 143015 | ... S45: ='0. Database'!T5 -> 624709.64
A46: AMZN | B46: ='0. Database'!C21 -> 74452 | C46: ='0. Database'!D21 -> 88988 | D46: ='0. Database'!E21 -> 107006 | E46: ='0. Database'!F21 -> 135987 | F46: ='0. Database'!G21 -> 177866 | G46: ='0. Database'!H21 -> 232887 | H46: ='0. Database'!I21 -> 280522 | I46: ='0. Database'!J21 -> 386064 | ... S46: ='0. Database'!T21 -> 1303433.7
...

Sheet 6. Depreciation Sensitivity
A1: D&AAnalysis: Based on MSFT Actual PP&E Breakdown's Proxy
A3: A. MSFT Actual PP&E/Capex Breakdown (SEC filing)
A4: MSFT Capex Sheet actual PP&E analysis. Company-level asset breakdown.
A5: Metric (MSFT FY) | B5: FY2020A | C5: FY2021A | D5: FY2022A | E5: FY2023A | F5: FY2024A | G5: FY2025A | H5: FY2026E | I5: FY2027E | J5: FY2028E | K5: FY2029E | L5: FY2030E
A6: IT Equipment Capex ($mm) | B6: 7438 | C6: 9989 | D6: 9381 | E6: 14330 | F6: 18819 | G6: 41432 | H6: 85947 | I6: 144612 | J6: 166321 | K6: 174122 | L6: 176677
A7: Buildings Capex ($mm) | B7: 4377 | C7: 6197 | D7: 7805 | E7: 10301 | F7: 13768 | G7: 36747 | H7: 50201 | I7: 83886 | J7: 100380 | K7: 105090 | L7: 106632
A8: Finance Leases Capex ($mm) | B8: 3330 | C8: 3736 | D8: 3281 | E8: 3150 | F8: 11710 | G8: 21628 | H8: 32878 | I8: 42085 | J8: 37876 | K8: 30301 | L8: 21211
A9: Capex ($mm) | B9: 396 | C9: 2380 | D9: 2525 | E9: 2053 | F9: 3823 | G9: 10020 | H9: 9745 | I9: 16765 | J9: 20059 | K9: 20999 | L9: 21308
A10: Total Capex ($mm) | B10: 19000 | C10: 24200 | D10: 29200 | E10: 31900 | F10: 55700 | G10: 88200 | H10: 145871 | I10: 245263 | J10: 286760 | K10: 300211 | L10: 304616
A11: IT Equipment % of Capex | B11: 0.39 | C11: 0.41 | D11: 0.32 | E11: 0.45 | F11: 0.34 | G11: 0.47 | H11: 0.59 | I11: 0.59 | J11: 0.58 | K11: 0.58 | L11: 0.58
A12: IT Equipment D&A ($mm) | E12: 2231 | F12: 10063 | G12: 14563 | H12: 23911 | I12: 43743 | J12: 68286 | K12: 94877 | L12: 121252
A13: Buildings D&A ($mm) | E13: 680 | F13: 3304 | G13: 5132 | H13: 8149 | I13: 12605 | J13: 18775 | K13: 25426 | L13: 32434
A14: Total D&A ($mm) | B14: 10700 | C14: 9300 | D14: 12600 | E14: 11000 | F14: 15200 | G14: 22000 | H14: 34839 | I14: 59542 | J14: 92995 | K14: 129654 | L14: 165840
A15: IT D&A % of TotalD&A | E15: 0.2 | F15: 0.66 | G15: 0.66 | H15: 0.69 | I15: 0.73 | J15: 0.73 | K15: 0.73 | L15: 0.73
A16: IT EquipmentUseful Life | B16: 6 | C16: 6 | D16: 6 | E16: 6 | F16: 6 | G16: 6 | H16: 6 | I16: 6 | J16: 6 | K16: 6 | L16: 6
A17: BuildingsUseful Life | B17: 15 | C17: 15 | D17: 15 | E17: 15 | F17: 15 | G17: 15 | H17: 15 | I17: 15 | J17: 15 | K17: 15 | L17: 15
A19: 📌 Key Finding: IT Equipment pre-AI 's ~35% jumped to AI 's 59%. IT contributes 66-73% 'sTotalD&A (because IT 6Year vs Buildings 15Year). This is Burry thesis attack surface.
A21: B. IT EquipmentShare ofEstimation: MSFT Hard Data → 4 Proxy (⚠️ Estimate)
A22: Company | B22: IT EquipmentShare of Capex | C22: Estimation Basis (Confidence) | D22: IT Equipment Useful Life | E22: Buildings+ Share ofCapex% | F22: Buildings Useful Life | G22: (/)% | H22: Useful Life
A23: MSFT | B23: 0.59 | C23: ✅ Hard Data: Capex sheet Row 90 = 50.1% gross PP&E; capex share 59% | D23: 6 | E23: 0.36 | F23: 15 | G23: 0.05 | H23: 10
A24: AMZN | B24: 0.42 | C24: ⚠️ : 10-K Equipment $185B //; AWS ~40-45% (Behind the Balance SheetAnalysis) | D24: 5 | E24: 0.35 | F24: 18 | G24: 0.23 | H24: 8
A25: GOOGL | B25: 0.57 | C25: ⚠️ : MBI Deep Dives IT assets ~45% of PP&E; capex share (TPUIT) | D25: 6 | E25: 0.35 | F25: 20 | G25: 0.08 | H25: 10
A26: META | B26: 0.62 | C26: ⚠️ : Company, /; 1.3M GPU; server+networkPP&E (MBI) | D26: 5.5 | E26: 0.33 | F26: 22 | G26: 0.05 | H26: 10
A27: ORCL | B27: 0.5 | C27: ⚠️ : OCI, buildings; But+GPU; ITShare of | D27: 5.5 | E27: 0.4 | F27: 20 | G27: 0.1 | H27: 10
A30: C. 2026E / 2027E Base Data (From Database Sheet)
A31: Company | B31: 2026E Capex ($mm) | C31: 2026E D&A ($mm) | D31: 2026E NI ($mm) | E31: 2026E EPS ($) | F31: Shares (mm) | G31: Tax Rate (Editable) | H31: Depr Base = Capex×wtd life | I31: 2027E Capex ($mm) | J31: 2027E D&A ($mm) | K31: 2027E NI ($mm) | L31: 2027E EPS ($)
A32: MSFT | B32: ='0. Database'!P12 -> 145871.3 | C32: ='0. Database'!P11 -> 42005.11 | D32: ='0. Database'!P7 -> 129372.86 | E32: ='0. Database'!P8 -> 17.28 | F32: ='0. Database'!P9 -> 7425.9 | G32: 0.18 | H32: =$C$32*($B$23*$D$23+$E$23*$F$23+$G$23*$H$23) -> 396528.24 | I32: ='0. Database'!Q12 -> 245263.45 | J32: ='0. Database'!Q11 -> 55415.31 | K32: ='0. Database'!Q7 -> 144971.56 | L32: ='0. Database'!Q8 -> 19.42
A33: AMZN | B33: ='0. Database'!P28 -> 200104.98 | C33: ='0. Database'!P27 -> 84391.58 | D33: ='0. Database'!P23 -> 98333.72 | E33: ='0. Database'!P24 -> 8.79 | F33: ='0. Database'!P25 -> 10862.95 | G33: 0.2 | H33: =$C$33*($B$24*$D$24+$E$24*$F$24+$G$24*$H$24) -> 864169.78 | I33: ='0. Database'!Q28 -> 270141.72 | J33: ='0. Database'!Q27 -> 107181.82 | K33: ='0. Database'!Q23 -> 116218.4 | L33: ='0. Database'!Q24 -> 10.03
A34: GOOGL | B34: ='0. Database'!P43 -> 185234.28 | C34: ='0. Database'!P42 -> 42874.7 | D34: ='0. Database'!P38 -> 168543.28 | E34: ='0. Database'!P39 -> 14.19 | F34: ='0. Database'!P40 -> 12096.35 | G34: 0.16 | H34: =$C$34*($B$25*$D$25+$E$25*$F$25+$G$25*$H$25) -> 481054.13 | I34: ='0. Database'!Q43 -> 259327.99 | J34: ='0. Database'!Q42 -> 69582.72 | K34: ='0. Database'!Q38 -> 174626.97 | L34: ='0. Database'!Q39 -> 14.69
A35: META | B35: ='0. Database'!P60 -> 135583.71 | C35: ='0. Database'!P59 -> 29596.55 | D35: ='0. Database'!P55 -> 85782.86 | E35: ='0. Database'!P56 -> 32.2 | F35: ='0. Database'!P57 -> 2541.31 | G35: 0.13 | H35: =$C$35*($B$26*$D$26+$E$26*$F$26+$G$26*$H$26) -> 330593.46 | I35: ='0. Database'!Q60 -> 165714.44 | J35: ='0. Database'!Q59 -> 43105.48 | K35: ='0. Database'!Q55 -> 91160.94 | L35: ='0. Database'!Q56 -> 34.9
A36: ORCL | B36: ='0. Database'!P78 -> 51882 | C36: ='0. Database'!P77 -> 9142.32 | D36: ='0. Database'!P73 -> 15820.55 | E36: ='0. Database'!P74 -> 5.85 | F36: ='0. Database'!P75 -> 2864.8 | G36: 0.2 | H36: =$C$36*($B$27*$D$27+$E$27*$F$27+$G$27*$H$27) -> 107422.26 | I36: ='0. Database'!Q78 -> 52141.41 | J36: ='0. Database'!Q77 -> 13499.83 | K36: ='0. Database'!Q73 -> 13363.1 | L36: ='0. Database'!Q74 -> 6.26
A39: D. Core Sensitivity: Compress Only IT Equipment (Buildings/) — Straight-Line
A40: Logic: D&A = ITD&A + Buildings + . ITBurry.
A41: IT Equipment = 6 Year (Buildings/)
A42: Company | B42: ITD&A ($mm) | C42: BuildingsD&A (,$mm) | D42: D&A (,$mm) | E42: New Total D&A ($mm) | F42: Current D&A ($mm) | G42: ΔD&A ($mm) | H42: Δ ($mm) | I42: Adj NI ($mm) | J42: Adj EPS ($) | K42: EPS Change%
A43: MSFT | B43: =$H$32*$B$23/6 -> 38991.943 | C43: =$H$32*$E$23/$F$23 -> 9516.6777 | D43: =$H$32*$G$23/$H$23 -> 1982.6412 | E43: =$B$43+$C$43+$D$43 -> 50491.262 | F43: =$C$32 -> 42005.11 | G43: =$E$43-$C$32 -> 8486.1524 | H43: =$G$43*(1-$G$32) -> 6958.6449 | I43: =$D$32-$H$43 -> 122414.22 | J43: =$I$43/$F$32 -> 16.484765 | K43: =IFERROR($J$43/$E$32-1,"") -> -0.046020554
A44: AMZN | B44: =$H$33*$B$24/6 -> 60491.885 | C44: =$H$33*$E$24/$F$24 -> 16803.301 | D44: =$H$33*$G$24/$H$24 -> 24844.881 | E44: =$B$44+$C$44+$D$44 -> 102140.07 | F44: =$C$33 -> 84391.58 | G44: =$E$44-$C$33 -> 17748.487 | H44: =$G$44*(1-$G$33) -> 14198.79 | I44: =$D$33-$H$44 -> 84134.93 | J44: =$I$44/$F$33 -> 7.7451273 | K44: =IFERROR($J$44/$E$33-1,"") -> -0.11887062
A45: GOOGL | B45: =$H$34*$B$25/6 -> 45700.143 | C45: =$H$34*$E$25/$F$25 -> 8418.4473 | D45: =$H$34*$G$25/$H$25 -> 3848.4331 | E45: =$B$45+$C$45+$D$45 -> 57967.023 | F45: =$C$34 -> 42874.7 | G45: =$E$45-$C$34 -> 15092.323 | H45: =$G$45*(1-$G$34) -> 12677.551 | I45: =$D$34-$H$45 -> 155865.73 | J45: =$I$45/$F$34 -> 12.885352 | K45: =IFERROR($J$45/$E$34-1,"") -> -0.091941362
A46: META | B46: =$H$35*$B$26/6 -> 34161.325 | C46: =$H$35*$E$26/$F$26 -> 4958.902 | D46: =$H$35*$G$26/$H$26 -> 1652.9673 | E46: =$B$46+$C$46+$D$46 -> 40773.194 | F46: =$C$35 -> 29596.55 | G46: =$E$46-$C$35 -> 11176.644 | H46: =$G$46*(1-$G$35) -> 9723.6801 | I46: =$D$35-$H$46 -> 76059.18 | J46: =$I$46/$F$35 -> 29.929123 | K46: =IFERROR($J$46/$E$35-1,"") -> -0.070524127
A47: ORCL | B47: =$H$36*$B$27/6 -> 8951.855 | C47: =$H$36*$E$27/$F$27 -> 2148.4452 | D47: =$H$36*$G$27/$H$27 -> 1074.2226 | E47: =$B$47+$C$47+$D$47 -> 12174.523 | F47: =$C$36 -> 9142.32 | G47: =$E$47-$C$36 -> 3032.2028 | H47: =$G$47*(1-$G$36) -> 2425.7622 | I47: =$D$36-$H$47 -> 13394.788 | J47: =$I$47/$F$36 -> 4.675645 | K47: =IFERROR($J$47/$E$36-1,"") -> -0.20074445
...

Sheet 7. SP500 AI EPS Split
A1: S&P 500: AI vs Non-AI EPSBreakdown + Dual P/E Valuation
A3: S&P 500 EPS — Bloomberg Consensus ($)
A4: EPS: FactSet actual (2018-2024), sell-side/consensus estimates (2025+). Capex/Buybacks: sell-side data (May 7 2026 report). Yellow = editable.
A5: Metric | B5: 2018A | C5: 2019A | D5: 2020A | E5: 2021A | F5: 2022A | G5: 2023A | H5: 2024A | I5: 2025A | J5: 2026E | K5: 2027E | L5: 2028E (ext) | M5: 2029E (ext) | N5: 2030E (ext)
A6: S&P 500 Operating EPS ($) | B6: 160 | C6: 165 | D6: 142 | E6: 200 | F6: 224 | G6: 222 | H6: 239 | I6: 269 | J6: 337 | K6: 386 | L6: 420 | M6: 450 | N6: 478
A7: S&P 500Capex ($B) — sell-side data | B7: 644 | C7: 697 | D7: 591 | E7: 739 | F7: 892 | G7: 958 | H7: 1077 | I7: 1296 | J7: 1724 | K7: 2103 | L7: 2400 | M7: 2600 | N7: 2750
A8: AICapex ($B) — 5 cos | B8: 50 | C8: 55 | D8: 60 | E8: 86 | F8: 158 | G8: 154 | H8: 237 | I8: 412 | J8: 755 | K8: 892 | L8: 950 | M8: 980 | N8: 1000
A9: S&P 500 Buybacks ($B) — sell-side data | B9: 770 | C9: 729 | D9: 520 | E9: 919 | F9: 950 | G9: 823 | H9: 982 | I9: 1066 | J9: 1098 | K9: 1153 | L9: 1200 | M9: 1250 | N9: 1300
A11: B. AI-Driven EPS Estimation: Hyperscaler Capex → Supply Chain Profit → S&P 500 EPS
A12: Logic: Hyperscaler capex = revenue for NVDA/AVGO/MU/ANET/etc. Their net margin × capex = AI-driven NI. Divide by S&P 500 share count ≈ AI EPS.
A13: Metric | B13: 2018A | C13: 2019A | D13: 2020A | E13: 2021A | F13: 2022A | G13: 2023A | H13: 2024A | I13: 2025A | J13: 2026E | K13: 2027E | L13: 2028E | M13: 2029E | N13: 2030E
A14: % of Hyp Capex → S&P 500 co revenue (editable) | B14: 0.55 | C14: 0.55 | D14: 0.55 | E14: 0.55 | F14: 0.55 | G14: 0.55 | H14: 0.55 | I14: 0.6 | J14: 0.65 | K14: 0.65 | L14: 0.65 | M14: 0.63 | N14: 0.6
A15: Wtd avg net margin of AI supply chain (editable) | B15: 0.2 | C15: 0.2 | D15: 0.2 | E15: 0.22 | F15: 0.25 | G15: 0.3 | H15: 0.35 | I15: 0.4 | J15: 0.45 | K15: 0.42 | L15: 0.38 | M15: 0.35 | N15: 0.33
A16: AI Revenue to S&P 500 cos ($B) | B16: =B8*B14 -> 27.5 | C16: =C8*C14 -> 30.25 | D16: =D8*D14 -> 33 | E16: =E8*E14 -> 47.3 | F16: =F8*F14 -> 86.9 | G16: =G8*G14 -> 84.7 | H16: =H8*H14 -> 130.35 | I16: =I8*I14 -> 247.2 | ... N16: =N8*N14 -> 600
A17: AI Net Income to S&P 500 cos ($B) | B17: =B16*B15 -> 5.5 | C17: =C16*C15 -> 6.05 | D17: =D16*D15 -> 6.6 | E17: =E16*E15 -> 10.406 | F17: =F16*F15 -> 21.725 | G17: =G16*G15 -> 25.41 | H17: =H16*H15 -> 45.6225 | I17: =I16*I15 -> 98.88 | ... N17: =N16*N15 -> 198
A18: S&P 500TotalNet Income ($B) ≈ EPS × 8.8B shares (S&P 500 Index Divisor) | B18: =B6*8.8 -> 1408 | C18: =C6*8.8 -> 1452 | D18: =D6*8.8 -> 1249.6 | E18: =E6*8.8 -> 1760 | F18: =F6*8.8 -> 1971.2 | G18: =G6*8.8 -> 1953.6 | H18: =H6*8.8 -> 2103.2 | I18: =I6*8.8 -> 2367.2 | ... N18: =N6*8.8 -> 4206.4
A19: AI-Driven EPS ($) = AI NI / 8.8B shares (S&P 500 Index Divisor) | B19: =B17/8.8 -> 0.625 | C19: =C17/8.8 -> 0.6875 | D19: =D17/8.8 -> 0.75 | E19: =E17/8.8 -> 1.1825 | F19: =F17/8.8 -> 2.46875 | G19: =G17/8.8 -> 2.8875 | H19: =H17/8.8 -> 5.184375 | I19: =I17/8.8 -> 11.236364 | ... N19: =N17/8.8 -> 22.5
