Workbook

Sheet 0. Database
A1: Centralized Database (USD mm except EPS/shares) — Blue = input
A3: Ticker | B3: Metric | C3: 2013A | D3: 2014A | E3: 2015A | F3: 2016A | G3: 2017A | H3: 2018A | I3: 2019A | J3: 2020A | K3: 2021A | L3: 2022A | M3: 2023A | N3: 2024A | O3: 2025E | P3: 2026E | Q3: 2027E | R3: 2028E | S3: 2029E | T3: 2030E
A4: MSFT (FY(Jun))
A5: MSFT | B5: Revenue | C5: 77849 | D5: 86833 | E5: 93580 | F5: 85320 | G5: 96571 | H5: 110360 | I5: 125843 | J5: 143015 | K5: 168088 | L5: 198270 | M5: 211915 | N5: 245122 | O5: 281724 | P5: 329440.24 | Q5: 387103.71 | R5: 463474.17 | S5: 553714.52 | T5: 652772.62
A6: MSFT | B6: Operating Income | C6: 26764 | D6: 27759 | E6: 18161 | F6: 20182 | G6: 29025 | H6: 35058 | I6: 42959 | J6: 52959 | K6: 69916 | L6: 83383 | M6: 88523 | N6: 109433 | O6: 128528 | P6: 153454.1 | Q6: 179274.53 | R6: 217551.82 | S6: 266239.28 | T6: 318436.19
A7: MSFT | B7: Net Income | C7: 21863 | D7: 22074 | E7: 12193 | F7: 16798 | G7: 25489 | H7: 16571 | I7: 39240 | J7: 44281 | K7: 61271 | L7: 72738 | M7: 72361 | N7: 88136 | O7: 101832 | P7: 129372.86 | Q7: 144971.56 | R7: 175683.92 | S7: 215472.22 | T7: 258948.36
A8: MSFT | B8: EPS | C8: 2.63 | D8: 2.66 | E8: 2.59 | F8: 2.79 | G8: 3.29 | H8: 3.88 | I8: 4.75 | J8: 5.76 | K8: 7.97 | L8: 9.21 | M8: 9.81 | N8: 11.8 | O8: 13.91 | P8: 16.75 | Q8: 19.47 | R8: 23.61 | S8: 28.97 | T8: 34.82
A9: MSFT | B9: Diluted Shares (mm) | C9: 8452.25 | D9: 8385.25 | E9: 8254 | F9: 8012.25 | G9: 7831.25 | H9: 7792.25 | I9: 7752 | J9: 7681.5 | K9: 7607.75 | L9: 7540.5 | M9: 7472.25 | N9: 7468.5 | O9: 7467.75 | P9: 7453.97 | Q9: 7446.49 | R9: 7440.67 | S9: 7436.61 | T9: 7436.22
A10: MSFT | B10: SBC | C10: 2406 | D10: 2446 | E10: 2574 | F10: 2668 | G10: 3266 | H10: 3940 | I10: 4652 | J10: 5289 | K10: 6118 | L10: 7502 | M10: 9611 | N10: 10734 | O10: 11974 | P10: 12189 | Q10: 10478.4 | R10: 11434.24 | S10: 12826.56 | T10: 14871.62
A11: MSFT | B11: D&A | C11: 3339 | D11: 4245 | E11: 5400 | F11: 5878 | G11: 7800 | H11: 9900 | I11: 11600 | J11: 12300 | K11: 10900 | L11: 14600 | M11: 13500 | N11: 20000 | O11: 28000 | P11: 39638.96 | Q11: 62441.96 | R11: 94995.43 | S11: 131504.45 | T11: 167239.58
A12: MSFT | B12: Capex | C12: 4257 | D12: 5485 | E12: 5944 | F12: 8932 | G12: 10200 | H12: 13600 | I12: 16900 | J12: 19000 | K12: 24200 | L12: 29200 | M12: 31900 | N12: 55700 | O12: 88200 | P12: 145871.3 | Q12: 245263.45 | R12: 286760.35 | S12: 300210.91 | T12: 304616.04
A13: MSFT | B13: CFO | C13: 28833 | D13: 32231 | E13: 29080 | F13: 33325 | G13: 39507 | H13: 43884 | I13: 52185 | J13: 60675 | K13: 76740 | L13: 89035 | M13: 87582 | N13: 118548 | O13: 136162 | P13: 174558.18 | Q13: 232097.78 | R13: 294570.35 | S13: 359672.36 | T13: 438548.9
A14: MSFT | B14: FCF | C14: 24576 | D14: 26746 | E14: 23136 | F14: 24393 | G14: 29307 | H14: 30284 | I14: 35285 | J14: 41675 | K14: 52540 | L14: 59835 | M14: 55682 | N14: 62848 | O14: 47962 | P14: 28686.88 | Q14: -13165.67 | R14: 7810 | S14: 59461.45 | T14: 133932.86
A15: MSFT | B15: Buybacks | C15: 5360 | D15: 7316 | E15: 14443 | F15: 15969 | G15: 11788 | H15: 10721 | I15: 19543 | J15: 22968 | K15: 27385 | L15: 32696 | M15: 22245 | N15: 17254 | O15: 18420 | P15: 22499.7 | Q15: 19070.28 | R15: 19500.41 | S15: 20126.95 | T15: 21047.23
A16: MSFT | B16: Intell Cloud | C16: 0 | D16: 0 | E16: 0 | F16: 0 | G16: 0 | H16: 0 | I16: 0 | J16: 0 | K16: 0 | L16: 0 | M16: 72314 | N16: 87464 | O16: 106265 | P16: 136688.31 | Q16: 180358.14 | R16: 235873.55 | S16: 304531.45 | T16: 384276.13
... A18: MSFT | B18: Useful Life(yr) | C18: 3.16 | D18: 2.69 | E18: 2.81 | F18: 2.83 | G18: 2.71 | H18: 2.73 | I18: 2.74 | J18: 3.08 | K18: 4.33 | L18: 4.12 | M18: 6.1 | N18: 5.59 | O18: 5.26 | P18: 4.89 | Q18: 4.36 | R18: 4.38 | S18: 4.6 | T18: 4.7
A20: AMZN (CY)
A21: AMZN | B21: Revenue | C21: 74453 | D21: 88988.4 | E21: 107006.6 | F21: 135987 | G21: 177866 | H21: 232887 | I21: 280522 | J21: 386064 | K21: 469822 | L21: 513983 | M21: 574785 | N21: 637959 | O21: 716924 | P21: 827599.51 | Q21: 946630.91 | R21: 1063340.6 | S21: 1183117.7 | T21: 1305415.5
A22: AMZN | B22: Operating Income | C22: 745 | D22: 178.4 | E22: 2232.6 | F22: 4186 | G22: 4107 | H22: 12420 | I22: 14540 | J22: 22899 | K22: 24879 | L22: 12248 | M22: 36852 | N22: 68593 | O22: 79975 | P22: 109001.86 | Q22: 146127.4 | R22: 183469.22 | S22: 223208.87 | T22: 264582.39
A23: AMZN | B23: Net Income | C23: 273 | D23: -240.6 | E23: 596.1 | F23: 2371 | G23: 3033 | H23: 10073 | I23: 11588 | J23: 21331 | K23: 33364 | L23: -2722 | M23: 30425 | N23: 59248 | O23: 77670 | P23: 98333.72 | Q23: 116218.4 | R23: 145016.4 | S23: 177176.2 | T23: 211925.99
A24: AMZN | B24: EPS | C24: 0.03 | D24: -0.03 | E24: 0.06 | F24: 0.24 | G24: 0.31 | H24: 1.01 | I24: 1.15 | J24: 2.08 | K24: 3.25 | L24: -0.26 | M24: 2.88 | N24: 5.53 | O24: 7.17 | P24: 9.02 | Q24: 10.58 | R24: 13.11 | S24: 15.92 | T24: 18.92
A25: AMZN | B25: Diluted Shares (mm) | C25: 9340 | D25: 9440 | E25: 9620 | F25: 9720 | G25: 9910 | H25: 10020 | I25: 10100 | J25: 10254 | K25: 10274.5 | L25: 10296.5 | M25: 10568.69 | N25: 10721 | O25: 10827 | P25: 10907.55 | Q25: 10986.16 | R25: 11059.39 | S25: 11131.13 | T25: 11201.4
A26: AMZN | B26: SBC | C26: -1134 | D26: -1497 | E26: -2120 | F26: -2975 | G26: -4214 | H26: -5418 | I26: -6864 | J26: -9208 | K26: -12757 | L26: -19621 | M26: -24023 | N26: -22077.4 | O26: -19467 | P26: -18863.32 | Q26: -17920.15 | R26: -18816.16 | S26: -19756.97 | T26: -20744.82
A27: AMZN | B27: D&A | C27: 3253 | D27: 4745 | E27: 6281 | F27: 8117 | G27: 11478 | H27: 15341 | I27: 21789 | J27: 25251 | K27: 34296 | L27: 41461 | M27: 48663 | N27: 52795 | O27: 65756 | P27: 81175.82 | Q27: 90716.93 | R27: 120533.23 | S27: 150703.05 | T27: 175451.44
A28: AMZN | B28: Capex | C28: 3443 | D28: 4892 | E28: 4588 | F28: 6736 | G28: 10057 | H28: 11322 | I28: 12690 | J28: 35046 | K28: 55396 | L28: 58321 | M28: 48133 | N28: 77658 | O28: 128320 | P28: 200104.98 | Q28: 270141.72 | R28: 283648.81 | S28: 297831.25 | T28: 312722.81
A29: AMZN | B29: CFO | C29: 5474 | D29: 6841.4 | E29: 11920.1 | F29: 17271 | G29: 18434 | H29: 30724 | I29: 38515 | J29: 66064 | K29: 46327 | L29: 46752 | M29: 84946 | N29: 115877 | O29: 139514 | P29: 181004.31 | Q29: 224443.7 | R29: 281471.71 | S29: 342814.42 | T29: 401080.41
A30: AMZN | B30: FCF | C30: 2031 | D30: 1949.4 | E30: 7332.1 | F30: 10535 | G30: 8377 | H30: 19402 | I30: 25825 | J30: 31018 | K30: -9069 | L30: -11569 | M30: 36813 | N30: 38219 | O30: 11194 | P30: -19100.67 | Q30: -45698.02 | R30: -2177.1 | S30: 44983.17 | T30: 88357.6
A31: AMZN | B31: Buybacks | C31: 0 | D31: 0 | E31: 0 | F31: 0 | G31: 0 | H31: 0 | I31: 0 | J31: 0 | K31: 0 | L31: 6000 | M31: 0 | N31: 0 | O31: 0 | P31: 0 | Q31: 0 | R31: 0 | S31: 0 | T31: 0
A32: AMZN | B32: AWS Rev | C32: 3107.57 | D32: 4644 | E32: 7880 | F32: 12219 | G32: 17458 | H32: 25656 | I32: 35026 | J32: 45370 | K32: 62202 | L32: 80096 | M32: 90757 | N32: 107556 | O32: 128725 | P32: 171284.9 | Q32: 225587.94 | R32: 274421.67 | S32: 323817.58 | T32: 374009.3
A33: AMZN | B33: AWS OI | D33: 458 | E33: 1508 | F33: 3109 | G33: 4331 | H33: 7296 | I33: 9201 | J33: 13531 | K33: 18532 | L33: 22841 | M33: 24631 | N33: 39834 | O33: 45606 | P33: 61254.41 | Q33: 81248.3 | R33: 100888.47 | S33: 121477.03 | T33: 143111.04
A35: GOOGL (CY)
A36: GOOGL | B36: Revenue | C36: 55519 | D36: 66001 | E36: 74989 | F36: 90272 | G36: 110855 | H36: 136819 | I36: 161857 | J36: 182527 | K36: 257637 | L36: 282836 | M36: 307394 | N36: 350018 | O36: 402836 | P36: 488278.6 | Q36: 591935.74 | R36: 701414.49 | S36: 815276.88 | T36: 921874.95
A37: GOOGL | B37: Operating Income | C37: 15403 | D37: 16496 | E37: 19360 | F37: 23716 | G37: 26146 | H37: 26953 | I37: 34231 | J37: 41224 | K37: 78714 | L37: 74842 | M37: 84293 | N37: 112390 | O37: 129039 | P37: 167318.21 | Q37: 210287.33 | R37: 253779.42 | S37: 298519.7 | T37: 338347.07
A38: GOOGL | B38: Net Income | C38: 12720 | D38: 14136 | E38: 16348 | F38: 19478 | G38: 12662 | H38: 30736 | I38: 34343 | J38: 40269 | K38: 76033 | L38: 59972 | M38: 73795 | N38: 100118 | O38: 132170 | P38: 168543.28 | Q38: 174626.97 | R38: 210753.44 | S38: 249488.6 | T38: 285975.76
A39: GOOGL | B39: EPS | C39: 0.94 | D39: 1.03 | E39: 1.18 | F39: 1.39 | G39: 0.9 | H39: 2.19 | I39: 2.46 | J39: 2.93 | K39: 5.61 | L39: 4.56 | M39: 5.8 | N39: 8.04 | O39: 10.81 | P39: 13.73 | Q39: 14.16 | R39: 17.04 | S39: 20.12 | T39: 22.99
A40: GOOGL | B40: Diluted Shares (mm) | C40: 13552.38 | D40: 13741.41 | E40: 13858.6 | F40: 13974.09 | G40: 14071.67 | H40: 14065.69 | I40: 13971.13 | J40: 13740.56 | K40: 13553 | L40: 13159 | M40: 12722 | N40: 12447 | O40: 12230 | P40: 12275.96 | Q40: 12335.53 | R40: 12366.42 | S40: 12399.99 | T40: 12436.85
A41: GOOGL | B41: SBC | C41: -3268 | D41: -4175 | E41: -4903 | F41: -6703 | G41: -7679 | H41: -9353 | I41: -10794 | J41: -12991 | K41: -15376 | L41: -19362 | M41: -22460 | N41: -22785 | O41: -24953 | P41: -27937.33 | Q41: -30032.63 | R41: -31979.73 | S41: -33657.1 | T41: -35339.95
A42: GOOGL | B42: D&A | C42: 2781 | D42: 3523 | E42: 4132 | F42: 5267 | G42: 6103 | H42: 8164 | I42: 10856 | J42: 12905 | K42: 11555 | L42: 15287 | M42: 13326 | N42: 15311 | O42: 21136 | P42: 42874.7 | Q42: 69582.72 | R42: 98340.16 | S42: 127674.93 | T42: 156155.17
A43: GOOGL | B43: Capex | C43: 7358 | D43: 10959 | E43: 9915 | F43: 10183 | G43: 13184 | H43: 25139 | I43: 23548 | J43: 22281 | K43: 24640 | L43: 31485 | M43: 32251 | N43: 52535 | O43: 91447 | P43: 185234.28 | Q43: 259327.99 | R43: 285260.79 | S43: 299523.83 | T43: 314500.02
A44: GOOGL | B44: CFO | C44: 18584 | D44: 22272 | E44: 25829 | F44: 36036 | G44: 37091 | H44: 47971 | I44: 54520 | J44: 65124 | K44: 91652 | L44: 91495 | M44: 101746 | N44: 125299 | O44: 164713 | P44: 211985.47 | Q44: 282346.21 | R44: 352943.8 | S44: 424226.82 | T44: 490867.35
...

Sheet 1. Summary
B2: AI Capex Cycle: Hyperscaler Deep-Dive (2013-2030)
B3: MSFT | AMZN | GOOGL | META | ORCL + S&P 500 AI EPS Decomposition
B5: SHEETS
B6: 0. Database — 2013-2030 centralized data. Blue=input. All other sheets reference this.
B7: 1. Summary — This page
B8: 2. Revenue — Total rev, YoY%, Cloud/AI proxy. Derived metrics reference SAME sheet cells (black font).
B9: 3. Capex & D&A — Capex, Capex/Rev, D&A, D&A/Rev. Local formulas reference raw data on same sheet.
B10: 4. FCF & Cash — CFO, FCF margin, FCF/NI, Capex/CFO. All ratios use same-sheet references.
B11: 5. EPS & Margins — OpMargin, Net Margin, EPS YoY. Same-sheet referencing pattern.
B12: 6. Burry Sensitivity — GPU life compression on 2026E EPS. Editable tax rate assumptions.
B13: 7. S&P 500 AI EPS Split — AI vs Non-AI EPS decomposition + dual P/E valuation + 4 stress scenarios.
B14: 8. Charts — 6 visualizations (Capex/Rev, FCF Margin, Capex absolute, Rev YoY, OpMargin, D&A/Rev).

Sheet 2. Revenue
A1: Revenue & AI/Cloud Detail (2013-2030E)
A3: A. Total Revenue ($mm)
A4: Company | B4: 2013A | C4: 2014A | D4: 2015A | E4: 2016A | F4: 2017A | G4: 2018A | H4: 2019A | I4: 2020A | J4: 2021A | K4: 2022A | L4: 2023A | M4: 2024A | N4: 2025E | O4: 2026E | P4: 2027E | Q4: 2028E | R4: 2029E | S4: 2030E
A5: MSFT | B5: ='0. Database'!C5 -> 77849 | C5: ='0. Database'!D5 -> 86833 | D5: ='0. Database'!E5 -> 93580 | E5: ='0. Database'!F5 -> 85320 | F5: ='0. Database'!G5 -> 96571 | G5: ='0. Database'!H5 -> 110360 | H5: ='0. Database'!I5 -> 125843 | I5: ='0. Database'!J5 -> 143015 | ... S5: ='0. Database'!T5 -> 652772.62
A6: AMZN | B6: ='0. Database'!C21 -> 74453 | C6: ='0. Database'!D21 -> 88988.4 | D6: ='0. Database'!E21 -> 107006.6 | E6: ='0. Database'!F21 -> 135987 | F6: ='0. Database'!G21 -> 177866 | G6: ='0. Database'!H21 -> 232887 | H6: ='0. Database'!I21 -> 280522 | I6: ='0. Database'!J21 -> 386064 | ... S6: ='0. Database'!T21 -> 1305415.5
A7: GOOGL | B7: ='0. Database'!C36 -> 55519 | C7: ='0. Database'!D36 -> 66001 | D7: ='0. Database'!E36 -> 74989 | E7: ='0. Database'!F36 -> 90272 | F7: ='0. Database'!G36 -> 110855 | G7: ='0. Database'!H36 -> 136819 | H7: ='0. Database'!I36 -> 161857 | I7: ='0. Database'!J36 -> 182527 | ... S7: ='0. Database'!T36 -> 921874.95
A8: META | B8: ='0. Database'!C53 -> 7872 | C8: ='0. Database'!D53 -> 12466 | D8: ='0. Database'!E53 -> 17927 | E8: ='0. Database'!F53 -> 27638 | F8: ='0. Database'!G53 -> 40653 | G8: ='0. Database'!H53 -> 55838 | H8: ='0. Database'!I53 -> 70696.5 | I8: ='0. Database'!J53 -> 85966 | ... S8: ='0. Database'!T53 -> 456192.68
A9: ORCL | B9: ='0. Database'!C71 -> 37253 | C9: ='0. Database'!D71 -> 38305 | D9: ='0. Database'!E71 -> 38253 | E9: ='0. Database'!F71 -> 37057 | F9: ='0. Database'!G71 -> 37899 | G9: ='0. Database'!H71 -> 39431 | H9: ='0. Database'!I71 -> 39525 | I9: ='0. Database'!J71 -> 39073 | ... S9: ='0. Database'!T71 -> 185555.08
A11: C. Cloud / AI Proxy Revenue ($mm)
A12: Company | B12: 2013A | C12: 2014A | D12: 2015A | E12: 2016A | F12: 2017A | G12: 2018A | H12: 2019A | I12: 2020A | J12: 2021A | K12: 2022A | L12: 2023A | M12: 2024A | N12: 2025E | O12: 2026E | P12: 2027E | Q12: 2028E | R12: 2029E | S12: 2030E
A13: MSFT — Azure
A14: AMZN — AWS | B14: ='0. Database'!C32 -> 3107.57 | C14: ='0. Database'!D32 -> 4644 | D14: ='0. Database'!E32 -> 7880 | E14: ='0. Database'!F32 -> 12219 | F14: ='0. Database'!G32 -> 17458 | G14: ='0. Database'!H32 -> 25656 | H14: ='0. Database'!I32 -> 35026 | I14: ='0. Database'!J32 -> 45370 | ... S14: ='0. Database'!T32 -> 374009.3
A15: GOOGL — Cloud | B15: ='0. Database'!C47 -> 0 | C15: ='0. Database'!D47 -> 0 | D15: ='0. Database'!E47 -> 0 | E15: ='0. Database'!F47 -> 0 | F15: ='0. Database'!G47 -> 4056 | G15: ='0. Database'!H47 -> 5838 | H15: ='0. Database'!I47 -> 8918 | I15: ='0. Database'!J47 -> 13059 | ... S15: ='0. Database'!T47 -> 343551.74
A16: META — Advertising | B16: ='0. Database'!C64 -> 6986 | C16: ='0. Database'!D64 -> 11492 | D16: ='0. Database'!E64 -> 17080 | E16: ='0. Database'!F64 -> 26885 | F16: ='0. Database'!G64 -> 39942 | G16: ='0. Database'!H64 -> 55012 | H16: ='0. Database'!I64 -> 69654.5 | I16: ='0. Database'!J64 -> 84169 | ... S16: ='0. Database'!T64 -> 444912.31
A17: ORCL — Cloud Total | B17: ='0. Database'!C82 -> 1365 | C17: ='0. Database'!D82 -> 1577 | D17: ='0. Database'!E82 -> 2094 | E17: ='0. Database'!F82 -> 2854 | F17: ='0. Database'!G82 -> 4572 | G17: ='0. Database'!H82 -> 6189.17 | H17: ='0. Database'!I82 -> 6918.19 | I17: ='0. Database'!J82 -> 7811.32 | ... S17: ='0. Database'!T82 -> 152708.94
A19: B. Revenue YoY %
A20: Company | B20: 2013A | C20: 2014A | D20: 2015A | E20: 2016A | F20: 2017A | G20: 2018A | H20: 2019A | I20: 2020A | J20: 2021A | K20: 2022A | L20: 2023A | M20: 2024A | N20: 2025E | O20: 2026E | P20: 2027E | Q20: 2028E | R20: 2029E | S20: 2030E
A21: MSFT | C21: =IFERROR(C5/B5-1,"") -> 0.1154029 | D21: =IFERROR(D5/C5-1,"") -> 0.077700874 | E21: =IFERROR(E5/D5-1,"") -> -0.088266724 | F21: =IFERROR(F5/E5-1,"") -> 0.13186826 | G21: =IFERROR(G5/F5-1,"") -> 0.14278614 | H21: =IFERROR(H5/G5-1,"") -> 0.1402954 | I21: =IFERROR(I5/H5-1,"") -> 0.13645574 | J21: =IFERROR(J5/I5-1,"") -> 0.17531727 | ... S21: =IFERROR(S5/R5-1,"") -> 0.17889742
A22: AMZN | C22: =IFERROR(C6/B6-1,"") -> 0.19522921 | D22: =IFERROR(D6/C6-1,"") -> 0.20247808 | E22: =IFERROR(E6/D6-1,"") -> 0.27082815 | F22: =IFERROR(F6/E6-1,"") -> 0.30796326 | G22: =IFERROR(G6/F6-1,"") -> 0.30933962 | H22: =IFERROR(H6/G6-1,"") -> 0.20454126 | I22: =IFERROR(I6/H6-1,"") -> 0.37623431 | J22: =IFERROR(J6/I6-1,"") -> 0.21695367 | ... S22: =IFERROR(S6/R6-1,"") -> 0.10336905
A23: GOOGL | C23: =IFERROR(C7/B7-1,"") -> 0.18880023 | D23: =IFERROR(D7/C7-1,"") -> 0.13617975 | E23: =IFERROR(E7/D7-1,"") -> 0.20380322 | F23: =IFERROR(F7/E7-1,"") -> 0.2280109 | G23: =IFERROR(G7/F7-1,"") -> 0.23421587 | H23: =IFERROR(H7/G7-1,"") -> 0.1830009 | I23: =IFERROR(I7/H7-1,"") -> 0.12770532 | J23: =IFERROR(J7/I7-1,"") -> 0.41150076 | ... S23: =IFERROR(S7/R7-1,"") -> 0.13075076
A24: META | C24: =IFERROR(C8/B8-1,"") -> 0.5835874 | D24: =IFERROR(D8/C8-1,"") -> 0.43807155 | E24: =IFERROR(E8/D8-1,"") -> 0.54169688 | F24: =IFERROR(F8/E8-1,"") -> 0.47090962 | G24: =IFERROR(G8/F8-1,"") -> 0.37352717 | H24: =IFERROR(H8/G8-1,"") -> 0.26610015 | I24: =IFERROR(I8/H8-1,"") -> 0.21598665 | J24: =IFERROR(J8/I8-1,"") -> 0.37180979 | ... S24: =IFERROR(S8/R8-1,"") -> 0.11989806
A25: ORCL | C25: =IFERROR(C9/B9-1,"") -> 0.028239336 | D25: =IFERROR(D9/C9-1,"") -> -0.0013575251 | E25: =IFERROR(E9/D9-1,"") -> -0.031265522 | F25: =IFERROR(F9/E9-1,"") -> 0.022721753 | G25: =IFERROR(G9/F9-1,"") -> 0.04042323 | H25: =IFERROR(H9/G9-1,"") -> 0.0023839111 | I25: =IFERROR(I9/H9-1,"") -> -0.0114358 | J25: =IFERROR(J9/I9-1,"") -> 0.036035114 | ... S25: =IFERROR(S9/R9-1,"") -> 0.12326264

Sheet 3. Capex & D&A
A1: Capex & Depreciation (2013-2030E)
A3: A. Capex ($mm)
A4: Company | B4: 2013A | C4: 2014A | D4: 2015A | E4: 2016A | F4: 2017A | G4: 2018A | H4: 2019A | I4: 2020A | J4: 2021A | K4: 2022A | L4: 2023A | M4: 2024A | N4: 2025E | O4: 2026E | P4: 2027E | Q4: 2028E | R4: 2029E | S4: 2030E
A5: MSFT | B5: ='0. Database'!C12 -> 4257 | C5: ='0. Database'!D12 -> 5485 | D5: ='0. Database'!E12 -> 5944 | E5: ='0. Database'!F12 -> 8932 | F5: ='0. Database'!G12 -> 10200 | G5: ='0. Database'!H12 -> 13600 | H5: ='0. Database'!I12 -> 16900 | I5: ='0. Database'!J12 -> 19000 | ... S5: ='0. Database'!T12 -> 304616.04
A6: AMZN | B6: ='0. Database'!C28 -> 3443 | C6: ='0. Database'!D28 -> 4892 | D6: ='0. Database'!E28 -> 4588 | E6: ='0. Database'!F28 -> 6736 | F6: ='0. Database'!G28 -> 10057 | G6: ='0. Database'!H28 -> 11322 | H6: ='0. Database'!I28 -> 12690 | I6: ='0. Database'!J28 -> 35046 | ... S6: ='0. Database'!T28 -> 312722.81
A7: GOOGL | B7: ='0. Database'!C43 -> 7358 | C7: ='0. Database'!D43 -> 10959 | D7: ='0. Database'!E43 -> 9915 | E7: ='0. Database'!F43 -> 10183 | F7: ='0. Database'!G43 -> 13184 | G7: ='0. Database'!H43 -> 25139 | H7: ='0. Database'!I43 -> 23548 | I7: ='0. Database'!J43 -> 22281 | ... S7: ='0. Database'!T43 -> 314500.02
A8: META | B8: ='0. Database'!C60 -> 1362 | C8: ='0. Database'!D60 -> 1831 | D8: ='0. Database'!E60 -> 2523 | E8: ='0. Database'!F60 -> 4491 | F8: ='0. Database'!G60 -> 6732 | G8: ='0. Database'!H60 -> 13980 | H8: ='0. Database'!I60 -> 15102 | I8: ='0. Database'!J60 -> 15115 | ... S8: ='0. Database'!T60 -> 208540.35
A9: ORCL | B9: ='0. Database'!C78 -> 650 | C9: ='0. Database'!D78 -> 580 | D9: ='0. Database'!E78 -> 1391 | E9: ='0. Database'!F78 -> 1189 | F9: ='0. Database'!G78 -> 2021 | G9: ='0. Database'!H78 -> 1736 | H9: ='0. Database'!I78 -> 1660 | I9: ='0. Database'!J78 -> 1564 | ... S9: ='0. Database'!T78 -> 66459.86
A11: D. D&A ($mm)
A12: Company | B12: 2013A | C12: 2014A | D12: 2015A | E12: 2016A | F12: 2017A | G12: 2018A | H12: 2019A | I12: 2020A | J12: 2021A | K12: 2022A | L12: 2023A | M12: 2024A | N12: 2025E | O12: 2026E | P12: 2027E | Q12: 2028E | R12: 2029E | S12: 2030E
A13: MSFT | B13: ='0. Database'!C11 -> 3339 | C13: ='0. Database'!D11 -> 4245 | D13: ='0. Database'!E11 -> 5400 | E13: ='0. Database'!F11 -> 5878 | F13: ='0. Database'!G11 -> 7800 | G13: ='0. Database'!H11 -> 9900 | H13: ='0. Database'!I11 -> 11600 | I13: ='0. Database'!J11 -> 12300 | ... S13: ='0. Database'!T11 -> 167239.58
A14: AMZN | B14: ='0. Database'!C27 -> 3253 | C14: ='0. Database'!D27 -> 4745 | D14: ='0. Database'!E27 -> 6281 | E14: ='0. Database'!F27 -> 8117 | F14: ='0. Database'!G27 -> 11478 | G14: ='0. Database'!H27 -> 15341 | H14: ='0. Database'!I27 -> 21789 | I14: ='0. Database'!J27 -> 25251 | ... S14: ='0. Database'!T27 -> 175451.44
A15: GOOGL | B15: ='0. Database'!C42 -> 2781 | C15: ='0. Database'!D42 -> 3523 | D15: ='0. Database'!E42 -> 4132 | E15: ='0. Database'!F42 -> 5267 | F15: ='0. Database'!G42 -> 6103 | G15: ='0. Database'!H42 -> 8164 | H15: ='0. Database'!I42 -> 10856 | I15: ='0. Database'!J42 -> 12905 | ... S15: ='0. Database'!T42 -> 156155.17
A16: META | B16: ='0. Database'!C59 -> 1011 | C16: ='0. Database'!D59 -> 1243 | D16: ='0. Database'!E59 -> 1945 | E16: ='0. Database'!F59 -> 2342 | F16: ='0. Database'!G59 -> 3025 | G16: ='0. Database'!H59 -> 4315 | H16: ='0. Database'!I59 -> 5741 | I16: ='0. Database'!J59 -> 6862 | ... S16: ='0. Database'!T59 -> 120937.09
A17: ORCL | B17: ='0. Database'!C77 -> 546 | C17: ='0. Database'!D77 -> 608 | D17: ='0. Database'!E77 -> 712 | E17: ='0. Database'!F77 -> 871 | F17: ='0. Database'!G77 -> 1000 | G17: ='0. Database'!H77 -> 1165 | H17: ='0. Database'!I77 -> 1230 | I17: ='0. Database'!J77 -> 1382 | ... S17: ='0. Database'!T77 -> 48244.32
A19: (Revenue — for ratios)
A20: Company | B20: 2013A | C20: 2014A | D20: 2015A | E20: 2016A | F20: 2017A | G20: 2018A | H20: 2019A | I20: 2020A | J20: 2021A | K20: 2022A | L20: 2023A | M20: 2024A | N20: 2025E | O20: 2026E | P20: 2027E | Q20: 2028E | R20: 2029E | S20: 2030E
A21: MSFT | B21: ='0. Database'!C5 -> 77849 | C21: ='0. Database'!D5 -> 86833 | D21: ='0. Database'!E5 -> 93580 | E21: ='0. Database'!F5 -> 85320 | F21: ='0. Database'!G5 -> 96571 | G21: ='0. Database'!H5 -> 110360 | H21: ='0. Database'!I5 -> 125843 | I21: ='0. Database'!J5 -> 143015 | ... S21: ='0. Database'!T5 -> 652772.62
A22: AMZN | B22: ='0. Database'!C21 -> 74453 | C22: ='0. Database'!D21 -> 88988.4 | D22: ='0. Database'!E21 -> 107006.6 | E22: ='0. Database'!F21 -> 135987 | F22: ='0. Database'!G21 -> 177866 | G22: ='0. Database'!H21 -> 232887 | H22: ='0. Database'!I21 -> 280522 | I22: ='0. Database'!J21 -> 386064 | ... S22: ='0. Database'!T21 -> 1305415.5
A23: GOOGL | B23: ='0. Database'!C36 -> 55519 | C23: ='0. Database'!D36 -> 66001 | D23: ='0. Database'!E36 -> 74989 | E23: ='0. Database'!F36 -> 90272 | F23: ='0. Database'!G36 -> 110855 | G23: ='0. Database'!H36 -> 136819 | H23: ='0. Database'!I36 -> 161857 | I23: ='0. Database'!J36 -> 182527 | ... S23: ='0. Database'!T36 -> 921874.95
A24: META | B24: ='0. Database'!C53 -> 7872 | C24: ='0. Database'!D53 -> 12466 | D24: ='0. Database'!E53 -> 17927 | E24: ='0. Database'!F53 -> 27638 | F24: ='0. Database'!G53 -> 40653 | G24: ='0. Database'!H53 -> 55838 | H24: ='0. Database'!I53 -> 70696.5 | I24: ='0. Database'!J53 -> 85966 | ... S24: ='0. Database'!T53 -> 456192.68
A25: ORCL | B25: ='0. Database'!C71 -> 37253 | C25: ='0. Database'!D71 -> 38305 | D25: ='0. Database'!E71 -> 38253 | E25: ='0. Database'!F71 -> 37057 | F25: ='0. Database'!G71 -> 37899 | G25: ='0. Database'!H71 -> 39431 | H25: ='0. Database'!I71 -> 39525 | I25: ='0. Database'!J71 -> 39073 | ... S25: ='0. Database'!T71 -> 185555.08
A27: B. Capex YoY %
A28: Company | B28: 2013A | C28: 2014A | D28: 2015A | E28: 2016A | F28: 2017A | G28: 2018A | H28: 2019A | I28: 2020A | J28: 2021A | K28: 2022A | L28: 2023A | M28: 2024A | N28: 2025E | O28: 2026E | P28: 2027E | Q28: 2028E | R28: 2029E | S28: 2030E
A29: MSFT | C29: =IFERROR(C5/B5-1,"") -> 0.28846606 | D29: =IFERROR(D5/C5-1,"") -> 0.083682771 | E29: =IFERROR(E5/D5-1,"") -> 0.50269179 | F29: =IFERROR(F5/E5-1,"") -> 0.14196149 | G29: =IFERROR(G5/F5-1,"") -> 0.33333333 | H29: =IFERROR(H5/G5-1,"") -> 0.24264706 | I29: =IFERROR(I5/H5-1,"") -> 0.12426036 | J29: =IFERROR(J5/I5-1,"") -> 0.27368421 | ... S29: =IFERROR(S5/R5-1,"") -> 0.014673451
A30: AMZN | C30: =IFERROR(C6/B6-1,"") -> 0.42085391 | D30: =IFERROR(D6/C6-1,"") -> -0.062142273 | E30: =IFERROR(E6/D6-1,"") -> 0.46817786 | F30: =IFERROR(F6/E6-1,"") -> 0.49302257 | G30: =IFERROR(G6/F6-1,"") -> 0.12578304 | H30: =IFERROR(H6/G6-1,"") -> 0.12082671 | I30: =IFERROR(I6/H6-1,"") -> 1.7617021 | J30: =IFERROR(J6/I6-1,"") -> 0.58066541 | ... S30: =IFERROR(S6/R6-1,"") -> 0.049999992
A31: GOOGL | C31: =IFERROR(C7/B7-1,"") -> 0.48939929 | D31: =IFERROR(D7/C7-1,"") -> -0.095264166 | E31: =IFERROR(E7/D7-1,"") -> 0.027029753 | F31: =IFERROR(F7/E7-1,"") -> 0.29470686 | G31: =IFERROR(G7/F7-1,"") -> 0.90678095 | H31: =IFERROR(H7/G7-1,"") -> -0.063288118 | I31: =IFERROR(I7/H7-1,"") -> -0.053804994 | J31: =IFERROR(J7/I7-1,"") -> 0.10587496 | ... S31: =IFERROR(S7/R7-1,"") -> 0.049999995
A32: META | C32: =IFERROR(C8/B8-1,"") -> 0.34434655 | D32: =IFERROR(D8/C8-1,"") -> 0.37793555 | E32: =IFERROR(E8/D8-1,"") -> 0.78002378 | F32: =IFERROR(F8/E8-1,"") -> 0.498998 | G32: =IFERROR(G8/F8-1,"") -> 1.0766488 | H32: =IFERROR(H8/G8-1,"") -> 0.080257511 | I32: =IFERROR(I8/H8-1,"") -> 0.00086081314 | J32: =IFERROR(J8/I8-1,"") -> 0.2283824 | ... S32: =IFERROR(S8/R8-1,"") -> 0.059999996
A33: ORCL | C33: =IFERROR(C9/B9-1,"") -> -0.10769231 | D33: =IFERROR(D9/C9-1,"") -> 1.3982759 | E33: =IFERROR(E9/D9-1,"") -> -0.14521927 | F33: =IFERROR(F9/E9-1,"") -> 0.69974769 | G33: =IFERROR(G9/F9-1,"") -> -0.1410193 | H33: =IFERROR(H9/G9-1,"") -> -0.043778802 | I33: =IFERROR(I9/H9-1,"") -> -0.057831325 | J33: =IFERROR(J9/I9-1,"") -> 0.36508951 | ... S33: =IFERROR(S9/R9-1,"") -> -0.18
A35: C. Capex / Revenue %
A36: Company | B36: 2013A | C36: 2014A | D36: 2015A | E36: 2016A | F36: 2017A | G36: 2018A | H36: 2019A | I36: 2020A | J36: 2021A | K36: 2022A | L36: 2023A | M36: 2024A | N36: 2025E | O36: 2026E | P36: 2027E | Q36: 2028E | R36: 2029E | S36: 2030E
A37: MSFT | B37: =IFERROR(B5/B21,"") -> 0.054682783 | C37: =IFERROR(C5/C21,"") -> 0.063167229 | D37: =IFERROR(D5/D21,"") -> 0.063517846 | E37: =IFERROR(E5/E21,"") -> 0.10468823 | F37: =IFERROR(F5/F21,"") -> 0.10562177 | G37: =IFERROR(G5/G21,"") -> 0.12323306 | H37: =IFERROR(H5/H21,"") -> 0.13429432 | I37: =IFERROR(I5/I21,"") -> 0.1328532 | ... S37: =IFERROR(S5/S21,"") -> 0.46664954
A38: AMZN | B38: =IFERROR(B6/B22,"") -> 0.046243939 | C38: =IFERROR(C6/C22,"") -> 0.054973457 | D38: =IFERROR(D6/D22,"") -> 0.04287586 | E38: =IFERROR(E6/E22,"") -> 0.049534147 | F38: =IFERROR(F6/F22,"") -> 0.056542566 | G38: =IFERROR(G6/G22,"") -> 0.048615852 | H38: =IFERROR(H6/H22,"") -> 0.045237094 | I38: =IFERROR(I6/I22,"") -> 0.090777695 | ... S38: =IFERROR(S6/S22,"") -> 0.23955807
A39: GOOGL | B39: =IFERROR(B7/B23,"") -> 0.13253121 | C39: =IFERROR(C7/C23,"") -> 0.16604294 | D39: =IFERROR(D7/D23,"") -> 0.13221939 | E39: =IFERROR(E7/E23,"") -> 0.11280353 | F39: =IFERROR(F7/F23,"") -> 0.11893013 | G39: =IFERROR(G7/G23,"") -> 0.1837391 | H39: =IFERROR(H7/H23,"") -> 0.14548645 | I39: =IFERROR(I7/I23,"") -> 0.12206961 | ... S39: =IFERROR(S7/S23,"") -> 0.34115258
A40: META | B40: =IFERROR(B8/B24,"") -> 0.17301829 | C40: =IFERROR(C8/C24,"") -> 0.14687951 | D40: =IFERROR(D8/D24,"") -> 0.14073744 | E40: =IFERROR(E8/E24,"") -> 0.16249367 | F40: =IFERROR(F8/F24,"") -> 0.16559663 | G40: =IFERROR(G8/G24,"") -> 0.25036713 | H40: =IFERROR(H8/H24,"") -> 0.21361736 | I40: =IFERROR(I8/I24,"") -> 0.17582533 | ... S40: =IFERROR(S8/S24,"") -> 0.45713217
A41: ORCL | B41: =IFERROR(B9/B25,"") -> 0.017448259 | C41: =IFERROR(C9/C25,"") -> 0.015141626 | D41: =IFERROR(D9/D25,"") -> 0.036363161 | E41: =IFERROR(E9/E25,"") -> 0.032085706 | F41: =IFERROR(F9/F25,"") -> 0.053325945 | G41: =IFERROR(G9/G25,"") -> 0.044026274 | H41: =IFERROR(H9/H25,"") -> 0.041998735 | I41: =IFERROR(I9/I25,"") -> 0.040027641 | ... S41: =IFERROR(S9/S25,"") -> 0.35816783
A43: E. D&A / Revenue %
A44: Company | B44: 2013A | C44: 2014A | D44: 2015A | E44: 2016A | F44: 2017A | G44: 2018A | H44: 2019A | I44: 2020A | J44: 2021A | K44: 2022A | L44: 2023A | M44: 2024A | N44: 2025E | O44: 2026E | P44: 2027E | Q44: 2028E | R44: 2029E | S44: 2030E
A45: MSFT | B45: =IFERROR(B13/B21,"") -> 0.042890724 | C45: =IFERROR(C13/C21,"") -> 0.048886944 | D45: =IFERROR(D13/D21,"") -> 0.057704638 | E45: =IFERROR(E13/E21,"") -> 0.068893577 | F45: =IFERROR(F13/F21,"") -> 0.080769589 | G45: =IFERROR(G13/G21,"") -> 0.089706415 | H45: =IFERROR(H13/H21,"") -> 0.092178349 | I45: =IFERROR(I13/I21,"") -> 0.086004965 | ... S45: =IFERROR(S13/S21,"") -> 0.25619883
A46: AMZN | B46: =IFERROR(B14/B22,"") -> 0.043691994 | C46: =IFERROR(C14/C22,"") -> 0.053321557 | D46: =IFERROR(D14/D22,"") -> 0.058697314 | E46: =IFERROR(E14/E22,"") -> 0.059689529 | F46: =IFERROR(F14/F22,"") -> 0.064531726 | G46: =IFERROR(G14/G22,"") -> 0.065873149 | H46: =IFERROR(H14/H22,"") -> 0.077673052 | I46: =IFERROR(I14/I22,"") -> 0.065406254 | ... S46: =IFERROR(S14/S22,"") -> 0.13440276
...

Sheet 4. FCF & Cash
A1: FCF & Cash Quality (2013-2030E)
A3: A. CFO ($mm)
A4: Company | B4: 2013A | C4: 2014A | D4: 2015A | E4: 2016A | F4: 2017A | G4: 2018A | H4: 2019A | I4: 2020A | J4: 2021A | K4: 2022A | L4: 2023A | M4: 2024A | N4: 2025E | O4: 2026E | P4: 2027E | Q4: 2028E | R4: 2029E | S4: 2030E
A5: MSFT | B5: ='0. Database'!C13 -> 28833 | C5: ='0. Database'!D13 -> 32231 | D5: ='0. Database'!E13 -> 29080 | E5: ='0. Database'!F13 -> 33325 | F5: ='0. Database'!G13 -> 39507 | G5: ='0. Database'!H13 -> 43884 | H5: ='0. Database'!I13 -> 52185 | I5: ='0. Database'!J13 -> 60675 | ... S5: ='0. Database'!T13 -> 438548.9
A6: AMZN | B6: ='0. Database'!C29 -> 5474 | C6: ='0. Database'!D29 -> 6841.4 | D6: ='0. Database'!E29 -> 11920.1 | E6: ='0. Database'!F29 -> 17271 | F6: ='0. Database'!G29 -> 18434 | G6: ='0. Database'!H29 -> 30724 | H6: ='0. Database'!I29 -> 38515 | I6: ='0. Database'!J29 -> 66064 | ... S6: ='0. Database'!T29 -> 401080.41
A7: GOOGL | B7: ='0. Database'!C44 -> 18584 | C7: ='0. Database'!D44 -> 22272 | D7: ='0. Database'!E44 -> 25829 | E7: ='0. Database'!F44 -> 36036 | F7: ='0. Database'!G44 -> 37091 | G7: ='0. Database'!H44 -> 47971 | H7: ='0. Database'!I44 -> 54520 | I7: ='0. Database'!J44 -> 65124 | ... S7: ='0. Database'!T44 -> 490867.35
A8: META | B8: ='0. Database'!C61 -> 4222 | C8: ='0. Database'!D61 -> 5507.8 | D8: ='0. Database'!E61 -> 8607 | E8: ='0. Database'!F61 -> 16061 | F8: ='0. Database'!G61 -> 24216 | G8: ='0. Database'!H61 -> 29339 | H8: ='0. Database'!I61 -> 36312.5 | I8: ='0. Database'!J61 -> 38747 | ... S8: ='0. Database'!T61 -> 314478.51
A9: ORCL | B9: ='0. Database'!C79 -> 14225 | C9: ='0. Database'!D79 -> 14921 | D9: ='0. Database'!E79 -> 14336 | E9: ='0. Database'!F79 -> 13560 | F9: ='0. Database'!G79 -> 14125 | G9: ='0. Database'!H79 -> 15386 | H9: ='0. Database'!I79 -> 14551 | I9: ='0. Database'!J79 -> 13139 | ... S9: ='0. Database'!T79 -> 84964.12
A11: B. FCF ($mm)
A12: Company | B12: 2013A | C12: 2014A | D12: 2015A | E12: 2016A | F12: 2017A | G12: 2018A | H12: 2019A | I12: 2020A | J12: 2021A | K12: 2022A | L12: 2023A | M12: 2024A | N12: 2025E | O12: 2026E | P12: 2027E | Q12: 2028E | R12: 2029E | S12: 2030E
A13: MSFT | B13: ='0. Database'!C14 -> 24576 | C13: ='0. Database'!D14 -> 26746 | D13: ='0. Database'!E14 -> 23136 | E13: ='0. Database'!F14 -> 24393 | F13: ='0. Database'!G14 -> 29307 | G13: ='0. Database'!H14 -> 30284 | H13: ='0. Database'!I14 -> 35285 | I13: ='0. Database'!J14 -> 41675 | ... S13: ='0. Database'!T14 -> 133932.86
A14: AMZN | B14: ='0. Database'!C30 -> 2031 | C14: ='0. Database'!D30 -> 1949.4 | D14: ='0. Database'!E30 -> 7332.1 | E14: ='0. Database'!F30 -> 10535 | F14: ='0. Database'!G30 -> 8377 | G14: ='0. Database'!H30 -> 19402 | H14: ='0. Database'!I30 -> 25825 | I14: ='0. Database'!J30 -> 31018 | ... S14: ='0. Database'!T30 -> 88357.6
A15: GOOGL | B15: ='0. Database'!C45 -> 11226 | C15: ='0. Database'!D45 -> 11313 | D15: ='0. Database'!E45 -> 15914 | E15: ='0. Database'!F45 -> 25853 | F15: ='0. Database'!G45 -> 23907 | G15: ='0. Database'!H45 -> 22832 | H15: ='0. Database'!I45 -> 30972 | I15: ='0. Database'!J45 -> 42843 | ... S15: ='0. Database'!T45 -> 176367.33
A16: META | B16: ='0. Database'!C62 -> 2860 | C16: ='0. Database'!D62 -> 3676.8 | D16: ='0. Database'!E62 -> 6084 | E16: ='0. Database'!F62 -> 11570 | F16: ='0. Database'!G62 -> 17484 | G16: ='0. Database'!H62 -> 15359 | H16: ='0. Database'!I62 -> 21210.5 | I16: ='0. Database'!J62 -> 23632 | ... S16: ='0. Database'!T62 -> 105938.16
A17: ORCL | B17: ='0. Database'!C80 -> 13575 | C17: ='0. Database'!D80 -> 14341 | D17: ='0. Database'!E80 -> 12945 | E17: ='0. Database'!F80 -> 12371 | F17: ='0. Database'!G80 -> 12104 | G17: ='0. Database'!H80 -> 13650 | H17: ='0. Database'!I80 -> 12891 | I17: ='0. Database'!J80 -> 11575 | ... S17: ='0. Database'!T80 -> 18504.26
A19: E. Buybacks ($mm)
A20: Company | B20: 2013A | C20: 2014A | D20: 2015A | E20: 2016A | F20: 2017A | G20: 2018A | H20: 2019A | I20: 2020A | J20: 2021A | K20: 2022A | L20: 2023A | M20: 2024A | N20: 2025E | O20: 2026E | P20: 2027E | Q20: 2028E | R20: 2029E | S20: 2030E
A21: MSFT | B21: ='0. Database'!C15 -> 5360 | C21: ='0. Database'!D15 -> 7316 | D21: ='0. Database'!E15 -> 14443 | E21: ='0. Database'!F15 -> 15969 | F21: ='0. Database'!G15 -> 11788 | G21: ='0. Database'!H15 -> 10721 | H21: ='0. Database'!I15 -> 19543 | I21: ='0. Database'!J15 -> 22968 | ... S21: ='0. Database'!T15 -> 21047.23
A22: AMZN | B22: ='0. Database'!C31 -> 0 | C22: ='0. Database'!D31 -> 0 | D22: ='0. Database'!E31 -> 0 | E22: ='0. Database'!F31 -> 0 | F22: ='0. Database'!G31 -> 0 | G22: ='0. Database'!H31 -> 0 | H22: ='0. Database'!I31 -> 0 | I22: ='0. Database'!J31 -> 0 | ... S22: ='0. Database'!T31 -> 0
A23: GOOGL | B23: ='0. Database'!C46 -> 0 | C23: ='0. Database'!D46 -> 0 | D23: ='0. Database'!E46 -> 1827 | E23: ='0. Database'!F46 -> 3693 | F23: ='0. Database'!G46 -> 4846 | G23: ='0. Database'!H46 -> 9075 | H23: ='0. Database'!I46 -> 18396 | I23: ='0. Database'!J46 -> 31149 | ... S23: ='0. Database'!T46 -> 15000
A24: META | B24: ='0. Database'!C63 -> 0 | C24: ='0. Database'!D63 -> 0 | D24: ='0. Database'!E63 -> 0 | E24: ='0. Database'!F63 -> 0 | F24: ='0. Database'!G63 -> 1976 | G24: ='0. Database'!H63 -> 12879 | H24: ='0. Database'!I63 -> 4201 | I24: ='0. Database'!J63 -> 6272 | ... S24: ='0. Database'!T63 -> 6000
A25: ORCL | B25: ='0. Database'!C81 -> 11021 | C25: ='0. Database'!D81 -> 9813 | D25: ='0. Database'!E81 -> 8087 | E25: ='0. Database'!F81 -> 10440 | F25: ='0. Database'!G81 -> 3561 | G25: ='0. Database'!H81 -> 11347 | H25: ='0. Database'!I81 -> 36140 | I25: ='0. Database'!J81 -> 19240 | ... S25: ='0. Database'!T81 -> 0
A27: (Revenue)
A28: Company | B28: 2013A | C28: 2014A | D28: 2015A | E28: 2016A | F28: 2017A | G28: 2018A | H28: 2019A | I28: 2020A | J28: 2021A | K28: 2022A | L28: 2023A | M28: 2024A | N28: 2025E | O28: 2026E | P28: 2027E | Q28: 2028E | R28: 2029E | S28: 2030E
A29: MSFT | B29: ='0. Database'!C5 -> 77849 | C29: ='0. Database'!D5 -> 86833 | D29: ='0. Database'!E5 -> 93580 | E29: ='0. Database'!F5 -> 85320 | F29: ='0. Database'!G5 -> 96571 | G29: ='0. Database'!H5 -> 110360 | H29: ='0. Database'!I5 -> 125843 | I29: ='0. Database'!J5 -> 143015 | ... S29: ='0. Database'!T5 -> 652772.62
A30: AMZN | B30: ='0. Database'!C21 -> 74453 | C30: ='0. Database'!D21 -> 88988.4 | D30: ='0. Database'!E21 -> 107006.6 | E30: ='0. Database'!F21 -> 135987 | F30: ='0. Database'!G21 -> 177866 | G30: ='0. Database'!H21 -> 232887 | H30: ='0. Database'!I21 -> 280522 | I30: ='0. Database'!J21 -> 386064 | ... S30: ='0. Database'!T21 -> 1305415.5
A31: GOOGL | B31: ='0. Database'!C36 -> 55519 | C31: ='0. Database'!D36 -> 66001 | D31: ='0. Database'!E36 -> 74989 | E31: ='0. Database'!F36 -> 90272 | F31: ='0. Database'!G36 -> 110855 | G31: ='0. Database'!H36 -> 136819 | H31: ='0. Database'!I36 -> 161857 | I31: ='0. Database'!J36 -> 182527 | ... S31: ='0. Database'!T36 -> 921874.95
A32: META | B32: ='0. Database'!C53 -> 7872 | C32: ='0. Database'!D53 -> 12466 | D32: ='0. Database'!E53 -> 17927 | E32: ='0. Database'!F53 -> 27638 | F32: ='0. Database'!G53 -> 40653 | G32: ='0. Database'!H53 -> 55838 | H32: ='0. Database'!I53 -> 70696.5 | I32: ='0. Database'!J53 -> 85966 | ... S32: ='0. Database'!T53 -> 456192.68
A33: ORCL | B33: ='0. Database'!C71 -> 37253 | C33: ='0. Database'!D71 -> 38305 | D33: ='0. Database'!E71 -> 38253 | E33: ='0. Database'!F71 -> 37057 | F33: ='0. Database'!G71 -> 37899 | G33: ='0. Database'!H71 -> 39431 | H33: ='0. Database'!I71 -> 39525 | I33: ='0. Database'!J71 -> 39073 | ... S33: ='0. Database'!T71 -> 185555.08
A35: (NI)
A36: Company | B36: 2013A | C36: 2014A | D36: 2015A | E36: 2016A | F36: 2017A | G36: 2018A | H36: 2019A | I36: 2020A | J36: 2021A | K36: 2022A | L36: 2023A | M36: 2024A | N36: 2025E | O36: 2026E | P36: 2027E | Q36: 2028E | R36: 2029E | S36: 2030E
A37: MSFT | B37: ='0. Database'!C7 -> 21863 | C37: ='0. Database'!D7 -> 22074 | D37: ='0. Database'!E7 -> 12193 | E37: ='0. Database'!F7 -> 16798 | F37: ='0. Database'!G7 -> 25489 | G37: ='0. Database'!H7 -> 16571 | H37: ='0. Database'!I7 -> 39240 | I37: ='0. Database'!J7 -> 44281 | ... S37: ='0. Database'!T7 -> 258948.36
A38: AMZN | B38: ='0. Database'!C23 -> 273 | C38: ='0. Database'!D23 -> -240.6 | D38: ='0. Database'!E23 -> 596.1 | E38: ='0. Database'!F23 -> 2371 | F38: ='0. Database'!G23 -> 3033 | G38: ='0. Database'!H23 -> 10073 | H38: ='0. Database'!I23 -> 11588 | I38: ='0. Database'!J23 -> 21331 | ... S38: ='0. Database'!T23 -> 211925.99
A39: GOOGL | B39: ='0. Database'!C38 -> 12720 | C39: ='0. Database'!D38 -> 14136 | D39: ='0. Database'!E38 -> 16348 | E39: ='0. Database'!F38 -> 19478 | F39: ='0. Database'!G38 -> 12662 | G39: ='0. Database'!H38 -> 30736 | H39: ='0. Database'!I38 -> 34343 | I39: ='0. Database'!J38 -> 40269 | ... S39: ='0. Database'!T38 -> 285975.76
A40: META | B40: ='0. Database'!C55 -> 1491 | C40: ='0. Database'!D55 -> 2924.8 | D40: ='0. Database'!E55 -> 3669 | E40: ='0. Database'!F55 -> 10187.2 | F40: ='0. Database'!G55 -> 15919 | G40: ='0. Database'!H55 -> 22112 | H40: ='0. Database'!I55 -> 18484.5 | I40: ='0. Database'!J55 -> 29145 | ... S40: ='0. Database'!T55 -> 127804.37
A41: ORCL | B41: ='0. Database'!C73 -> 10926 | C41: ='0. Database'!D73 -> 10955 | D41: ='0. Database'!E73 -> 9938 | E41: ='0. Database'!F73 -> 8900 | F41: ='0. Database'!G73 -> 9334 | G41: ='0. Database'!H73 -> 3587 | H41: ='0. Database'!I73 -> 11083 | I41: ='0. Database'!J73 -> 10135 | ... S41: ='0. Database'!T73 -> 44104.48
A43: (Capex)
A44: Company | B44: 2013A | C44: 2014A | D44: 2015A | E44: 2016A | F44: 2017A | G44: 2018A | H44: 2019A | I44: 2020A | J44: 2021A | K44: 2022A | L44: 2023A | M44: 2024A | N44: 2025E | O44: 2026E | P44: 2027E | Q44: 2028E | R44: 2029E | S44: 2030E
A45: MSFT | B45: ='0. Database'!C12 -> 4257 | C45: ='0. Database'!D12 -> 5485 | D45: ='0. Database'!E12 -> 5944 | E45: ='0. Database'!F12 -> 8932 | F45: ='0. Database'!G12 -> 10200 | G45: ='0. Database'!H12 -> 13600 | H45: ='0. Database'!I12 -> 16900 | I45: ='0. Database'!J12 -> 19000 | ... S45: ='0. Database'!T12 -> 304616.04
A46: AMZN | B46: ='0. Database'!C28 -> 3443 | C46: ='0. Database'!D28 -> 4892 | D46: ='0. Database'!E28 -> 4588 | E46: ='0. Database'!F28 -> 6736 | F46: ='0. Database'!G28 -> 10057 | G46: ='0. Database'!H28 -> 11322 | H46: ='0. Database'!I28 -> 12690 | I46: ='0. Database'!J28 -> 35046 | ... S46: ='0. Database'!T28 -> 312722.81
...

Sheet 5. EPS & Margins
A1: EPS, OpMargin & Profitability (2013-2030E)
A3: A. Operating Income ($mm)
A4: Company | B4: 2013A | C4: 2014A | D4: 2015A | E4: 2016A | F4: 2017A | G4: 2018A | H4: 2019A | I4: 2020A | J4: 2021A | K4: 2022A | L4: 2023A | M4: 2024A | N4: 2025E | O4: 2026E | P4: 2027E | Q4: 2028E | R4: 2029E | S4: 2030E
A5: MSFT | B5: ='0. Database'!C6 -> 26764 | C5: ='0. Database'!D6 -> 27759 | D5: ='0. Database'!E6 -> 18161 | E5: ='0. Database'!F6 -> 20182 | F5: ='0. Database'!G6 -> 29025 | G5: ='0. Database'!H6 -> 35058 | H5: ='0. Database'!I6 -> 42959 | I5: ='0. Database'!J6 -> 52959 | ... S5: ='0. Database'!T6 -> 318436.19
A6: AMZN | B6: ='0. Database'!C22 -> 745 | C6: ='0. Database'!D22 -> 178.4 | D6: ='0. Database'!E22 -> 2232.6 | E6: ='0. Database'!F22 -> 4186 | F6: ='0. Database'!G22 -> 4107 | G6: ='0. Database'!H22 -> 12420 | H6: ='0. Database'!I22 -> 14540 | I6: ='0. Database'!J22 -> 22899 | ... S6: ='0. Database'!T22 -> 264582.39
A7: GOOGL | B7: ='0. Database'!C37 -> 15403 | C7: ='0. Database'!D37 -> 16496 | D7: ='0. Database'!E37 -> 19360 | E7: ='0. Database'!F37 -> 23716 | F7: ='0. Database'!G37 -> 26146 | G7: ='0. Database'!H37 -> 26953 | H7: ='0. Database'!I37 -> 34231 | I7: ='0. Database'!J37 -> 41224 | ... S7: ='0. Database'!T37 -> 338347.07
A8: META | B8: ='0. Database'!C54 -> 2804 | C8: ='0. Database'!D54 -> 4994.8 | D8: ='0. Database'!E54 -> 6225 | E8: ='0. Database'!F54 -> 12427 | F8: ='0. Database'!G54 -> 20202 | G8: ='0. Database'!H54 -> 24913 | H8: ='0. Database'!I54 -> 23985.5 | I8: ='0. Database'!J54 -> 32671 | ... S8: ='0. Database'!T54 -> 142814.67
A9: ORCL | B9: ='0. Database'!C72 -> 14684 | C9: ='0. Database'!D72 -> 14758 | D9: ='0. Database'!E72 -> 13870 | E9: ='0. Database'!F72 -> 12604 | F9: ='0. Database'!G72 -> 12710 | G9: ='0. Database'!H72 -> 13264 | H9: ='0. Database'!I72 -> 13535 | I9: ='0. Database'!J72 -> 13897 | ... S9: ='0. Database'!T72 -> 57952.82
A11: C. Net Income ($mm)
A12: Company | B12: 2013A | C12: 2014A | D12: 2015A | E12: 2016A | F12: 2017A | G12: 2018A | H12: 2019A | I12: 2020A | J12: 2021A | K12: 2022A | L12: 2023A | M12: 2024A | N12: 2025E | O12: 2026E | P12: 2027E | Q12: 2028E | R12: 2029E | S12: 2030E
A13: MSFT | B13: ='0. Database'!C7 -> 21863 | C13: ='0. Database'!D7 -> 22074 | D13: ='0. Database'!E7 -> 12193 | E13: ='0. Database'!F7 -> 16798 | F13: ='0. Database'!G7 -> 25489 | G13: ='0. Database'!H7 -> 16571 | H13: ='0. Database'!I7 -> 39240 | I13: ='0. Database'!J7 -> 44281 | ... S13: ='0. Database'!T7 -> 258948.36
A14: AMZN | B14: ='0. Database'!C23 -> 273 | C14: ='0. Database'!D23 -> -240.6 | D14: ='0. Database'!E23 -> 596.1 | E14: ='0. Database'!F23 -> 2371 | F14: ='0. Database'!G23 -> 3033 | G14: ='0. Database'!H23 -> 10073 | H14: ='0. Database'!I23 -> 11588 | I14: ='0. Database'!J23 -> 21331 | ... S14: ='0. Database'!T23 -> 211925.99
A15: GOOGL | B15: ='0. Database'!C38 -> 12720 | C15: ='0. Database'!D38 -> 14136 | D15: ='0. Database'!E38 -> 16348 | E15: ='0. Database'!F38 -> 19478 | F15: ='0. Database'!G38 -> 12662 | G15: ='0. Database'!H38 -> 30736 | H15: ='0. Database'!I38 -> 34343 | I15: ='0. Database'!J38 -> 40269 | ... S15: ='0. Database'!T38 -> 285975.76
A16: META | B16: ='0. Database'!C55 -> 1491 | C16: ='0. Database'!D55 -> 2924.8 | D16: ='0. Database'!E55 -> 3669 | E16: ='0. Database'!F55 -> 10187.2 | F16: ='0. Database'!G55 -> 15919 | G16: ='0. Database'!H55 -> 22112 | H16: ='0. Database'!I55 -> 18484.5 | I16: ='0. Database'!J55 -> 29145 | ... S16: ='0. Database'!T55 -> 127804.37
A17: ORCL | B17: ='0. Database'!C73 -> 10926 | C17: ='0. Database'!D73 -> 10955 | D17: ='0. Database'!E73 -> 9938 | E17: ='0. Database'!F73 -> 8900 | F17: ='0. Database'!G73 -> 9334 | G17: ='0. Database'!H73 -> 3587 | H17: ='0. Database'!I73 -> 11083 | I17: ='0. Database'!J73 -> 10135 | ... S17: ='0. Database'!T73 -> 44104.48
A19: E. EPS ($)
A20: Company | B20: 2013A | C20: 2014A | D20: 2015A | E20: 2016A | F20: 2017A | G20: 2018A | H20: 2019A | I20: 2020A | J20: 2021A | K20: 2022A | L20: 2023A | M20: 2024A | N20: 2025E | O20: 2026E | P20: 2027E | Q20: 2028E | R20: 2029E | S20: 2030E
A21: MSFT | B21: ='0. Database'!C8 -> 2.63 | C21: ='0. Database'!D8 -> 2.66 | D21: ='0. Database'!E8 -> 2.59 | E21: ='0. Database'!F8 -> 2.79 | F21: ='0. Database'!G8 -> 3.29 | G21: ='0. Database'!H8 -> 3.88 | H21: ='0. Database'!I8 -> 4.75 | I21: ='0. Database'!J8 -> 5.76 | ... S21: ='0. Database'!T8 -> 34.82
A22: AMZN | B22: ='0. Database'!C24 -> 0.03 | C22: ='0. Database'!D24 -> -0.03 | D22: ='0. Database'!E24 -> 0.06 | E22: ='0. Database'!F24 -> 0.24 | F22: ='0. Database'!G24 -> 0.31 | G22: ='0. Database'!H24 -> 1.01 | H22: ='0. Database'!I24 -> 1.15 | I22: ='0. Database'!J24 -> 2.08 | ... S22: ='0. Database'!T24 -> 18.92
A23: GOOGL | B23: ='0. Database'!C39 -> 0.94 | C23: ='0. Database'!D39 -> 1.03 | D23: ='0. Database'!E39 -> 1.18 | E23: ='0. Database'!F39 -> 1.39 | F23: ='0. Database'!G39 -> 0.9 | G23: ='0. Database'!H39 -> 2.19 | H23: ='0. Database'!I39 -> 2.46 | I23: ='0. Database'!J39 -> 2.93 | ... S23: ='0. Database'!T39 -> 22.99
A24: META | B24: ='0. Database'!C56 -> 0.59 | C24: ='0. Database'!D56 -> 1.1 | D24: ='0. Database'!E56 -> 1.28 | E24: ='0. Database'!F56 -> 3.48 | F24: ='0. Database'!G56 -> 5.39 | G24: ='0. Database'!H56 -> 7.66 | H24: ='0. Database'!I56 -> 6.44 | I24: ='0. Database'!J56 -> 10.08 | ... S24: ='0. Database'!T56 -> 47.52
A25: ORCL | B25: ='0. Database'!C74 -> 2.26 | C25: ='0. Database'!D74 -> 2.38 | D25: ='0. Database'!E74 -> 2.21 | E25: ='0. Database'!F74 -> 2.07 | F25: ='0. Database'!G74 -> 2.21 | G25: ='0. Database'!H74 -> 0.85 | H25: ='0. Database'!I74 -> 2.97 | I25: ='0. Database'!J74 -> 3.08 | ... S25: ='0. Database'!T74 -> 14.32
A27: G. Diluted Shares (mm)
A28: Company | B28: 2013A | C28: 2014A | D28: 2015A | E28: 2016A | F28: 2017A | G28: 2018A | H28: 2019A | I28: 2020A | J28: 2021A | K28: 2022A | L28: 2023A | M28: 2024A | N28: 2025E | O28: 2026E | P28: 2027E | Q28: 2028E | R28: 2029E | S28: 2030E
A29: MSFT | B29: ='0. Database'!C9 -> 8452.25 | C29: ='0. Database'!D9 -> 8385.25 | D29: ='0. Database'!E9 -> 8254 | E29: ='0. Database'!F9 -> 8012.25 | F29: ='0. Database'!G9 -> 7831.25 | G29: ='0. Database'!H9 -> 7792.25 | H29: ='0. Database'!I9 -> 7752 | I29: ='0. Database'!J9 -> 7681.5 | ... S29: ='0. Database'!T9 -> 7436.22
A30: AMZN | B30: ='0. Database'!C25 -> 9340 | C30: ='0. Database'!D25 -> 9440 | D30: ='0. Database'!E25 -> 9620 | E30: ='0. Database'!F25 -> 9720 | F30: ='0. Database'!G25 -> 9910 | G30: ='0. Database'!H25 -> 10020 | H30: ='0. Database'!I25 -> 10100 | I30: ='0. Database'!J25 -> 10254 | ... S30: ='0. Database'!T25 -> 11201.4
A31: GOOGL | B31: ='0. Database'!C40 -> 13552.38 | C31: ='0. Database'!D40 -> 13741.41 | D31: ='0. Database'!E40 -> 13858.6 | E31: ='0. Database'!F40 -> 13974.09 | F31: ='0. Database'!G40 -> 14071.67 | G31: ='0. Database'!H40 -> 14065.69 | H31: ='0. Database'!I40 -> 13971.13 | I31: ='0. Database'!J40 -> 13740.56 | ... S31: ='0. Database'!T40 -> 12436.85
A32: META | B32: ='0. Database'!C57 -> 2521.75 | C32: ='0. Database'!D57 -> 2671 | D32: ='0. Database'!E57 -> 2856.75 | E32: ='0. Database'!F57 -> 2923.75 | F32: ='0. Database'!G57 -> 2954 | G32: ='0. Database'!H57 -> 2886 | H32: ='0. Database'!I57 -> 2871 | I32: ='0. Database'!J57 -> 2890 | ... S32: ='0. Database'!T57 -> 2689.4
A33: ORCL | B33: ='0. Database'!C75 -> 4843.75 | C33: ='0. Database'!D75 -> 4604.5 | D33: ='0. Database'!E75 -> 4502.5 | E33: ='0. Database'!F75 -> 4305.5 | F33: ='0. Database'!G75 -> 4217 | G33: ='0. Database'!H75 -> 4238 | H33: ='0. Database'!I75 -> 3732 | I33: ='0. Database'!J75 -> 3293.5 | ... S33: ='0. Database'!T75 -> 3079.57
A35: H. SBC ($mm)
A36: Company | B36: 2013A | C36: 2014A | D36: 2015A | E36: 2016A | F36: 2017A | G36: 2018A | H36: 2019A | I36: 2020A | J36: 2021A | K36: 2022A | L36: 2023A | M36: 2024A | N36: 2025E | O36: 2026E | P36: 2027E | Q36: 2028E | R36: 2029E | S36: 2030E
A37: MSFT | B37: ='0. Database'!C10 -> 2406 | C37: ='0. Database'!D10 -> 2446 | D37: ='0. Database'!E10 -> 2574 | E37: ='0. Database'!F10 -> 2668 | F37: ='0. Database'!G10 -> 3266 | G37: ='0. Database'!H10 -> 3940 | H37: ='0. Database'!I10 -> 4652 | I37: ='0. Database'!J10 -> 5289 | ... S37: ='0. Database'!T10 -> 14871.62
A38: AMZN | B38: ='0. Database'!C26 -> -1134 | C38: ='0. Database'!D26 -> -1497 | D38: ='0. Database'!E26 -> -2120 | E38: ='0. Database'!F26 -> -2975 | F38: ='0. Database'!G26 -> -4214 | G38: ='0. Database'!H26 -> -5418 | H38: ='0. Database'!I26 -> -6864 | I38: ='0. Database'!J26 -> -9208 | ... S38: ='0. Database'!T26 -> -20744.82
A39: GOOGL | B39: ='0. Database'!C41 -> -3268 | C39: ='0. Database'!D41 -> -4175 | D39: ='0. Database'!E41 -> -4903 | E39: ='0. Database'!F41 -> -6703 | F39: ='0. Database'!G41 -> -7679 | G39: ='0. Database'!H41 -> -9353 | H39: ='0. Database'!I41 -> -10794 | I39: ='0. Database'!J41 -> -12991 | ... S39: ='0. Database'!T41 -> -35339.95
A40: META | B40: ='0. Database'!C58 -> -906 | C40: ='0. Database'!D58 -> -1837 | D40: ='0. Database'!E58 -> -2969 | E40: ='0. Database'!F58 -> -3202 | F40: ='0. Database'!G58 -> -3723 | G40: ='0. Database'!H58 -> -4152 | H40: ='0. Database'!I58 -> -4835 | I40: ='0. Database'!J58 -> -6536 | ... S40: ='0. Database'!T58 -> -28834.48
A41: ORCL | B41: ='0. Database'!C76 -> 755 | C41: ='0. Database'!D76 -> 805 | D41: ='0. Database'!E76 -> 933 | E41: ='0. Database'!F76 -> 1037 | F41: ='0. Database'!G76 -> 1350 | G41: ='0. Database'!H76 -> 1607 | H41: ='0. Database'!I76 -> 1653 | I41: ='0. Database'!J76 -> 1590 | ... S41: ='0. Database'!T76 -> 11212.32
A43: (Revenue)
A44: Company | B44: 2013A | C44: 2014A | D44: 2015A | E44: 2016A | F44: 2017A | G44: 2018A | H44: 2019A | I44: 2020A | J44: 2021A | K44: 2022A | L44: 2023A | M44: 2024A | N44: 2025E | O44: 2026E | P44: 2027E | Q44: 2028E | R44: 2029E | S44: 2030E
A45: MSFT | B45: ='0. Database'!C5 -> 77849 | C45: ='0. Database'!D5 -> 86833 | D45: ='0. Database'!E5 -> 93580 | E45: ='0. Database'!F5 -> 85320 | F45: ='0. Database'!G5 -> 96571 | G45: ='0. Database'!H5 -> 110360 | H45: ='0. Database'!I5 -> 125843 | I45: ='0. Database'!J5 -> 143015 | ... S45: ='0. Database'!T5 -> 652772.62
A46: AMZN | B46: ='0. Database'!C21 -> 74453 | C46: ='0. Database'!D21 -> 88988.4 | D46: ='0. Database'!E21 -> 107006.6 | E46: ='0. Database'!F21 -> 135987 | F46: ='0. Database'!G21 -> 177866 | G46: ='0. Database'!H21 -> 232887 | H46: ='0. Database'!I21 -> 280522 | I46: ='0. Database'!J21 -> 386064 | ... S46: ='0. Database'!T21 -> 1305415.5
...

Sheet 6. Depreciation Sensitivity
A1: Depreciation Sensitivity: Useful Life × Method → D&A & EPS Impact
A3: A. Current Depreciation Assumptions (2026E)
A4: Company | B4: 2026E D&A ($mm) | C4: 2026E NI ($mm) | D4: 2026E EPS ($) | E4: Shares (mm) | F4: Tax Rate (editable) | G4: Current Wtd Avg Life (yr) | H4: Depreciable Base ($mm) | I4: D&A Check = Base/Life
A5: MSFT | B5: ='0. Database'!P11 -> 39638.96 | C5: ='0. Database'!P7 -> 129372.86 | D5: ='0. Database'!P8 -> 16.75 | E5: ='0. Database'!P9 -> 7453.97 | F5: 0.18 | G5: 4.9 | H5: =$B$5*$G$5 -> 194230.9 | I5: =IFERROR($H$5/$G$5,"") -> 39638.96
A6: AMZN | B6: ='0. Database'!P27 -> 81175.82 | C6: ='0. Database'!P23 -> 98333.72 | D6: ='0. Database'!P24 -> 9.02 | E6: ='0. Database'!P25 -> 10907.55 | F6: 0.2 | G6: 5.5 | H6: =$B$6*$G$6 -> 446467.01 | I6: =IFERROR($H$6/$G$6,"") -> 81175.82
A7: GOOGL | B7: ='0. Database'!P42 -> 42874.7 | C7: ='0. Database'!P38 -> 168543.28 | D7: ='0. Database'!P39 -> 13.73 | E7: ='0. Database'!P40 -> 12275.96 | F7: 0.16 | G7: 6 | H7: =$B$7*$G$7 -> 257248.2 | I7: =IFERROR($H$7/$G$7,"") -> 42874.7
A8: META | B8: ='0. Database'!P59 -> 35955.99 | C8: ='0. Database'!P55 -> 85782.86 | D8: ='0. Database'!P56 -> 33.28 | E8: ='0. Database'!P57 -> 2577.79 | F8: 0.13 | G8: 5.5 | H8: =$B$8*$G$8 -> 197757.95 | I8: =IFERROR($H$8/$G$8,"") -> 35955.99
A9: ORCL | B9: ='0. Database'!P77 -> 7501.53 | C9: ='0. Database'!P73 -> 15820.55 | D9: ='0. Database'!P74 -> 5.43 | E9: ='0. Database'!P75 -> 2915.76 | F9: 0.2 | G9: 5.5 | H9: =$B$9*$G$9 -> 41258.415 | I9: =IFERROR($H$9/$G$9,"") -> 7501.53
A12: B. Straight-Line: If Useful Life = X Years → D&A & EPS Impact
A13: Formula: New D&A = Depreciable Base / New Life. ΔD&A after-tax hits NI. New EPS = (NI - ΔD&A × (1-tax)) / Shares.
A14: Useful Life = 6 Years (Straight-Line)
A15: Company | B15: New D&A ($mm) | C15: Δ D&A ($mm) | D15: Δ After-tax ($mm) | E15: Adj NI ($mm) | F15: Adj EPS ($) | G15: EPS Δ% vs Current
A16: MSFT | B16: =$H$5/6 -> 32371.817 | C16: =$B$16-$B$5 -> -7267.1427 | D16: =$C$16*(1-$F$5) -> -5959.057 | E16: =$C$5-$D$16 -> 135331.92 | F16: =$E$16/$E$5 -> 18.155683 | G16: =IFERROR($F$16/$D$5-1,"") -> 0.083921378
A17: AMZN | B17: =$H$6/6 -> 74411.168 | C17: =$B$17-$B$6 -> -6764.6517 | D17: =$C$17*(1-$F$6) -> -5411.7213 | E17: =$C$6-$D$17 -> 103745.44 | F17: =$E$17/$E$6 -> 9.5113423 | G17: =IFERROR($F$17/$D$6-1,"") -> 0.054472535
A18: GOOGL | B18: =$H$7/6 -> 42874.7 | C18: =$B$18-$B$7 -> 0 | D18: =$C$18*(1-$F$7) -> 0 | E18: =$C$7-$D$18 -> 168543.28 | F18: =$E$18/$E$7 -> 13.72954 | G18: =IFERROR($F$18/$D$7-1,"") -> -3.3526169e-05
A19: META | B19: =$H$8/6 -> 32959.658 | C19: =$B$19-$B$8 -> -2996.3325 | D19: =$C$19*(1-$F$8) -> -2606.8093 | E19: =$C$8-$D$19 -> 88389.669 | F19: =$E$19/$E$8 -> 34.288933 | G19: =IFERROR($F$19/$D$8-1,"") -> 0.030316504
A20: ORCL | B20: =$H$9/6 -> 6876.4025 | C20: =$B$20-$B$9 -> -625.1275 | D20: =$C$20*(1-$F$9) -> -500.102 | E20: =$C$9-$D$20 -> 16320.652 | F20: =$E$20/$E$9 -> 5.5973921 | G20: =IFERROR($F$20/$D$9-1,"") -> 0.030827275
A22: Useful Life = 5 Years (Straight-Line)
A23: Company | B23: New D&A ($mm) | C23: Δ D&A ($mm) | D23: Δ After-tax ($mm) | E23: Adj NI ($mm) | F23: Adj EPS ($) | G23: EPS Δ% vs Current
A24: MSFT | B24: =$H$5/5 -> 38846.181 | C24: =$B$24-$B$5 -> -792.7792 | D24: =$C$24*(1-$F$5) -> -650.07894 | E24: =$C$5-$D$24 -> 130022.94 | F24: =$E$24/$E$5 -> 17.443448 | G24: =IFERROR($F$24/$D$5-1,"") -> 0.041399887
A25: AMZN | B25: =$H$6/5 -> 89293.402 | C25: =$B$25-$B$6 -> 8117.582 | D25: =$C$25*(1-$F$6) -> 6494.0656 | E25: =$C$6-$D$25 -> 91839.654 | F25: =$E$25/$E$6 -> 8.4198243 | G25: =IFERROR($F$25/$D$6-1,"") -> -0.066538327
A26: GOOGL | B26: =$H$7/5 -> 51449.64 | C26: =$B$26-$B$7 -> 8574.94 | D26: =$C$26*(1-$F$7) -> 7202.9496 | E26: =$C$7-$D$26 -> 161340.33 | F26: =$E$26/$E$7 -> 13.142787 | G26: =IFERROR($F$26/$D$7-1,"") -> -0.042768592
A27: META | B27: =$H$8/5 -> 39551.589 | C27: =$B$27-$B$8 -> 3595.599 | D27: =$C$27*(1-$F$8) -> 3128.1711 | E27: =$C$8-$D$27 -> 82654.689 | F27: =$E$27/$E$8 -> 32.064167 | G27: =IFERROR($F$27/$D$8-1,"") -> -0.036533446
A28: ORCL | B28: =$H$9/5 -> 8251.683 | C28: =$B$28-$B$9 -> 750.153 | D28: =$C$28*(1-$F$9) -> 600.1224 | E28: =$C$9-$D$28 -> 15220.428 | F28: =$E$28/$E$9 -> 5.220055 | G28: =IFERROR($F$28/$D$9-1,"") -> -0.038663902
A30: Useful Life = 4 Years (Straight-Line)
A31: Company | B31: New D&A ($mm) | C31: Δ D&A ($mm) | D31: Δ After-tax ($mm) | E31: Adj NI ($mm) | F31: Adj EPS ($) | G31: EPS Δ% vs Current
A32: MSFT | B32: =$H$5/4 -> 48557.726 | C32: =$B$32-$B$5 -> 8918.766 | D32: =$C$32*(1-$F$5) -> 7313.3881 | E32: =$C$5-$D$32 -> 122059.47 | F32: =$E$32/$E$5 -> 16.375096 | G32: =IFERROR($F$32/$D$5-1,"") -> -0.022382348
A33: AMZN | B33: =$H$6/4 -> 111616.75 | C33: =$B$33-$B$6 -> 30440.932 | D33: =$C$33*(1-$F$6) -> 24352.746 | E33: =$C$6-$D$33 -> 73980.974 | F33: =$E$33/$E$6 -> 6.7825473 | G33: =IFERROR($F$33/$D$6-1,"") -> -0.24805462
A34: GOOGL | B34: =$H$7/4 -> 64312.05 | C34: =$B$34-$B$7 -> 21437.35 | D34: =$C$34*(1-$F$7) -> 18007.374 | E34: =$C$7-$D$34 -> 150535.91 | F34: =$E$34/$E$7 -> 12.262659 | G34: =IFERROR($F$34/$D$7-1,"") -> -0.10687119
A35: META | B35: =$H$8/4 -> 49439.486 | C35: =$B$35-$B$8 -> 13483.496 | D35: =$C$35*(1-$F$8) -> 11730.642 | E35: =$C$8-$D$35 -> 74052.218 | F35: =$E$35/$E$8 -> 28.727017 | G35: =IFERROR($F$35/$D$8-1,"") -> -0.13680837
A36: ORCL | B36: =$H$9/4 -> 10314.604 | C36: =$B$36-$B$9 -> 2813.0738 | D36: =$C$36*(1-$F$9) -> 2250.459 | E36: =$C$9-$D$36 -> 13570.091 | F36: =$E$36/$E$9 -> 4.6540494 | G36: =IFERROR($F$36/$D$9-1,"") -> -0.14290067
A38: Useful Life = 3 Years (Straight-Line)
A39: Company | B39: New D&A ($mm) | C39: Δ D&A ($mm) | D39: Δ After-tax ($mm) | E39: Adj NI ($mm) | F39: Adj EPS ($) | G39: EPS Δ% vs Current
A40: MSFT | B40: =$H$5/3 -> 64743.635 | C40: =$B$40-$B$5 -> 25104.675 | D40: =$C$40*(1-$F$5) -> 20585.833 | E40: =$C$5-$D$40 -> 108787.03 | F40: =$E$40/$E$5 -> 14.594508 | G40: =IFERROR($F$40/$D$5-1,"") -> -0.12868607
A41: AMZN | B41: =$H$6/3 -> 148822.34 | C41: =$B$41-$B$6 -> 67646.517 | D41: =$C$41*(1-$F$6) -> 54117.213 | E41: =$C$6-$D$41 -> 44216.507 | F41: =$E$41/$E$6 -> 4.0537524 | G41: =IFERROR($F$41/$D$6-1,"") -> -0.55058178
A42: GOOGL | B42: =$H$7/3 -> 85749.4 | C42: =$B$42-$B$7 -> 42874.7 | D42: =$C$42*(1-$F$7) -> 36014.748 | E42: =$C$7-$D$42 -> 132528.53 | F42: =$E$42/$E$7 -> 10.795777 | G42: =IFERROR($F$42/$D$7-1,"") -> -0.21370885
A43: META | B43: =$H$8/3 -> 65919.315 | C43: =$B$43-$B$8 -> 29963.325 | D43: =$C$43*(1-$F$8) -> 26068.093 | E43: =$C$8-$D$43 -> 59714.767 | F43: =$E$43/$E$8 -> 23.165102 | G43: =IFERROR($F$43/$D$8-1,"") -> -0.30393325
A44: ORCL | B44: =$H$9/3 -> 13752.805 | C44: =$B$44-$B$9 -> 6251.275 | D44: =$C$44*(1-$F$9) -> 5001.02 | E44: =$C$9-$D$44 -> 10819.53 | F44: =$E$44/$E$9 -> 3.7107066 | G44: =IFERROR($F$44/$D$9-1,"") -> -0.31662861
A46: Useful Life = 2 Years (Straight-Line)
A47: Company | B47: New D&A ($mm) | C47: Δ D&A ($mm) | D47: Δ After-tax ($mm) | E47: Adj NI ($mm) | F47: Adj EPS ($) | G47: EPS Δ% vs Current
...

Sheet 7. SP500 AI EPS Split
A1: S&P 500 EPS Decomposition: AI vs Non-AI + Valuation Framework
A3: A. S&P 500 EPS Decomposition (Historical + Estimates)
A4: Metric | B4: 2018A | C4: 2019A | D4: 2020A | E4: 2021A | F4: 2022A | G4: 2023A | H4: 2024A | I4: 2025A | J4: 2026E | K4: 2027E | L4: 2028E | M4: 2029E | N4: 2030E
A5: S&P 500 Total EPS ($) | B5: 152 | C5: 157 | D5: 139 | E5: 208 | F5: 218 | G5: 221 | H5: 240 | I5: 262 | J5: 275 | K5: 300 | L5: 325 | M5: 350 | N5: 375
A6: AI-Driven EPS ($) — assumption | B6: 0 | C6: 0 | D6: 0 | E6: 0 | F6: 2 | G6: 8 | H6: 22 | I6: 40 | J6: 55 | K6: 65 | L6: 70 | M6: 72 | N6: 73
A7: Non-AI EPS ($) = Total - AI | B7: =B5-B6 -> 152 | C7: =C5-C6 -> 157 | D7: =D5-D6 -> 139 | E7: =E5-E6 -> 208 | F7: =F5-F6 -> 216 | G7: =G5-G6 -> 213 | H7: =H5-H6 -> 218 | I7: =I5-I6 -> 222 | ... N7: =N5-N6 -> 302
A8: AI % of Total EPS | B8: =IFERROR(B6/B5,"") -> 0 | C8: =IFERROR(C6/C5,"") -> 0 | D8: =IFERROR(D6/D5,"") -> 0 | E8: =IFERROR(E6/E5,"") -> 0 | F8: =IFERROR(F6/F5,"") -> 0.0091743119 | G8: =IFERROR(G6/G5,"") -> 0.036199095 | H8: =IFERROR(H6/H5,"") -> 0.091666667 | I8: =IFERROR(I6/I5,"") -> 0.15267176 | ... N8: =IFERROR(N6/N5,"") -> 0.19466667
A9: AI EPS YoY % | C9: =IFERROR(C6/B6-1,"") | D9: =IFERROR(D6/C6-1,"") | E9: =IFERROR(E6/D6-1,"") | F9: =IFERROR(F6/E6-1,"") | G9: =IFERROR(G6/F6-1,"") -> 3 | H9: =IFERROR(H6/G6-1,"") -> 1.75 | I9: =IFERROR(I6/H6-1,"") -> 0.81818182 | J9: =IFERROR(J6/I6-1,"") -> 0.375 | ... N9: =IFERROR(N6/M6-1,"") -> 0.013888889
A10: Non-AI EPS YoY % | C10: =IFERROR(C7/B7-1,"") -> 0.032894737 | D10: =IFERROR(D7/C7-1,"") -> -0.11464968 | E10: =IFERROR(E7/D7-1,"") -> 0.49640288 | F10: =IFERROR(F7/E7-1,"") -> 0.038461538 | G10: =IFERROR(G7/F7-1,"") -> -0.013888889 | H10: =IFERROR(H7/G7-1,"") -> 0.023474178 | I10: =IFERROR(I7/H7-1,"") -> 0.018348624 | J10: =IFERROR(J7/I7-1,"") -> -0.009009009 | ... N10: =IFERROR(N7/M7-1,"") -> 0.086330935
A12: B. Dual P/E Valuation — Different Multiples for AI vs Non-AI EPS
A13: Yellow cells = editable assumptions. Change P/E multiples to see impact on implied S&P 500 level.
A14: Non-AI P/E Multiple (editable) | B14: 18 | C14: (historical avg ~18-20x for broad market ex-tech)
A15: AI P/E Multiple (editable) | B15: 35 | C15: (NVDA trades ~30-40x fwd; AI infra basket ~35x)
A17: Metric | B17: 2024A | C17: 2025A | D17: 2026E | E17: 2027E | F17: 2028E | G17: 2029E | H17: 2030E
A18: Non-AI Value Component | B18: =H7*$B$14 -> 3924 | C18: =I7*$B$14 -> 3996 | D18: =J7*$B$14 -> 3960 | E18: =K7*$B$14 -> 4230 | F18: =L7*$B$14 -> 4590 | G18: =M7*$B$14 -> 5004 | H18: =N7*$B$14 -> 5436
A19: AI Value Component | B19: =H6*$B$15 -> 770 | C19: =I6*$B$15 -> 1400 | D19: =J6*$B$15 -> 1925 | E19: =K6*$B$15 -> 2275 | F19: =L6*$B$15 -> 2450 | G19: =M6*$B$15 -> 2520 | H19: =N6*$B$15 -> 2555
A20: Implied S&P 500 Level | B20: =B18+B19 -> 4694 | C20: =C18+C19 -> 5396 | D20: =D18+D19 -> 5885 | E20: =E18+E19 -> 6505 | F20: =F18+F19 -> 7040 | G20: =G18+G19 -> 7524 | H20: =H18+H19 -> 7991
A21: Blended P/E (implied) | B21: =IFERROR(B20/H5,"") -> 19.558333 | C21: =IFERROR(C20/I5,"") -> 20.59542 | D21: =IFERROR(D20/J5,"") -> 21.4 | E21: =IFERROR(E20/K5,"") -> 21.683333 | F21: =IFERROR(F20/L5,"") -> 21.661538 | G21: =IFERROR(G20/M5,"") -> 21.497143 | H21: =IFERROR(H20/N5,"") -> 21.309333
A23: C. Stress Test Scenarios — What if AI Capex Slows / Collapses?
A24: Scenario: Base Case
A25: Current consensus. AI EPS keeps growing as capex sustains.
A26: Metric | B26: 2024A | C26: 2025A | D26: 2026E | E26: 2027E | F26: 2028E | G26: 2029E | H26: 2030E
A27: AI EPS ($) | B27: 22 | C27: 40 | D27: 55 | E27: 65 | F27: 70 | G27: 72 | H27: 73
A28: Non-AI EPS ($) | B28: 218 | C28: 222 | D28: 220 | E28: 235 | F28: 255 | G28: 278 | H28: 302
A29: Implied S&P 500 (AI PE=35x, Other=18x) | B29: =B27*35+B28*18 -> 4694 | C29: =C27*35+C28*18 -> 5396 | D29: =D27*35+D28*18 -> 5885 | E29: =E27*35+E28*18 -> 6505 | F29: =F27*35+F28*18 -> 7040 | G29: =G27*35+G28*18 -> 7524 | H29: =H27*35+H28*18 -> 7991
A31: Scenario: Slowdown (-30% AI EPS)
A32: AI capex growth decelerates 2027+. Nvidia/Broadcom revenue stalls. AI P/E compresses.
