Workbook

Sheet 0. Database
A1: Centralized Database (USD mm except EPS/shares) — Blue = input
A3: Ticker | B3: Metric | C3: 2013A | D3: 2014A | E3: 2015A | F3: 2016A | G3: 2017A | H3: 2018A | I3: 2019A | J3: 2020A | K3: 2021A | L3: 2022A | M3: 2023A | N3: 2024A | O3: 2025E | P3: 2026E | Q3: 2027E | R3: 2028E | S3: 2029E | T3: 2030E
A4: MSFT (FY(Jun))
A5: MSFT | B5: Revenue | C5: 77849 | D5: 86833 | E5: 93580 | F5: 91154 | G5: 96571 | H5: 110360 | I5: 125843 | J5: 143015 | K5: 168088 | L5: 198270 | M5: 211915 | N5: 245122 | O5: 281724 | P5: 319618.35 | Q5: 373106.65 | R5: 445409.63 | S5: 534000.03 | T5: 628544.33
A6: MSFT | B6: Operating Income | C6: 26764 | D6: 27759 | E6: 13359 | F6: 11756 | G6: 11389 | H6: 12924 | I6: 16219 | J6: 18724 | K6: 24351 | L6: 29687 | M6: 50074 | N6: 59661 | O6: 69773 | P6: 79541.62 | Q6: 85628.96 | R6: 69877.51 | S6: 101371.29 | T6: 108509.49
A7: MSFT | B7: Net Income | C7: 21863 | D7: 22074 | E7: 12193 | F7: 16798 | G7: 21204 | H7: 16571 | I7: 39240 | J7: 44281 | K7: 61271 | L7: 72738 | M7: 72361 | N7: 88136 | O7: 101832 | P7: 128773.53 | Q7: 144093.73 | R7: 170374.88 | S7: 198374.44 | T7: 231003.5
A8: MSFT | B8: EPS | C8: 2.58 | D8: 2.63 | E8: 1.48 | F8: 2.1 | G8: 2.71 | H8: 2.13 | I8: 5.06 | J8: 5.76 | K8: 8.05 | L8: 9.65 | M8: 9.68 | N8: 11.8 | O8: 13.64 | P8: 17.280667 | Q8: 19.417143 | R8: 22.809762 | S8: 26.996923 | T8: 31.4925
A9: MSFT | B9: Diluted Shares (mm) | C9: 8470 | D9: 8399 | E9: 8254 | F9: 8013 | G9: 7832 | H9: 7794 | I9: 7753 | J9: 7683 | K9: 7608 | L9: 7540 | M9: 7472 | N9: 7469 | O9: 7465 | P9: 7449.9017 | Q9: 7435.5853 | R9: 7424.3177 | S9: 7387.1205 | T9: 7366.4511
A10: MSFT | B10: SBC | C10: 2197 | D10: 2446 | E10: 2574 | F10: 2668 | G10: 3266 | H10: 3940 | I10: 4652 | J10: 5289 | K10: 6118 | L10: 7502 | M10: 9611 | N10: 10734 | O10: 11974 | P10: 12484.274 | Q10: 13833.136 | R10: 15727.995 | S10: 19055.002 | T10: 21162.66
A11: MSFT | B11: D&A | C11: 3755 | D11: 5212 | E11: 5957 | F11: 6622 | G11: 8778 | H11: 10261 | I11: 11682 | J11: 12796 | K11: 11686 | L11: 14460 | M11: 13861 | N11: 22287 | O11: 34153 | P11: 42005.109 | Q11: 55415.305 | R11: 73946.227 | S11: 97100.106 | T11: 127810.23
A12: MSFT | B12: Capex | C12: 4257 | D12: 5485 | E12: 5944 | F12: 8343 | G12: 8129 | H12: 11632 | I12: 13925 | J12: 15441 | K12: 20622 | L12: 23886 | M12: 28107 | N12: 44477 | O12: 64551 | P12: 117213.77 | Q12: 175938.58 | R12: 195085 | S12: 191785.5 | T12: 196810
A13: MSFT | B13: CFO | C13: 28833 | D13: 32502 | E13: 29668 | F13: 33325 | G13: 39507 | H13: 43884 | I13: 52185 | J13: 60675 | K13: 76740 | L13: 89035 | M13: 87582 | N13: 118548 | O13: 136162 | P13: 173163.84 | Q13: 210868.57 | R13: 255947.12 | S13: 307337.05 | T13: 359926.18
A14: MSFT | B14: FCF | C14: 24576 | D14: 27017 | E14: 23724 | F14: 24982 | G14: 31378 | H14: 32252 | I14: 38260 | J14: 45129 | K14: 56118 | L14: 65149 | M14: 64291 | N14: 74071 | O14: 71611 | P14: 63833.683 | Q14: 40769.753 | R14: 61522.486 | S14: 94794.224 | T14: 137549.86
A15: MSFT | B15: Buybacks | C15: 5360 | D15: 7316 | E15: 14443 | F15: 15969 | G15: 11788 | H15: 10721 | I15: 19543 | J15: 22968 | K15: 27385 | L15: 32696 | M15: 22245 | N15: 17254 | O15: 18420 | P15: 21283.747 | Q15: 20273.417 | R15: 21048.115 | S15: 22626.768 | T15: 24405.726
A16: MSFT | B16: Intell Cloud | C16: 0 | D16: 0 | E16: 0 | F16: 0 | G16: 0 | H16: 0 | I16: 0 | J16: 0 | K16: 0 | L16: 0 | M16: 72314 | N16: 87464 | O16: 106265 | P16: 136688.31 | Q16: 180358.14 | R16: 235873.55 | S16: 304531.45 | T16: 384276.13
... A18: MSFT | B18: Useful Life(yr) | C18: 3.16 | D18: 2.69 | E18: 2.81 | F18: 2.83 | G18: 2.71 | H18: 2.73 | I18: 2.74 | J18: 3.08 | K18: 4.33 | L18: 4.12 | M18: 6.1 | N18: 5.59 | O18: 5.26 | P18: 4.89 | Q18: 4.36 | R18: 4.38 | S18: 4.6 | T18: 4.7
A20: AMZN (CY)
A21: AMZN | B21: Revenue | C21: 41410 | D21: 50834 | E21: 63708 | F21: 79785 | G21: 106110 | H21: 141366 | I21: 170773 | J21: 236282 | K21: 279833 | L21: 315880 | M21: 352828 | N21: 387497 | O21: 426305 | P21: 461081.72 | Q21: 516677.03 | R21: 556072.43 | S21: 599450.61 | T21: 645470.67
A22: AMZN | B22: Operating Income | C22: 673 | D22: 458 | E22: 1507 | F22: 3108 | G22: 4331 | H22: 7296 | I22: 9201 | J22: 13531 | K22: 18532 | L22: 22841 | M22: 24631 | N22: 39834 | O22: 45606 | P22: 58892.45 | Q22: 76144.3 | R22: 98372.18 | S22: 123330.71 | T22: 152115.05
A23: AMZN | B23: Net Income | C23: 274 | D23: -241 | E23: 596 | F23: 2371 | G23: 2244 | H23: 10073 | I23: 11588 | J23: 21331 | K23: 24042 | L23: 7311 | M23: 29793 | N23: 59248 | O23: 77670 | P23: 95381.37 | Q23: 109556.18 | R23: 138562.23 | S23: 162769.35 | T23: 199614.81
A24: AMZN | B24: EPS | C24: 0.0295 | D24: -0.026 | E24: 0.0625 | F24: 0.245 | G24: 0.2275 | H24: 1.007 | I24: 1.1505 | J24: 2.0915 | K24: 2.3341747 | L24: 0.717539 | M24: 2.839592 | N24: 5.53 | O24: 7.17 | P24: 8.7931915 | Q24: 10.028182 | R24: 12.9156 | S24: 14.342727 | T24: 17.133333
A25: AMZN | B25: Diluted Shares (mm) | C25: 9300 | D25: 9240 | E25: 9540 | F25: 9680 | G25: 9860 | H25: 10000 | I25: 10080 | J25: 10200 | K25: 10300 | L25: 10189 | M25: 10492 | N25: 10721 | O25: 10827 | P25: 10899.309 | Q25: 11005.661 | R25: 11088.389 | S25: 11138.956 | T25: 11236.528
A26: AMZN | B26: SBC | C26: 1056 | D26: 1491 | E26: 2119 | F26: 2975 | G26: 4215 | H26: 5418 | I26: 6864 | J26: 9208 | K26: 12757 | L26: 19621 | M26: 24023 | N26: 22011 | O26: 19467 | P26: 19792.578 | Q26: 22146.495 | R26: 24906.477 | S26: 28060.926 | T26: 31047.394
A27: AMZN | B27: D&A | C27: 3253 | D27: 4746 | E27: 6281 | F27: 8116 | G27: 11478 | H27: 15341 | I27: 21789 | J27: 25180 | K27: 34433 | L27: 41921 | M27: 48663 | N27: 52795 | O27: 65756 | P27: 84391.581 | Q27: 107181.82 | R27: 131811.18 | S27: 145951.12 | T27: 164275.19
A28: AMZN | B28: Capex | C28: 3444 | D28: 4893 | E28: 5387 | F28: 7804 | G28: 11955 | H28: 13427 | I28: 16861 | J28: 40140 | K28: 61053 | L28: 63645 | M28: 52729 | N28: 82999 | O28: 131819 | P28: 199073.7 | Q28: 226404.48 | R28: 231478.22 | S28: 222715.44 | T28: 224350.56
A29: AMZN | B29: CFO | C29: 5475 | D29: 6842 | E29: 12039 | F29: 17203 | G29: 18365 | H29: 30723 | I29: 38514 | J29: 66064 | K29: 46327 | L29: 46752 | M29: 84946 | N29: 115877 | O29: 139514 | P29: 183450.99 | Q29: 235811.65 | R29: 295261.25 | S29: 339695.17 | T29: 400510.43
A30: AMZN | B30: FCF | C30: 2031 | D30: 1949 | E30: 6652 | F30: 9399 | G30: 6410 | H30: 17296 | I30: 21653 | J30: 25924 | K30: -14726 | L30: -16893 | M30: 32217 | N30: 32878 | O30: 7695 | P30: -16137.635 | Q30: -1113.9982 | R30: 58782.816 | S30: 115563.17 | T30: 183593.77
A31: AMZN | B31: Buybacks | C31: 0 | D31: 0 | E31: 0 | F31: 0 | G31: 0 | H31: 0 | I31: 0 | J31: 0 | K31: 0 | L31: 6000 | M31: 0 | N31: 0 | O31: 0 | P31: 0 | Q31: 0 | R31: 0 | S31: 0 | T31: 0
A32: AMZN | B32: AWS Rev | C32: 3107.57 | D32: 4644 | E32: 7880 | F32: 12219 | G32: 17458 | H32: 25656 | I32: 35026 | J32: 45370 | K32: 62202 | L32: 80096 | M32: 90757 | N32: 107556 | O32: 128725 | P32: 171284.9 | Q32: 225587.94 | R32: 274421.67 | S32: 323817.58 | T32: 374009.3
A33: AMZN | B33: AWS OI | D33: 458 | E33: 1508 | F33: 3109 | G33: 4331 | H33: 7296 | I33: 9201 | J33: 13531 | K33: 18532 | L33: 22841 | M33: 24631 | N33: 39834 | O33: 45606 | P33: 61254.41 | Q33: 81248.3 | R33: 100888.47 | S33: 121477.03 | T33: 143111.04
A35: GOOGL (CY)
A36: GOOGL | B36: Revenue | C36: 55519 | D36: 66001 | E36: 74989 | F36: 90272 | G36: 110855 | H36: 136819 | I36: 161857 | J36: 182527 | K36: 257637 | L36: 282836 | M36: 307394 | N36: 350018 | O36: 402836 | P36: 486455.79 | Q36: 578508.88 | R36: 684008.77 | S36: 805409.01 | T36: 941245.16
A37: GOOGL | B37: Operating Income | C37: 16260 | D37: 18965 | E37: 23319 | F37: 27055 | G37: 32456 | H37: 43137 | I37: 48999 | J37: 54606 | K37: 91855 | L37: 82699 | M37: 95858 | N37: 121263 | O37: 139404 | P37: 166048.71 | Q37: 188404.24 | R37: 207483.23 | S37: 229196.58 | T37: 258679.36
A38: GOOGL | B38: Net Income | C38: 12214 | D38: 13928 | E38: 15826 | F38: 19478 | G38: 22519 | H38: 30736 | I38: 32508 | J38: 40269 | K38: 76033 | L38: 59972 | M38: 73795 | N38: 100118 | O38: 132170 | P38: 174612.84 | Q38: 180090.27 | R38: 212391.88 | S38: 263167.33 | T38: 322005.86
A39: GOOGL | B39: EPS | C39: 0.90125 | D39: 1.0135 | E39: 1.142 | F39: 1.3925 | G39: 1.6005 | H39: 2.185 | I39: 2.3265 | J39: 2.9305 | K39: 5.61 | L39: 4.56 | M39: 5.8 | N39: 8.04 | O39: 10.81 | P39: 14.186724 | Q39: 14.69 | R39: 17.354848 | S39: 21.248 | T39: 26.035714
A40: GOOGL | B40: Diluted Shares (mm) | C40: 14739.044 | D40: 14839.96 | E40: 14893.5 | F40: 14951.3 | G40: 15014.6 | H40: 15002.98 | I40: 14901.66 | J40: 14664.2 | K40: 14462.08 | L40: 13159 | M40: 12722 | N40: 12447 | O40: 12230 | P40: 12208.564 | Q40: 12183.553 | R40: 12276.514 | S40: 12322.313 | T40: 12302.528
A41: GOOGL | B41: SBC | C41: -3268 | D41: -4175 | E41: -4903 | F41: -6703 | G41: -7679 | H41: -9353 | I41: -10794 | J41: -12991 | K41: -15376 | L41: -19362 | M41: -22460 | N41: -22785 | O41: -24953 | P41: -27937.33 | Q41: -30032.63 | R41: -31979.73 | S41: -33657.1 | T41: -35339.95
A42: GOOGL | B42: D&A | C42: 2781 | D42: 3523 | E42: 4132 | F42: 5267 | G42: 6103 | H42: 8164 | I42: 10856 | J42: 12905 | K42: 11555 | L42: 15287 | M42: 13326 | N42: 15311 | O42: 21136 | P42: 42874.7 | Q42: 69582.72 | R42: 98340.16 | S42: 127674.93 | T42: 156155.17
A43: GOOGL | B43: Capex | C43: 7358 | D43: 10959 | E43: 9950 | F43: 10212 | G43: 13184 | H43: 25139 | I43: 23548 | J43: 22281 | K43: 24640 | L43: 31485 | M43: 32251 | N43: 52535 | O43: 91447 | P43: 186454.02 | Q43: 244373.73 | R43: 260117.7 | S43: 255889.49 | T43: 259990.25
A44: GOOGL | B44: CFO | C44: 18659 | D44: 22376 | E44: 26572 | F44: 36036 | G44: 37091 | H44: 47971 | I44: 54520 | J44: 65124 | K44: 91652 | L44: 91495 | M44: 101746 | N44: 125299 | O44: 164713 | P44: 211732.28 | Q44: 259409.95 | R44: 321961.13 | S44: 388350.35 | T44: 469096.49
...

Sheet 1. Revenue & Growth
A1: Revenue&AI/CloudSegment Detail (2013-2030E)
A3: A. Total Revenue ($mm)
A4: Company | B4: 2013A | C4: 2014A | D4: 2015A | E4: 2016A | F4: 2017A | G4: 2018A | H4: 2019A | I4: 2020A | J4: 2021A | K4: 2022A | L4: 2023A | M4: 2024A | N4: 2025E | O4: 2026E | P4: 2027E | Q4: 2028E | R4: 2029E | S4: 2030E
A5: MSFT | B5: ='0. Database'!C5 -> 77849 | C5: ='0. Database'!D5 -> 86833 | D5: ='0. Database'!E5 -> 93580 | E5: ='0. Database'!F5 -> 91154 | F5: ='0. Database'!G5 -> 96571 | G5: ='0. Database'!H5 -> 110360 | H5: ='0. Database'!I5 -> 125843 | I5: ='0. Database'!J5 -> 143015 | ... S5: ='0. Database'!T5 -> 628544.33
A6: AMZN | B6: ='0. Database'!C21 -> 41410 | C6: ='0. Database'!D21 -> 50834 | D6: ='0. Database'!E21 -> 63708 | E6: ='0. Database'!F21 -> 79785 | F6: ='0. Database'!G21 -> 106110 | G6: ='0. Database'!H21 -> 141366 | H6: ='0. Database'!I21 -> 170773 | I6: ='0. Database'!J21 -> 236282 | ... S6: ='0. Database'!T21 -> 645470.67
A7: GOOGL | B7: ='0. Database'!C36 -> 55519 | C7: ='0. Database'!D36 -> 66001 | D7: ='0. Database'!E36 -> 74989 | E7: ='0. Database'!F36 -> 90272 | F7: ='0. Database'!G36 -> 110855 | G7: ='0. Database'!H36 -> 136819 | H7: ='0. Database'!I36 -> 161857 | I7: ='0. Database'!J36 -> 182527 | ... S7: ='0. Database'!T36 -> 941245.16
A8: META | B8: ='0. Database'!C53 -> 7872 | C8: ='0. Database'!D53 -> 12466 | D8: ='0. Database'!E53 -> 17928 | E8: ='0. Database'!F53 -> 27638 | F8: ='0. Database'!G53 -> 40653 | G8: ='0. Database'!H53 -> 55838 | H8: ='0. Database'!I53 -> 70196 | I8: ='0. Database'!J53 -> 84826 | ... S8: ='0. Database'!T53 -> 448874.02
A9: ORCL | B9: ='0. Database'!C71 -> 37180 | C9: ='0. Database'!D71 -> 38275 | D9: ='0. Database'!E71 -> 38226 | E9: ='0. Database'!F71 -> 37047 | F9: ='0. Database'!G71 -> 37728 | G9: ='0. Database'!H71 -> 39383 | H9: ='0. Database'!I71 -> 39506 | I9: ='0. Database'!J71 -> 39068 | ... S9: ='0. Database'!T71 -> 223941.18
A11: C. Cloud / AI Proxy Revenue ($mm)
A12: Company | B12: 2013A | C12: 2014A | D12: 2015A | E12: 2016A | F12: 2017A | G12: 2018A | H12: 2019A | I12: 2020A | J12: 2021A | K12: 2022A | L12: 2023A | M12: 2024A | N12: 2025E | O12: 2026E | P12: 2027E | Q12: 2028E | R12: 2029E | S12: 2030E
A13: MSFT — Azure
A14: AMZN — AWS | B14: ='0. Database'!C32 -> 3107.57 | C14: ='0. Database'!D32 -> 4644 | D14: ='0. Database'!E32 -> 7880 | E14: ='0. Database'!F32 -> 12219 | F14: ='0. Database'!G32 -> 17458 | G14: ='0. Database'!H32 -> 25656 | H14: ='0. Database'!I32 -> 35026 | I14: ='0. Database'!J32 -> 45370 | ... S14: ='0. Database'!T32 -> 374009.3
A15: GOOGL — Cloud | B15: ='0. Database'!C47 -> 0 | C15: ='0. Database'!D47 -> 0 | D15: ='0. Database'!E47 -> 0 | E15: ='0. Database'!F47 -> 0 | F15: ='0. Database'!G47 -> 4056 | G15: ='0. Database'!H47 -> 5838 | H15: ='0. Database'!I47 -> 8918 | I15: ='0. Database'!J47 -> 13059 | ... S15: ='0. Database'!T47 -> 343551.74
A16: META — Advertising | B16: ='0. Database'!C64 -> 6986 | C16: ='0. Database'!D64 -> 11492 | D16: ='0. Database'!E64 -> 17080 | E16: ='0. Database'!F64 -> 26885 | F16: ='0. Database'!G64 -> 39942 | G16: ='0. Database'!H64 -> 55012 | H16: ='0. Database'!I64 -> 69654.5 | I16: ='0. Database'!J64 -> 84169 | ... S16: ='0. Database'!T64 -> 444912.31
A17: ORCL — CloudTotalRevenue | B17: ='0. Database'!C82 -> 37180 | C17: ='0. Database'!D82 -> 38275 | D17: ='0. Database'!E82 -> 38226 | E17: ='0. Database'!F82 -> 37047 | F17: ='0. Database'!G82 -> 37728 | G17: ='0. Database'!H82 -> 39383 | H17: ='0. Database'!I82 -> 39506 | I17: ='0. Database'!J82 -> 39068 | ... S17: ='0. Database'!T82 -> 223941.18
A19: B. Revenue YoY %
A20: Company | B20: 2013A | C20: 2014A | D20: 2015A | E20: 2016A | F20: 2017A | G20: 2018A | H20: 2019A | I20: 2020A | J20: 2021A | K20: 2022A | L20: 2023A | M20: 2024A | N20: 2025E | O20: 2026E | P20: 2027E | Q20: 2028E | R20: 2029E | S20: 2030E
A21: MSFT | C21: =IFERROR(C5/B5-1,"") -> 0.1154029 | D21: =IFERROR(D5/C5-1,"") -> 0.077700874 | E21: =IFERROR(E5/D5-1,"") -> -0.025924343 | F21: =IFERROR(F5/E5-1,"") -> 0.059426904 | G21: =IFERROR(G5/F5-1,"") -> 0.14278614 | H21: =IFERROR(H5/G5-1,"") -> 0.1402954 | I21: =IFERROR(I5/H5-1,"") -> 0.13645574 | J21: =IFERROR(J5/I5-1,"") -> 0.17531727 | ... S21: =IFERROR(S5/R5-1,"") -> 0.17704924
A22: AMZN | C22: =IFERROR(C6/B6-1,"") -> 0.22757788 | D22: =IFERROR(D6/C6-1,"") -> 0.2532557 | E22: =IFERROR(E6/D6-1,"") -> 0.25235449 | F22: =IFERROR(F6/E6-1,"") -> 0.32994924 | G22: =IFERROR(G6/F6-1,"") -> 0.33225898 | H22: =IFERROR(H6/G6-1,"") -> 0.20802032 | I22: =IFERROR(I6/H6-1,"") -> 0.38360279 | J22: =IFERROR(J6/I6-1,"") -> 0.18431789 | ... S22: =IFERROR(S6/R6-1,"") -> 0.076770408
A23: GOOGL | C23: =IFERROR(C7/B7-1,"") -> 0.18880023 | D23: =IFERROR(D7/C7-1,"") -> 0.13617975 | E23: =IFERROR(E7/D7-1,"") -> 0.20380322 | F23: =IFERROR(F7/E7-1,"") -> 0.2280109 | G23: =IFERROR(G7/F7-1,"") -> 0.23421587 | H23: =IFERROR(H7/G7-1,"") -> 0.1830009 | I23: =IFERROR(I7/H7-1,"") -> 0.12770532 | J23: =IFERROR(J7/I7-1,"") -> 0.41150076 | ... S23: =IFERROR(S7/R7-1,"") -> 0.16865486
A24: META | C24: =IFERROR(C8/B8-1,"") -> 0.5835874 | D24: =IFERROR(D8/C8-1,"") -> 0.43815177 | E24: =IFERROR(E8/D8-1,"") -> 0.54161089 | F24: =IFERROR(F8/E8-1,"") -> 0.47090962 | G24: =IFERROR(G8/F8-1,"") -> 0.37352717 | H24: =IFERROR(H8/G8-1,"") -> 0.25713672 | I24: =IFERROR(I8/H8-1,"") -> 0.20841643 | J24: =IFERROR(J8/I8-1,"") -> 0.3634381 | ... S24: =IFERROR(S8/R8-1,"") -> 0.12891139
A25: ORCL | C25: =IFERROR(C9/B9-1,"") -> 0.029451318 | D25: =IFERROR(D9/C9-1,"") -> -0.001280209 | E25: =IFERROR(E9/D9-1,"") -> -0.030842882 | F25: =IFERROR(F9/E9-1,"") -> 0.018382055 | G25: =IFERROR(G9/F9-1,"") -> 0.043866624 | H25: =IFERROR(H9/G9-1,"") -> 0.003123175 | I25: =IFERROR(I9/H9-1,"") -> -0.011086924 | J25: =IFERROR(J9/I9-1,"") -> 0.036116515 | ... S25: =IFERROR(S9/R9-1,"") -> 0.21405103

Sheet 2. Capex & D&A
A1: Capex&D&A (2013-2030E)
A3: A. Capex ($mm)
A4: Company | B4: 2013A | C4: 2014A | D4: 2015A | E4: 2016A | F4: 2017A | G4: 2018A | H4: 2019A | I4: 2020A | J4: 2021A | K4: 2022A | L4: 2023A | M4: 2024A | N4: 2025E | O4: 2026E | P4: 2027E | Q4: 2028E | R4: 2029E | S4: 2030E
A5: MSFT | B5: ='0. Database'!C12 -> 4257 | C5: ='0. Database'!D12 -> 5485 | D5: ='0. Database'!E12 -> 5944 | E5: ='0. Database'!F12 -> 8343 | F5: ='0. Database'!G12 -> 8129 | G5: ='0. Database'!H12 -> 11632 | H5: ='0. Database'!I12 -> 13925 | I5: ='0. Database'!J12 -> 15441 | ... S5: ='0. Database'!T12 -> 196810
A6: AMZN | B6: ='0. Database'!C28 -> 3444 | C6: ='0. Database'!D28 -> 4893 | D6: ='0. Database'!E28 -> 5387 | E6: ='0. Database'!F28 -> 7804 | F6: ='0. Database'!G28 -> 11955 | G6: ='0. Database'!H28 -> 13427 | H6: ='0. Database'!I28 -> 16861 | I6: ='0. Database'!J28 -> 40140 | ... S6: ='0. Database'!T28 -> 224350.56
A7: GOOGL | B7: ='0. Database'!C43 -> 7358 | C7: ='0. Database'!D43 -> 10959 | D7: ='0. Database'!E43 -> 9950 | E7: ='0. Database'!F43 -> 10212 | F7: ='0. Database'!G43 -> 13184 | G7: ='0. Database'!H43 -> 25139 | H7: ='0. Database'!I43 -> 23548 | I7: ='0. Database'!J43 -> 22281 | ... S7: ='0. Database'!T43 -> 259990.25
A8: META | B8: ='0. Database'!C60 -> 1362 | C8: ='0. Database'!D60 -> 1831 | D8: ='0. Database'!E60 -> 2523 | E8: ='0. Database'!F60 -> 4491 | F8: ='0. Database'!G60 -> 6733 | G8: ='0. Database'!H60 -> 13915 | H8: ='0. Database'!I60 -> 15102 | I8: ='0. Database'!J60 -> 15163 | ... S8: ='0. Database'!T60 -> 180526.35
A9: ORCL | B9: ='0. Database'!C78 -> 650 | C9: ='0. Database'!D78 -> 580 | D9: ='0. Database'!E78 -> 1391 | E9: ='0. Database'!F78 -> 1189 | F9: ='0. Database'!G78 -> 2021 | G9: ='0. Database'!H78 -> 1736 | H9: ='0. Database'!I78 -> 1660 | I9: ='0. Database'!J78 -> 1564 | ... S9: ='0. Database'!T78 -> 77098.125
A11: D. D&A ($mm)
A12: Company | B12: 2013A | C12: 2014A | D12: 2015A | E12: 2016A | F12: 2017A | G12: 2018A | H12: 2019A | I12: 2020A | J12: 2021A | K12: 2022A | L12: 2023A | M12: 2024A | N12: 2025E | O12: 2026E | P12: 2027E | Q12: 2028E | R12: 2029E | S12: 2030E
A13: MSFT | B13: ='0. Database'!C11 -> 3755 | C13: ='0. Database'!D11 -> 5212 | D13: ='0. Database'!E11 -> 5957 | E13: ='0. Database'!F11 -> 6622 | F13: ='0. Database'!G11 -> 8778 | G13: ='0. Database'!H11 -> 10261 | H13: ='0. Database'!I11 -> 11682 | I13: ='0. Database'!J11 -> 12796 | ... S13: ='0. Database'!T11 -> 127810.23
A14: AMZN | B14: ='0. Database'!C27 -> 3253 | C14: ='0. Database'!D27 -> 4746 | D14: ='0. Database'!E27 -> 6281 | E14: ='0. Database'!F27 -> 8116 | F14: ='0. Database'!G27 -> 11478 | G14: ='0. Database'!H27 -> 15341 | H14: ='0. Database'!I27 -> 21789 | I14: ='0. Database'!J27 -> 25180 | ... S14: ='0. Database'!T27 -> 164275.19
A15: GOOGL | B15: ='0. Database'!C42 -> 2781 | C15: ='0. Database'!D42 -> 3523 | D15: ='0. Database'!E42 -> 4132 | E15: ='0. Database'!F42 -> 5267 | F15: ='0. Database'!G42 -> 6103 | G15: ='0. Database'!H42 -> 8164 | H15: ='0. Database'!I42 -> 10856 | I15: ='0. Database'!J42 -> 12905 | ... S15: ='0. Database'!T42 -> 156155.17
A16: META | B16: ='0. Database'!C59 -> 1011 | C16: ='0. Database'!D59 -> 1243 | D16: ='0. Database'!E59 -> 1945 | E16: ='0. Database'!F59 -> 2342 | F16: ='0. Database'!G59 -> 3025 | G16: ='0. Database'!H59 -> 4315 | H16: ='0. Database'!I59 -> 5741 | I16: ='0. Database'!J59 -> 6862 | ... S16: ='0. Database'!T59 -> 87724.365
A17: ORCL | B17: ='0. Database'!C77 -> 2931 | C17: ='0. Database'!D77 -> 2908 | D17: ='0. Database'!E77 -> 2861 | E17: ='0. Database'!F77 -> 2509 | F17: ='0. Database'!G77 -> 2451 | G17: ='0. Database'!H77 -> 2785 | H17: ='0. Database'!I77 -> 2919 | I17: ='0. Database'!J77 -> 2968 | ... S17: ='0. Database'!T77 -> 37972.181
A19: (Revenue — for ratios)
A20: Company | B20: 2013A | C20: 2014A | D20: 2015A | E20: 2016A | F20: 2017A | G20: 2018A | H20: 2019A | I20: 2020A | J20: 2021A | K20: 2022A | L20: 2023A | M20: 2024A | N20: 2025E | O20: 2026E | P20: 2027E | Q20: 2028E | R20: 2029E | S20: 2030E
A21: MSFT | B21: ='0. Database'!C5 -> 77849 | C21: ='0. Database'!D5 -> 86833 | D21: ='0. Database'!E5 -> 93580 | E21: ='0. Database'!F5 -> 91154 | F21: ='0. Database'!G5 -> 96571 | G21: ='0. Database'!H5 -> 110360 | H21: ='0. Database'!I5 -> 125843 | I21: ='0. Database'!J5 -> 143015 | ... S21: ='0. Database'!T5 -> 628544.33
A22: AMZN | B22: ='0. Database'!C21 -> 41410 | C22: ='0. Database'!D21 -> 50834 | D22: ='0. Database'!E21 -> 63708 | E22: ='0. Database'!F21 -> 79785 | F22: ='0. Database'!G21 -> 106110 | G22: ='0. Database'!H21 -> 141366 | H22: ='0. Database'!I21 -> 170773 | I22: ='0. Database'!J21 -> 236282 | ... S22: ='0. Database'!T21 -> 645470.67
A23: GOOGL | B23: ='0. Database'!C36 -> 55519 | C23: ='0. Database'!D36 -> 66001 | D23: ='0. Database'!E36 -> 74989 | E23: ='0. Database'!F36 -> 90272 | F23: ='0. Database'!G36 -> 110855 | G23: ='0. Database'!H36 -> 136819 | H23: ='0. Database'!I36 -> 161857 | I23: ='0. Database'!J36 -> 182527 | ... S23: ='0. Database'!T36 -> 941245.16
A24: META | B24: ='0. Database'!C53 -> 7872 | C24: ='0. Database'!D53 -> 12466 | D24: ='0. Database'!E53 -> 17928 | E24: ='0. Database'!F53 -> 27638 | F24: ='0. Database'!G53 -> 40653 | G24: ='0. Database'!H53 -> 55838 | H24: ='0. Database'!I53 -> 70196 | I24: ='0. Database'!J53 -> 84826 | ... S24: ='0. Database'!T53 -> 448874.02
A25: ORCL | B25: ='0. Database'!C71 -> 37180 | C25: ='0. Database'!D71 -> 38275 | D25: ='0. Database'!E71 -> 38226 | E25: ='0. Database'!F71 -> 37047 | F25: ='0. Database'!G71 -> 37728 | G25: ='0. Database'!H71 -> 39383 | H25: ='0. Database'!I71 -> 39506 | I25: ='0. Database'!J71 -> 39068 | ... S25: ='0. Database'!T71 -> 223941.18
A27: B. CapexYoY %
A28: Company | B28: 2013A | C28: 2014A | D28: 2015A | E28: 2016A | F28: 2017A | G28: 2018A | H28: 2019A | I28: 2020A | J28: 2021A | K28: 2022A | L28: 2023A | M28: 2024A | N28: 2025E | O28: 2026E | P28: 2027E | Q28: 2028E | R28: 2029E | S28: 2030E
A29: MSFT | C29: =IFERROR(C5/B5-1,"") -> 0.28846606 | D29: =IFERROR(D5/C5-1,"") -> 0.083682771 | E29: =IFERROR(E5/D5-1,"") -> 0.40360027 | F29: =IFERROR(F5/E5-1,"") -> -0.025650246 | G29: =IFERROR(G5/F5-1,"") -> 0.43092631 | H29: =IFERROR(H5/G5-1,"") -> 0.19712861 | I29: =IFERROR(I5/H5-1,"") -> 0.10886894 | J29: =IFERROR(J5/I5-1,"") -> 0.33553526 | ... S29: =IFERROR(S5/R5-1,"") -> 0.02619854
A30: AMZN | C30: =IFERROR(C6/B6-1,"") -> 0.42073171 | D30: =IFERROR(D6/C6-1,"") -> 0.10096056 | E30: =IFERROR(E6/D6-1,"") -> 0.44867273 | F30: =IFERROR(F6/E6-1,"") -> 0.53190671 | G30: =IFERROR(G6/F6-1,"") -> 0.1231284 | H30: =IFERROR(H6/G6-1,"") -> 0.25575333 | I30: =IFERROR(I6/H6-1,"") -> 1.3806417 | J30: =IFERROR(J6/I6-1,"") -> 0.52100149 | ... S30: =IFERROR(S6/R6-1,"") -> 0.0073417051
A31: GOOGL | C31: =IFERROR(C7/B7-1,"") -> 0.48939929 | D31: =IFERROR(D7/C7-1,"") -> -0.092070444 | E31: =IFERROR(E7/D7-1,"") -> 0.026331658 | F31: =IFERROR(F7/E7-1,"") -> 0.29103016 | G31: =IFERROR(G7/F7-1,"") -> 0.90678095 | H31: =IFERROR(H7/G7-1,"") -> -0.063288118 | I31: =IFERROR(I7/H7-1,"") -> -0.053804994 | J31: =IFERROR(J7/I7-1,"") -> 0.10587496 | ... S31: =IFERROR(S7/R7-1,"") -> 0.0160255
A32: META | C32: =IFERROR(C8/B8-1,"") -> 0.34434655 | D32: =IFERROR(D8/C8-1,"") -> 0.37793555 | E32: =IFERROR(E8/D8-1,"") -> 0.78002378 | F32: =IFERROR(F8/E8-1,"") -> 0.49922066 | G32: =IFERROR(G8/F8-1,"") -> 1.0666865 | H32: =IFERROR(H8/G8-1,"") -> 0.085303629 | I32: =IFERROR(I8/H8-1,"") -> 0.0040392001 | J32: =IFERROR(J8/I8-1,"") -> 0.23260568 | ... S32: =IFERROR(S8/R8-1,"") -> 0.034644141
A33: ORCL | C33: =IFERROR(C9/B9-1,"") -> -0.10769231 | D33: =IFERROR(D9/C9-1,"") -> 1.3982759 | E33: =IFERROR(E9/D9-1,"") -> -0.14521927 | F33: =IFERROR(F9/E9-1,"") -> 0.69974769 | G33: =IFERROR(G9/F9-1,"") -> -0.1410193 | H33: =IFERROR(H9/G9-1,"") -> -0.043778802 | I33: =IFERROR(I9/H9-1,"") -> -0.057831325 | J33: =IFERROR(J9/I9-1,"") -> 0.36508951 | ... S33: =IFERROR(S9/R9-1,"") -> -0.11537516
A35: C. Capex / Revenue %
A36: Company | B36: 2013A | C36: 2014A | D36: 2015A | E36: 2016A | F36: 2017A | G36: 2018A | H36: 2019A | I36: 2020A | J36: 2021A | K36: 2022A | L36: 2023A | M36: 2024A | N36: 2025E | O36: 2026E | P36: 2027E | Q36: 2028E | R36: 2029E | S36: 2030E
A37: MSFT | B37: =IFERROR(B5/B21,"") -> 0.054682783 | C37: =IFERROR(C5/C21,"") -> 0.063167229 | D37: =IFERROR(D5/D21,"") -> 0.063517846 | E37: =IFERROR(E5/E21,"") -> 0.091526428 | F37: =IFERROR(F5/F21,"") -> 0.084176409 | G37: =IFERROR(G5/G21,"") -> 0.10540051 | H37: =IFERROR(H5/H21,"") -> 0.11065375 | I37: =IFERROR(I5/I21,"") -> 0.1079677 | ... S37: =IFERROR(S5/S21,"") -> 0.31312032
A38: AMZN | B38: =IFERROR(B6/B22,"") -> 0.083168317 | C38: =IFERROR(C6/C22,"") -> 0.096254475 | D38: =IFERROR(D6/D22,"") -> 0.084557669 | E38: =IFERROR(E6/E22,"") -> 0.097812872 | F38: =IFERROR(F6/F22,"") -> 0.1126661 | G38: =IFERROR(G6/G22,"") -> 0.094980405 | H38: =IFERROR(H6/H22,"") -> 0.098733406 | I38: =IFERROR(I6/I22,"") -> 0.16988175 | ... S38: =IFERROR(S6/S22,"") -> 0.34757668
A39: GOOGL | B39: =IFERROR(B7/B23,"") -> 0.13253121 | C39: =IFERROR(C7/C23,"") -> 0.16604294 | D39: =IFERROR(D7/D23,"") -> 0.13268613 | E39: =IFERROR(E7/E23,"") -> 0.11312478 | F39: =IFERROR(F7/F23,"") -> 0.11893013 | G39: =IFERROR(G7/G23,"") -> 0.1837391 | H39: =IFERROR(H7/H23,"") -> 0.14548645 | I39: =IFERROR(I7/I23,"") -> 0.12206961 | ... S39: =IFERROR(S7/S23,"") -> 0.27621948
A40: META | B40: =IFERROR(B8/B24,"") -> 0.17301829 | C40: =IFERROR(C8/C24,"") -> 0.14687951 | D40: =IFERROR(D8/D24,"") -> 0.14072959 | E40: =IFERROR(E8/E24,"") -> 0.16249367 | F40: =IFERROR(F8/F24,"") -> 0.16562123 | G40: =IFERROR(G8/G24,"") -> 0.24920305 | H40: =IFERROR(H8/H24,"") -> 0.21514046 | I40: =IFERROR(I8/I24,"") -> 0.17875416 | ... S40: =IFERROR(S8/S24,"") -> 0.40217598
A41: ORCL | B41: =IFERROR(B9/B25,"") -> 0.017482517 | C41: =IFERROR(C9/C25,"") -> 0.015153494 | D41: =IFERROR(D9/D25,"") -> 0.036388845 | E41: =IFERROR(E9/E25,"") -> 0.032094367 | F41: =IFERROR(F9/F25,"") -> 0.053567642 | G41: =IFERROR(G9/G25,"") -> 0.044079933 | H41: =IFERROR(H9/H25,"") -> 0.042018934 | I41: =IFERROR(I9/I25,"") -> 0.040032763 | ... S41: =IFERROR(S9/S25,"") -> 0.34427846
A43: E. D&A / Revenue %
A44: Company | B44: 2013A | C44: 2014A | D44: 2015A | E44: 2016A | F44: 2017A | G44: 2018A | H44: 2019A | I44: 2020A | J44: 2021A | K44: 2022A | L44: 2023A | M44: 2024A | N44: 2025E | O44: 2026E | P44: 2027E | Q44: 2028E | R44: 2029E | S44: 2030E
A45: MSFT | B45: =IFERROR(B13/B21,"") -> 0.048234402 | C45: =IFERROR(C13/C21,"") -> 0.060023263 | D45: =IFERROR(D13/D21,"") -> 0.063656764 | E45: =IFERROR(E13/E21,"") -> 0.072646291 | F45: =IFERROR(F13/F21,"") -> 0.090896853 | G45: =IFERROR(G13/G21,"") -> 0.092977528 | H45: =IFERROR(H13/H21,"") -> 0.092829955 | I45: =IFERROR(I13/I21,"") -> 0.089473132 | ... S45: =IFERROR(S13/S21,"") -> 0.20334322
A46: AMZN | B46: =IFERROR(B14/B22,"") -> 0.078555904 | C46: =IFERROR(C14/C22,"") -> 0.09336271 | D46: =IFERROR(D14/D22,"") -> 0.098590444 | E46: =IFERROR(E14/E22,"") -> 0.10172338 | F46: =IFERROR(F14/F22,"") -> 0.10817077 | G46: =IFERROR(G14/G22,"") -> 0.10851973 | H46: =IFERROR(H14/H22,"") -> 0.12759043 | I46: =IFERROR(I14/I22,"") -> 0.10656758 | ... S46: =IFERROR(S14/S22,"") -> 0.25450451
...

Sheet 3. FCF & Cash
A1: Free Cash Flow&Cash Quality (2013-2030E)
A3: A. CFO ($mm)
A4: Company | B4: 2013A | C4: 2014A | D4: 2015A | E4: 2016A | F4: 2017A | G4: 2018A | H4: 2019A | I4: 2020A | J4: 2021A | K4: 2022A | L4: 2023A | M4: 2024A | N4: 2025E | O4: 2026E | P4: 2027E | Q4: 2028E | R4: 2029E | S4: 2030E
A5: MSFT | B5: ='0. Database'!C13 -> 28833 | C5: ='0. Database'!D13 -> 32502 | D5: ='0. Database'!E13 -> 29668 | E5: ='0. Database'!F13 -> 33325 | F5: ='0. Database'!G13 -> 39507 | G5: ='0. Database'!H13 -> 43884 | H5: ='0. Database'!I13 -> 52185 | I5: ='0. Database'!J13 -> 60675 | ... S5: ='0. Database'!T13 -> 359926.18
A6: AMZN | B6: ='0. Database'!C29 -> 5475 | C6: ='0. Database'!D29 -> 6842 | D6: ='0. Database'!E29 -> 12039 | E6: ='0. Database'!F29 -> 17203 | F6: ='0. Database'!G29 -> 18365 | G6: ='0. Database'!H29 -> 30723 | H6: ='0. Database'!I29 -> 38514 | I6: ='0. Database'!J29 -> 66064 | ... S6: ='0. Database'!T29 -> 400510.43
A7: GOOGL | B7: ='0. Database'!C44 -> 18659 | C7: ='0. Database'!D44 -> 22376 | D7: ='0. Database'!E44 -> 26572 | E7: ='0. Database'!F44 -> 36036 | F7: ='0. Database'!G44 -> 37091 | G7: ='0. Database'!H44 -> 47971 | H7: ='0. Database'!I44 -> 54520 | I7: ='0. Database'!J44 -> 65124 | ... S7: ='0. Database'!T44 -> 469096.49
A8: META | B8: ='0. Database'!C61 -> 4222 | C8: ='0. Database'!D61 -> 5457 | D8: ='0. Database'!E61 -> 8599 | E8: ='0. Database'!F61 -> 16108 | F8: ='0. Database'!G61 -> 24216 | G8: ='0. Database'!H61 -> 29274 | H8: ='0. Database'!I61 -> 36314 | I8: ='0. Database'!J61 -> 38747 | ... S8: ='0. Database'!T61 -> 283498.22
A9: ORCL | B9: ='0. Database'!C79 -> 14224 | C9: ='0. Database'!D79 -> 14921 | D9: ='0. Database'!E79 -> 14580 | E9: ='0. Database'!F79 -> 13685 | F9: ='0. Database'!G79 -> 14126 | G9: ='0. Database'!H79 -> 15386 | H9: ='0. Database'!I79 -> 14551 | I9: ='0. Database'!J79 -> 13139 | ... S9: ='0. Database'!T79 -> 102585.67
A11: B. FCF ($mm)
A12: Company | B12: 2013A | C12: 2014A | D12: 2015A | E12: 2016A | F12: 2017A | G12: 2018A | H12: 2019A | I12: 2020A | J12: 2021A | K12: 2022A | L12: 2023A | M12: 2024A | N12: 2025E | O12: 2026E | P12: 2027E | Q12: 2028E | R12: 2029E | S12: 2030E
A13: MSFT | B13: ='0. Database'!C14 -> 24576 | C13: ='0. Database'!D14 -> 27017 | D13: ='0. Database'!E14 -> 23724 | E13: ='0. Database'!F14 -> 24982 | F13: ='0. Database'!G14 -> 31378 | G13: ='0. Database'!H14 -> 32252 | H13: ='0. Database'!I14 -> 38260 | I13: ='0. Database'!J14 -> 45129 | ... S13: ='0. Database'!T14 -> 137549.86
A14: AMZN | B14: ='0. Database'!C30 -> 2031 | C14: ='0. Database'!D30 -> 1949 | D14: ='0. Database'!E30 -> 6652 | E14: ='0. Database'!F30 -> 9399 | F14: ='0. Database'!G30 -> 6410 | G14: ='0. Database'!H30 -> 17296 | H14: ='0. Database'!I30 -> 21653 | I14: ='0. Database'!J30 -> 25924 | ... S14: ='0. Database'!T30 -> 183593.77
A15: GOOGL | B15: ='0. Database'!C45 -> 11301 | C15: ='0. Database'!D45 -> 11417 | D15: ='0. Database'!E45 -> 20579 | E15: ='0. Database'!F45 -> 25853 | F15: ='0. Database'!G45 -> 23907 | G15: ='0. Database'!H45 -> 22832 | H15: ='0. Database'!I45 -> 30972 | I15: ='0. Database'!J45 -> 42843 | ... S15: ='0. Database'!T45 -> 168272.55
A16: META | B16: ='0. Database'!C62 -> 2849 | C16: ='0. Database'!D62 -> 3626 | D16: ='0. Database'!E62 -> 6076 | E16: ='0. Database'!F62 -> 11617 | F16: ='0. Database'!G62 -> 17483 | G16: ='0. Database'!H62 -> 15359 | H16: ='0. Database'!I62 -> 21212 | I16: ='0. Database'!J62 -> 23584 | ... S16: ='0. Database'!T62 -> 98032.852
A17: ORCL | B17: ='0. Database'!C80 -> 13574 | C17: ='0. Database'!D80 -> 14341 | D17: ='0. Database'!E80 -> 13189 | E17: ='0. Database'!F80 -> 12496 | F17: ='0. Database'!G80 -> 12105 | G17: ='0. Database'!H80 -> 13650 | H17: ='0. Database'!I80 -> 12891 | I17: ='0. Database'!J80 -> 11575 | ... S17: ='0. Database'!T80 -> 27298.067
A19: E. Buybacks ($mm)
A20: Company | B20: 2013A | C20: 2014A | D20: 2015A | E20: 2016A | F20: 2017A | G20: 2018A | H20: 2019A | I20: 2020A | J20: 2021A | K20: 2022A | L20: 2023A | M20: 2024A | N20: 2025E | O20: 2026E | P20: 2027E | Q20: 2028E | R20: 2029E | S20: 2030E
A21: MSFT | B21: ='0. Database'!C15 -> 5360 | C21: ='0. Database'!D15 -> 7316 | D21: ='0. Database'!E15 -> 14443 | E21: ='0. Database'!F15 -> 15969 | F21: ='0. Database'!G15 -> 11788 | G21: ='0. Database'!H15 -> 10721 | H21: ='0. Database'!I15 -> 19543 | I21: ='0. Database'!J15 -> 22968 | ... S21: ='0. Database'!T15 -> 24405.726
A22: AMZN | B22: ='0. Database'!C31 -> 0 | C22: ='0. Database'!D31 -> 0 | D22: ='0. Database'!E31 -> 0 | E22: ='0. Database'!F31 -> 0 | F22: ='0. Database'!G31 -> 0 | G22: ='0. Database'!H31 -> 0 | H22: ='0. Database'!I31 -> 0 | I22: ='0. Database'!J31 -> 0 | ... S22: ='0. Database'!T31 -> 0
A23: GOOGL | B23: ='0. Database'!C46 -> 0 | C23: ='0. Database'!D46 -> 0 | D23: ='0. Database'!E46 -> 1780 | E23: ='0. Database'!F46 -> 3693 | F23: ='0. Database'!G46 -> 4846 | G23: ='0. Database'!H46 -> 9075 | H23: ='0. Database'!I46 -> 18396 | I23: ='0. Database'!J46 -> 31149 | ... S23: ='0. Database'!T46 -> 56980.327
A24: META | B24: ='0. Database'!C63 -> 0 | C24: ='0. Database'!D63 -> 0 | D24: ='0. Database'!E63 -> 0 | E24: ='0. Database'!F63 -> 0 | F24: ='0. Database'!G63 -> 5222 | G24: ='0. Database'!H63 -> 16087 | H24: ='0. Database'!I63 -> 6539 | I24: ='0. Database'!J63 -> 9836 | ... S24: ='0. Database'!T63 -> 6000
A25: ORCL | B25: ='0. Database'!C81 -> 11021 | C25: ='0. Database'!D81 -> 9813 | D25: ='0. Database'!E81 -> 8087 | E25: ='0. Database'!F81 -> 10440 | F25: ='0. Database'!G81 -> 3561 | G25: ='0. Database'!H81 -> 11347 | H25: ='0. Database'!I81 -> 36140 | I25: ='0. Database'!J81 -> 19240 | ... S25: ='0. Database'!T81 -> 0
A27: (Revenue)
A28: Company | B28: 2013A | C28: 2014A | D28: 2015A | E28: 2016A | F28: 2017A | G28: 2018A | H28: 2019A | I28: 2020A | J28: 2021A | K28: 2022A | L28: 2023A | M28: 2024A | N28: 2025E | O28: 2026E | P28: 2027E | Q28: 2028E | R28: 2029E | S28: 2030E
A29: MSFT | B29: ='0. Database'!C5 -> 77849 | C29: ='0. Database'!D5 -> 86833 | D29: ='0. Database'!E5 -> 93580 | E29: ='0. Database'!F5 -> 91154 | F29: ='0. Database'!G5 -> 96571 | G29: ='0. Database'!H5 -> 110360 | H29: ='0. Database'!I5 -> 125843 | I29: ='0. Database'!J5 -> 143015 | ... S29: ='0. Database'!T5 -> 628544.33
A30: AMZN | B30: ='0. Database'!C21 -> 41410 | C30: ='0. Database'!D21 -> 50834 | D30: ='0. Database'!E21 -> 63708 | E30: ='0. Database'!F21 -> 79785 | F30: ='0. Database'!G21 -> 106110 | G30: ='0. Database'!H21 -> 141366 | H30: ='0. Database'!I21 -> 170773 | I30: ='0. Database'!J21 -> 236282 | ... S30: ='0. Database'!T21 -> 645470.67
A31: GOOGL | B31: ='0. Database'!C36 -> 55519 | C31: ='0. Database'!D36 -> 66001 | D31: ='0. Database'!E36 -> 74989 | E31: ='0. Database'!F36 -> 90272 | F31: ='0. Database'!G36 -> 110855 | G31: ='0. Database'!H36 -> 136819 | H31: ='0. Database'!I36 -> 161857 | I31: ='0. Database'!J36 -> 182527 | ... S31: ='0. Database'!T36 -> 941245.16
A32: META | B32: ='0. Database'!C53 -> 7872 | C32: ='0. Database'!D53 -> 12466 | D32: ='0. Database'!E53 -> 17928 | E32: ='0. Database'!F53 -> 27638 | F32: ='0. Database'!G53 -> 40653 | G32: ='0. Database'!H53 -> 55838 | H32: ='0. Database'!I53 -> 70196 | I32: ='0. Database'!J53 -> 84826 | ... S32: ='0. Database'!T53 -> 448874.02
A33: ORCL | B33: ='0. Database'!C71 -> 37180 | C33: ='0. Database'!D71 -> 38275 | D33: ='0. Database'!E71 -> 38226 | E33: ='0. Database'!F71 -> 37047 | F33: ='0. Database'!G71 -> 37728 | G33: ='0. Database'!H71 -> 39383 | H33: ='0. Database'!I71 -> 39506 | I33: ='0. Database'!J71 -> 39068 | ... S33: ='0. Database'!T71 -> 223941.18
A35: (NI)
A36: Company | B36: 2013A | C36: 2014A | D36: 2015A | E36: 2016A | F36: 2017A | G36: 2018A | H36: 2019A | I36: 2020A | J36: 2021A | K36: 2022A | L36: 2023A | M36: 2024A | N36: 2025E | O36: 2026E | P36: 2027E | Q36: 2028E | R36: 2029E | S36: 2030E
A37: MSFT | B37: ='0. Database'!C7 -> 21863 | C37: ='0. Database'!D7 -> 22074 | D37: ='0. Database'!E7 -> 12193 | E37: ='0. Database'!F7 -> 16798 | F37: ='0. Database'!G7 -> 21204 | G37: ='0. Database'!H7 -> 16571 | H37: ='0. Database'!I7 -> 39240 | I37: ='0. Database'!J7 -> 44281 | ... S37: ='0. Database'!T7 -> 231003.5
A38: AMZN | B38: ='0. Database'!C23 -> 274 | C38: ='0. Database'!D23 -> -241 | D38: ='0. Database'!E23 -> 596 | E38: ='0. Database'!F23 -> 2371 | F38: ='0. Database'!G23 -> 2244 | G38: ='0. Database'!H23 -> 10073 | H38: ='0. Database'!I23 -> 11588 | I38: ='0. Database'!J23 -> 21331 | ... S38: ='0. Database'!T23 -> 199614.81
A39: GOOGL | B39: ='0. Database'!C38 -> 12214 | C39: ='0. Database'!D38 -> 13928 | D39: ='0. Database'!E38 -> 15826 | E39: ='0. Database'!F38 -> 19478 | F39: ='0. Database'!G38 -> 22519 | G39: ='0. Database'!H38 -> 30736 | H39: ='0. Database'!I38 -> 32508 | I39: ='0. Database'!J38 -> 40269 | ... S39: ='0. Database'!T38 -> 322005.86
A40: META | B40: ='0. Database'!C55 -> 1491 | C40: ='0. Database'!D55 -> 2925 | D40: ='0. Database'!E55 -> 3669 | E40: ='0. Database'!F55 -> 10188 | F40: ='0. Database'!G55 -> 18190 | G40: ='0. Database'!H55 -> 22112 | H40: ='0. Database'!I55 -> 18485 | I40: ='0. Database'!J55 -> 29146 | ... S40: ='0. Database'!T55 -> 146055.1
A41: ORCL | B41: ='0. Database'!C73 -> 10926 | C41: ='0. Database'!D73 -> 10955 | D41: ='0. Database'!E73 -> 9938 | E41: ='0. Database'!F73 -> 8901 | F41: ='0. Database'!G73 -> 9335 | G41: ='0. Database'!H73 -> 3825 | H41: ='0. Database'!I73 -> 11083 | I41: ='0. Database'!J73 -> 10135 | ... S41: ='0. Database'!T73 -> 51960.267
A43: (Capex)
A44: Company | B44: 2013A | C44: 2014A | D44: 2015A | E44: 2016A | F44: 2017A | G44: 2018A | H44: 2019A | I44: 2020A | J44: 2021A | K44: 2022A | L44: 2023A | M44: 2024A | N44: 2025E | O44: 2026E | P44: 2027E | Q44: 2028E | R44: 2029E | S44: 2030E
A45: MSFT | B45: ='0. Database'!C12 -> 4257 | C45: ='0. Database'!D12 -> 5485 | D45: ='0. Database'!E12 -> 5944 | E45: ='0. Database'!F12 -> 8343 | F45: ='0. Database'!G12 -> 8129 | G45: ='0. Database'!H12 -> 11632 | H45: ='0. Database'!I12 -> 13925 | I45: ='0. Database'!J12 -> 15441 | ... S45: ='0. Database'!T12 -> 196810
A46: AMZN | B46: ='0. Database'!C28 -> 3444 | C46: ='0. Database'!D28 -> 4893 | D46: ='0. Database'!E28 -> 5387 | E46: ='0. Database'!F28 -> 7804 | F46: ='0. Database'!G28 -> 11955 | G46: ='0. Database'!H28 -> 13427 | H46: ='0. Database'!I28 -> 16861 | I46: ='0. Database'!J28 -> 40140 | ... S46: ='0. Database'!T28 -> 224350.56
...

Sheet 4. EPS & Margins
A1: EPS、Operating IncomeMargin&Profitability (2013-2030E)
A3: A. Operating Income ($mm)
A4: Company | B4: 2013A | C4: 2014A | D4: 2015A | E4: 2016A | F4: 2017A | G4: 2018A | H4: 2019A | I4: 2020A | J4: 2021A | K4: 2022A | L4: 2023A | M4: 2024A | N4: 2025E | O4: 2026E | P4: 2027E | Q4: 2028E | R4: 2029E | S4: 2030E
A5: MSFT | B5: ='0. Database'!C6 -> 26764 | C5: ='0. Database'!D6 -> 27759 | D5: ='0. Database'!E6 -> 13359 | E5: ='0. Database'!F6 -> 11756 | F5: ='0. Database'!G6 -> 11389 | G5: ='0. Database'!H6 -> 12924 | H5: ='0. Database'!I6 -> 16219 | I5: ='0. Database'!J6 -> 18724 | ... S5: ='0. Database'!T6 -> 108509.49
A6: AMZN | B6: ='0. Database'!C22 -> 673 | C6: ='0. Database'!D22 -> 458 | D6: ='0. Database'!E22 -> 1507 | E6: ='0. Database'!F22 -> 3108 | F6: ='0. Database'!G22 -> 4331 | G6: ='0. Database'!H22 -> 7296 | H6: ='0. Database'!I22 -> 9201 | I6: ='0. Database'!J22 -> 13531 | ... S6: ='0. Database'!T22 -> 152115.05
A7: GOOGL | B7: ='0. Database'!C37 -> 16260 | C7: ='0. Database'!D37 -> 18965 | D7: ='0. Database'!E37 -> 23319 | E7: ='0. Database'!F37 -> 27055 | F7: ='0. Database'!G37 -> 32456 | G7: ='0. Database'!H37 -> 43137 | H7: ='0. Database'!I37 -> 48999 | I7: ='0. Database'!J37 -> 54606 | ... S7: ='0. Database'!T37 -> 258679.36
A8: META | B8: ='0. Database'!C54 -> 2804 | C8: ='0. Database'!D54 -> 4994 | D8: ='0. Database'!E54 -> 6225 | E8: ='0. Database'!F54 -> 12427 | F8: ='0. Database'!G54 -> 20203 | G8: ='0. Database'!H54 -> 24913 | H8: ='0. Database'!I54 -> 23986 | I8: ='0. Database'!J54 -> 32671 | ... S8: ='0. Database'!T54 -> 162052.13
A9: ORCL | B9: ='0. Database'!C72 -> 14684 | C9: ='0. Database'!D72 -> 14758 | D9: ='0. Database'!E72 -> 13870 | E9: ='0. Database'!F72 -> 12604 | F9: ='0. Database'!G72 -> 12710 | G9: ='0. Database'!H72 -> 13264 | H9: ='0. Database'!I72 -> 13535 | I9: ='0. Database'!J72 -> 13897 | ... S9: ='0. Database'!T72 -> 57952.82
A11: C. Net Income ($mm)
A12: Company | B12: 2013A | C12: 2014A | D12: 2015A | E12: 2016A | F12: 2017A | G12: 2018A | H12: 2019A | I12: 2020A | J12: 2021A | K12: 2022A | L12: 2023A | M12: 2024A | N12: 2025E | O12: 2026E | P12: 2027E | Q12: 2028E | R12: 2029E | S12: 2030E
A13: MSFT | B13: ='0. Database'!C7 -> 21863 | C13: ='0. Database'!D7 -> 22074 | D13: ='0. Database'!E7 -> 12193 | E13: ='0. Database'!F7 -> 16798 | F13: ='0. Database'!G7 -> 21204 | G13: ='0. Database'!H7 -> 16571 | H13: ='0. Database'!I7 -> 39240 | I13: ='0. Database'!J7 -> 44281 | ... S13: ='0. Database'!T7 -> 231003.5
A14: AMZN | B14: ='0. Database'!C23 -> 274 | C14: ='0. Database'!D23 -> -241 | D14: ='0. Database'!E23 -> 596 | E14: ='0. Database'!F23 -> 2371 | F14: ='0. Database'!G23 -> 2244 | G14: ='0. Database'!H23 -> 10073 | H14: ='0. Database'!I23 -> 11588 | I14: ='0. Database'!J23 -> 21331 | ... S14: ='0. Database'!T23 -> 199614.81
A15: GOOGL | B15: ='0. Database'!C38 -> 12214 | C15: ='0. Database'!D38 -> 13928 | D15: ='0. Database'!E38 -> 15826 | E15: ='0. Database'!F38 -> 19478 | F15: ='0. Database'!G38 -> 22519 | G15: ='0. Database'!H38 -> 30736 | H15: ='0. Database'!I38 -> 32508 | I15: ='0. Database'!J38 -> 40269 | ... S15: ='0. Database'!T38 -> 322005.86
A16: META | B16: ='0. Database'!C55 -> 1491 | C16: ='0. Database'!D55 -> 2925 | D16: ='0. Database'!E55 -> 3669 | E16: ='0. Database'!F55 -> 10188 | F16: ='0. Database'!G55 -> 18190 | G16: ='0. Database'!H55 -> 22112 | H16: ='0. Database'!I55 -> 18485 | I16: ='0. Database'!J55 -> 29146 | ... S16: ='0. Database'!T55 -> 146055.1
A17: ORCL | B17: ='0. Database'!C73 -> 10926 | C17: ='0. Database'!D73 -> 10955 | D17: ='0. Database'!E73 -> 9938 | E17: ='0. Database'!F73 -> 8901 | F17: ='0. Database'!G73 -> 9335 | G17: ='0. Database'!H73 -> 3825 | H17: ='0. Database'!I73 -> 11083 | I17: ='0. Database'!J73 -> 10135 | ... S17: ='0. Database'!T73 -> 51960.267
A19: E. EPS ($)
A20: Company | B20: 2013A | C20: 2014A | D20: 2015A | E20: 2016A | F20: 2017A | G20: 2018A | H20: 2019A | I20: 2020A | J20: 2021A | K20: 2022A | L20: 2023A | M20: 2024A | N20: 2025E | O20: 2026E | P20: 2027E | Q20: 2028E | R20: 2029E | S20: 2030E
A21: MSFT | B21: ='0. Database'!C8 -> 2.58 | C21: ='0. Database'!D8 -> 2.63 | D21: ='0. Database'!E8 -> 1.48 | E21: ='0. Database'!F8 -> 2.1 | F21: ='0. Database'!G8 -> 2.71 | G21: ='0. Database'!H8 -> 2.13 | H21: ='0. Database'!I8 -> 5.06 | I21: ='0. Database'!J8 -> 5.76 | ... S21: ='0. Database'!T8 -> 31.4925
A22: AMZN | B22: ='0. Database'!C24 -> 0.0295 | C22: ='0. Database'!D24 -> -0.026 | D22: ='0. Database'!E24 -> 0.0625 | E22: ='0. Database'!F24 -> 0.245 | F22: ='0. Database'!G24 -> 0.2275 | G22: ='0. Database'!H24 -> 1.007 | H22: ='0. Database'!I24 -> 1.1505 | I22: ='0. Database'!J24 -> 2.0915 | ... S22: ='0. Database'!T24 -> 17.133333
A23: GOOGL | B23: ='0. Database'!C39 -> 0.90125 | C23: ='0. Database'!D39 -> 1.0135 | D23: ='0. Database'!E39 -> 1.142 | E23: ='0. Database'!F39 -> 1.3925 | F23: ='0. Database'!G39 -> 1.6005 | G23: ='0. Database'!H39 -> 2.185 | H23: ='0. Database'!I39 -> 2.3265 | I23: ='0. Database'!J39 -> 2.9305 | ... S23: ='0. Database'!T39 -> 26.035714
A24: META | B24: ='0. Database'!C56 -> 0.6 | C24: ='0. Database'!D56 -> 1.1 | D24: ='0. Database'!E56 -> 1.29 | E24: ='0. Database'!F56 -> 3.49 | F24: ='0. Database'!G56 -> 6.16 | G24: ='0. Database'!H56 -> 7.57 | H24: ='0. Database'!I56 -> 8.56 | I24: ='0. Database'!J56 -> 9.78 | ... S24: ='0. Database'!T56 -> 56.996875
A25: ORCL | B25: ='0. Database'!C74 -> 2.26 | C25: ='0. Database'!D74 -> 2.38 | D25: ='0. Database'!E74 -> 2.21 | E25: ='0. Database'!F74 -> 2.07 | F25: ='0. Database'!G74 -> 2.21 | G25: ='0. Database'!H74 -> 0.9 | H25: ='0. Database'!I74 -> 2.97 | I25: ='0. Database'!J74 -> 3.08 | ... S25: ='0. Database'!T74 -> 16.756
A27: G. Diluted Shares (mm)
A28: Company | B28: 2013A | C28: 2014A | D28: 2015A | E28: 2016A | F28: 2017A | G28: 2018A | H28: 2019A | I28: 2020A | J28: 2021A | K28: 2022A | L28: 2023A | M28: 2024A | N28: 2025E | O28: 2026E | P28: 2027E | Q28: 2028E | R28: 2029E | S28: 2030E
A29: MSFT | B29: ='0. Database'!C9 -> 8470 | C29: ='0. Database'!D9 -> 8399 | D29: ='0. Database'!E9 -> 8254 | E29: ='0. Database'!F9 -> 8013 | F29: ='0. Database'!G9 -> 7832 | G29: ='0. Database'!H9 -> 7794 | H29: ='0. Database'!I9 -> 7753 | I29: ='0. Database'!J9 -> 7683 | ... S29: ='0. Database'!T9 -> 7366.4511
A30: AMZN | B30: ='0. Database'!C25 -> 9300 | C30: ='0. Database'!D25 -> 9240 | D30: ='0. Database'!E25 -> 9540 | E30: ='0. Database'!F25 -> 9680 | F30: ='0. Database'!G25 -> 9860 | G30: ='0. Database'!H25 -> 10000 | H30: ='0. Database'!I25 -> 10080 | I30: ='0. Database'!J25 -> 10200 | ... S30: ='0. Database'!T25 -> 11236.528
A31: GOOGL | B31: ='0. Database'!C40 -> 14739.044 | C31: ='0. Database'!D40 -> 14839.96 | D31: ='0. Database'!E40 -> 14893.5 | E31: ='0. Database'!F40 -> 14951.3 | F31: ='0. Database'!G40 -> 15014.6 | G31: ='0. Database'!H40 -> 15002.98 | H31: ='0. Database'!I40 -> 14901.66 | I31: ='0. Database'!J40 -> 14664.2 | ... S31: ='0. Database'!T40 -> 12302.528
A32: META | B32: ='0. Database'!C57 -> 2517 | C32: ='0. Database'!D57 -> 2664 | D32: ='0. Database'!E57 -> 2853 | E32: ='0. Database'!F57 -> 2925 | F32: ='0. Database'!G57 -> 2956 | G32: ='0. Database'!H57 -> 2921 | H32: ='0. Database'!I57 -> 2876 | I32: ='0. Database'!J57 -> 2888 | ... S32: ='0. Database'!T57 -> 2611.4238
A33: ORCL | B33: ='0. Database'!C75 -> 4844 | C33: ='0. Database'!D75 -> 4604 | D33: ='0. Database'!E75 -> 4503 | E33: ='0. Database'!F75 -> 4305 | F33: ='0. Database'!G75 -> 4217 | G33: ='0. Database'!H75 -> 4238 | H33: ='0. Database'!I75 -> 3732 | I33: ='0. Database'!J75 -> 3294 | ... S33: ='0. Database'!T75 -> 3102.7389
A35: H. SBC ($mm)
A36: Company | B36: 2013A | C36: 2014A | D36: 2015A | E36: 2016A | F36: 2017A | G36: 2018A | H36: 2019A | I36: 2020A | J36: 2021A | K36: 2022A | L36: 2023A | M36: 2024A | N36: 2025E | O36: 2026E | P36: 2027E | Q36: 2028E | R36: 2029E | S36: 2030E
A37: MSFT | B37: ='0. Database'!C10 -> 2197 | C37: ='0. Database'!D10 -> 2446 | D37: ='0. Database'!E10 -> 2574 | E37: ='0. Database'!F10 -> 2668 | F37: ='0. Database'!G10 -> 3266 | G37: ='0. Database'!H10 -> 3940 | H37: ='0. Database'!I10 -> 4652 | I37: ='0. Database'!J10 -> 5289 | ... S37: ='0. Database'!T10 -> 21162.66
A38: AMZN | B38: ='0. Database'!C26 -> 1056 | C38: ='0. Database'!D26 -> 1491 | D38: ='0. Database'!E26 -> 2119 | E38: ='0. Database'!F26 -> 2975 | F38: ='0. Database'!G26 -> 4215 | G38: ='0. Database'!H26 -> 5418 | H38: ='0. Database'!I26 -> 6864 | I38: ='0. Database'!J26 -> 9208 | ... S38: ='0. Database'!T26 -> 31047.394
A39: GOOGL | B39: ='0. Database'!C41 -> -3268 | C39: ='0. Database'!D41 -> -4175 | D39: ='0. Database'!E41 -> -4903 | E39: ='0. Database'!F41 -> -6703 | F39: ='0. Database'!G41 -> -7679 | G39: ='0. Database'!H41 -> -9353 | H39: ='0. Database'!I41 -> -10794 | I39: ='0. Database'!J41 -> -12991 | ... S39: ='0. Database'!T41 -> -35339.95
A40: META | B40: ='0. Database'!C58 -> -906 | C40: ='0. Database'!D58 -> -1837 | D40: ='0. Database'!E58 -> -2969 | E40: ='0. Database'!F58 -> -3202 | F40: ='0. Database'!G58 -> -3723 | G40: ='0. Database'!H58 -> -4152 | H40: ='0. Database'!I58 -> -4835 | I40: ='0. Database'!J58 -> -6536 | ... S40: ='0. Database'!T58 -> -28834.48
A41: ORCL | B41: ='0. Database'!C76 -> 755 | C41: ='0. Database'!D76 -> 805 | D41: ='0. Database'!E76 -> 933 | E41: ='0. Database'!F76 -> 1037 | F41: ='0. Database'!G76 -> 1350 | G41: ='0. Database'!H76 -> 1607 | H41: ='0. Database'!I76 -> 1653 | I41: ='0. Database'!J76 -> 1590 | ... S41: ='0. Database'!T76 -> 11212.32
A43: (Revenue)
A44: Company | B44: 2013A | C44: 2014A | D44: 2015A | E44: 2016A | F44: 2017A | G44: 2018A | H44: 2019A | I44: 2020A | J44: 2021A | K44: 2022A | L44: 2023A | M44: 2024A | N44: 2025E | O44: 2026E | P44: 2027E | Q44: 2028E | R44: 2029E | S44: 2030E
A45: MSFT | B45: ='0. Database'!C5 -> 77849 | C45: ='0. Database'!D5 -> 86833 | D45: ='0. Database'!E5 -> 93580 | E45: ='0. Database'!F5 -> 91154 | F45: ='0. Database'!G5 -> 96571 | G45: ='0. Database'!H5 -> 110360 | H45: ='0. Database'!I5 -> 125843 | I45: ='0. Database'!J5 -> 143015 | ... S45: ='0. Database'!T5 -> 628544.33
A46: AMZN | B46: ='0. Database'!C21 -> 41410 | C46: ='0. Database'!D21 -> 50834 | D46: ='0. Database'!E21 -> 63708 | E46: ='0. Database'!F21 -> 79785 | F46: ='0. Database'!G21 -> 106110 | G46: ='0. Database'!H21 -> 141366 | H46: ='0. Database'!I21 -> 170773 | I46: ='0. Database'!J21 -> 236282 | ... S46: ='0. Database'!T21 -> 645470.67
...

Sheet 5. Depreciation Sensitivity
A1: Depreciation Sensitivity: IT Useful Life Compression Impact on EPS
A4: A. IT Equipment Share Estimation: MSFT Hard Data + Other Companies from 10-K Filings
A5: Company | B5: IT Equipment % of PP&E | C5: Estimation Basis (Source) | D5: IT Useful Life (yr) | E5: Buildings % of PP&E | F5: Building Life (yr) | G5: Other % of PP&E | H5: Other Life (yr)
A6: MSFT | B6: 0.59 | C6: 10-K/Model: IT equip = 59% of capex (FY2026E). Useful life: 6yr SL. | D6: 6 | E6: 0.34 | F6: 15 | G6: 0.07 | H6: 10
A7: AMZN | B7: 0.37 | C7: 10-K Note 3 (CY2025): Servers & networking $172B / $462B in-service (ex-CIP) = 37%. Heavy equip (logistics) = 14%. Life: 5-6yr. | D7: 5.5 | E7: 0.34 | F7: 30 | G7: 0.29 | H7: 8
A8: GOOGL | B8: 0.46 | C8: 10-K: Tech infra $203.7B / $266.5B in-service = 76%. 60% of tech infra = servers. → 76%×60% = 46% of total PP&E. | D8: 6 | E8: 0.31 | F8: 30 | G8: 0.23 | H8: 10
A9: META | B9: 0.54 | C9: 10-K Note 6 (Q1'26): Servers $106B / $195B in-service (ex-CIP) = 54%. Life: 5-5.5yr. Server D&A = 74% of total. | D9: 5.5 | E9: 0.3 | F9: 27 | G9: 0.16 | H9: 10
A10: ORCL | B10: 0.71 | C10: 10-K Note 5: Computer/network $30.3B/$42.9B ex-CIP = 71%. 10-Q: PP&E net doubled to $83.6B in 9mo. Capex 9mo=$39.2B. | D10: 5 | E10: 0.25 | F10: 25 | G10: 0.01 | H10: 10
A13: B. 2026E Base Data (from Database) + Gross PP&E (from 10-K filings)
A14: Company | B14: 2026E Capex ($mm) | C14: 2026E D&A ($mm) | D14: 2026E NI ($mm) | E14: 2026E EPS ($) | F14: Shares (mm) | G14: Tax Rate (Editable) | H14: 2026E Gross PP&E ($mm, Bloomberg) | I14: Current IT Life (yr) | J14: IT Share of D&A | K14: 2027E NI ($mm) | L14: 2027E EPS ($)
A15: MSFT | B15: ='0. Database'!P12 -> 117213.77 | C15: ='0. Database'!P11 -> 42005.109 | D15: ='0. Database'!P7 -> 128773.53 | E15: ='0. Database'!P8 -> 17.280667 | F15: ='0. Database'!P9 -> 7449.9017 | G15: 0.18 | H15: 439440 | I15: 6 | J15: 0.69 | K15: ='0. Database'!Q7 -> 144093.73 | L15: ='0. Database'!Q8 -> 19.417143
A16: AMZN | B16: ='0. Database'!P28 -> 199073.7 | C16: ='0. Database'!P27 -> 84391.581 | D16: ='0. Database'!P23 -> 95381.37 | E16: ='0. Database'!P24 -> 8.7931915 | F16: ='0. Database'!P25 -> 10899.309 | G16: 0.2 | H16: 732526 | I16: 5.5 | J16: 0.61 | K16: ='0. Database'!Q23 -> 109556.18 | L16: ='0. Database'!Q24 -> 10.028182
A17: GOOGL | B17: ='0. Database'!P43 -> 186454.02 | C17: ='0. Database'!P42 -> 42874.7 | D17: ='0. Database'!P38 -> 174612.84 | E17: ='0. Database'!P39 -> 14.186724 | F17: ='0. Database'!P40 -> 12208.564 | G17: 0.16 | H17: 380000 | I17: 6 | J17: 0.7 | K17: ='0. Database'!Q38 -> 180090.27 | L17: ='0. Database'!Q39 -> 14.69
A18: META | B18: ='0. Database'!P60 -> 134391.33 | C18: ='0. Database'!P59 -> 29596.548 | D18: ='0. Database'!P55 -> 83760.967 | E18: ='0. Database'!P56 -> 32.200161 | F18: ='0. Database'!P57 -> 2561.9327 | G18: 0.13 | H18: 361870 | I18: 5.25 | J18: 0.8 | K18: ='0. Database'!Q55 -> 89664.31 | L18: ='0. Database'!Q56 -> 34.904068
A19: ORCL | B19: ='0. Database'!P78 -> 50345.517 | C19: ='0. Database'!P77 -> 9142.317 | D19: ='0. Database'!P73 -> 17201.059 | E19: ='0. Database'!P87 -> 5.8483871 | F19: ='0. Database'!P75 -> 2920.2401 | G19: 0.2 | H19: 118000 | I19: 5 | J19: 0.92 | K19: ='0. Database'!Q73 -> 18923.588 | L19: ='0. Database'!Q74 -> 6.26125
A22: C. Core Sensitivity: Compress IT Equipment Useful Life (Buildings/Other Unchanged)
A23: New D&A = Gross PP&E × IT% / new_life + Gross PP&E × Bldg% / bldg_life + Gross PP&E × Other% / other_life. Delta vs current D&A flows through to NI and EPS.
A24: IT Equipment Life = 6 Years (Buildings/Other Unchanged)
A25: Company | B25: IT New D&A ($mm) | C25: Building D&A ($mm) | D25: New Total D&A ($mm) | E25: Current D&A ($mm) | F25: Delta D&A ($mm) | G25: Delta After-Tax ($mm) | H25: Adj NI ($mm) | I25: Adj EPS ($) | J25: EPS Change %
A26: MSFT | B26: =$C$15*$J$15*($I$15/6) -> 28983.525 | C26: =$C$15*(1-$J$15) -> 13021.584 | D26: =B26+C26 -> 42005.109 | E26: =$C$15 -> 42005.109 | F26: =D26-E26 -> 0 | G26: =F26*(1-$G$15) -> 0 | H26: =$D$15-G26 -> 128773.53 | I26: =H26/$F$15 -> 17.285266 | J26: =IFERROR(I26/$E$15-1,"") -> 0.00026613226
A27: AMZN | B27: =$C$16*$J$16*($I$16/6) -> 47188.959 | C27: =$C$16*(1-$J$16) -> 32912.716 | D27: =B27+C27 -> 80101.675 | E27: =$C$16 -> 84391.581 | F27: =D27-E27 -> -4289.9053 | G27: =F27*(1-$G$16) -> -3431.9243 | H27: =$D$16-G27 -> 98813.294 | I27: =H27/$F$16 -> 9.0660143 | J27: =IFERROR(I27/$E$16-1,"") -> 0.031026598
A28: GOOGL | B28: =$C$17*$J$17*($I$17/6) -> 30012.29 | C28: =$C$17*(1-$J$17) -> 12862.41 | D28: =B28+C28 -> 42874.7 | E28: =$C$17 -> 42874.7 | F28: =D28-E28 -> 0 | G28: =F28*(1-$G$17) -> 0 | H28: =$D$17-G28 -> 174612.84 | I28: =H28/$F$17 -> 14.302488 | J28: =IFERROR(I28/$E$17-1,"") -> 0.0081600075
A29: META | B29: =$C$18*$J$18*($I$18/6) -> 20717.583 | C29: =$C$18*(1-$J$18) -> 5919.3095 | D29: =B29+C29 -> 26636.893 | E29: =$C$18 -> 29596.548 | F29: =D29-E29 -> -2959.6548 | G29: =F29*(1-$G$18) -> -2574.8996 | H29: =$D$18-G29 -> 86335.867 | I29: =H29/$F$18 -> 33.699506 | J29: =IFERROR(I29/$E$18-1,"") -> 0.04656326
A30: ORCL | B30: =$C$19*$J$19*($I$19/6) -> 7009.1097 | C30: =$C$19*(1-$J$19) -> 731.38536 | D30: =B30+C30 -> 7740.4951 | E30: =$C$19 -> 9142.317 | F30: =D30-E30 -> -1401.8219 | G30: =F30*(1-$G$19) -> -1121.4576 | H30: =$D$19-G30 -> 18322.516 | I30: =H30/$F$19 -> 6.2743184 | J30: =IFERROR(I30/$E$19-1,"") -> 0.072828854
A32: IT Equipment Life = 5 Years (Buildings/Other Unchanged)
A33: Company | B33: IT New D&A ($mm) | C33: Building D&A ($mm) | D33: New Total D&A ($mm) | E33: Current D&A ($mm) | F33: Delta D&A ($mm) | G33: Delta After-Tax ($mm) | H33: Adj NI ($mm) | I33: Adj EPS ($) | J33: EPS Change %
A34: MSFT | B34: =$C$15*$J$15*($I$15/5) -> 34780.23 | C34: =$C$15*(1-$J$15) -> 13021.584 | D34: =B34+C34 -> 47801.814 | E34: =$C$15 -> 42005.109 | F34: =D34-E34 -> 5796.705 | G34: =F34*(1-$G$15) -> 4753.2981 | H34: =$D$15-G34 -> 124020.23 | I34: =H34/$F$15 -> 16.647231 | J34: =IFERROR(I34/$E$15-1,"") -> -0.036655766
A35: AMZN | B35: =$C$16*$J$16*($I$16/5) -> 56626.751 | C35: =$C$16*(1-$J$16) -> 32912.716 | D35: =B35+C35 -> 89539.467 | E35: =$C$16 -> 84391.581 | F35: =D35-E35 -> 5147.8864 | G35: =F35*(1-$G$16) -> 4118.3091 | H35: =$D$16-G35 -> 91263.06 | I35: =H35/$F$16 -> 8.3732884 | J35: =IFERROR(I35/$E$16-1,"") -> -0.047753201
A36: GOOGL | B36: =$C$17*$J$17*($I$17/5) -> 36014.748 | C36: =$C$17*(1-$J$17) -> 12862.41 | D36: =B36+C36 -> 48877.158 | E36: =$C$17 -> 42874.7 | F36: =D36-E36 -> 6002.458 | G36: =F36*(1-$G$17) -> 5042.0647 | H36: =$D$17-G36 -> 169570.78 | I36: =H36/$F$17 -> 13.889494 | J36: =IFERROR(I36/$E$17-1,"") -> -0.020951299
A37: META | B37: =$C$18*$J$18*($I$18/5) -> 24861.1 | C37: =$C$18*(1-$J$18) -> 5919.3095 | D37: =B37+C37 -> 30780.409 | E37: =$C$18 -> 29596.548 | F37: =D37-E37 -> 1183.8619 | G37: =F37*(1-$G$18) -> 1029.9599 | H37: =$D$18-G37 -> 82731.007 | I37: =H37/$F$18 -> 32.29242 | J37: =IFERROR(I37/$E$18-1,"") -> 0.0028651577
A38: ORCL | B38: =$C$19*$J$19*($I$19/5) -> 8410.9317 | C38: =$C$19*(1-$J$19) -> 731.38536 | D38: =B38+C38 -> 9142.317 | E38: =$C$19 -> 9142.317 | F38: =D38-E38 -> 0 | G38: =F38*(1-$G$19) -> 0 | H38: =$D$19-G38 -> 17201.059 | I38: =H38/$F$19 -> 5.8902892 | J38: =IFERROR(I38/$E$19-1,"") -> 0.0071647282
A40: IT Equipment Life = 4 Years (Buildings/Other Unchanged)
A41: Company | B41: IT New D&A ($mm) | C41: Building D&A ($mm) | D41: New Total D&A ($mm) | E41: Current D&A ($mm) | F41: Delta D&A ($mm) | G41: Delta After-Tax ($mm) | H41: Adj NI ($mm) | I41: Adj EPS ($) | J41: EPS Change %
A42: MSFT | B42: =$C$15*$J$15*($I$15/4) -> 43475.288 | C42: =$C$15*(1-$J$15) -> 13021.584 | D42: =B42+C42 -> 56496.872 | E42: =$C$15 -> 42005.109 | F42: =D42-E42 -> 14491.763 | G42: =F42*(1-$G$15) -> 11883.245 | H42: =$D$15-G42 -> 116890.28 | I42: =H42/$F$15 -> 15.690178 | J42: =IFERROR(I42/$E$15-1,"") -> -0.092038613
A43: AMZN | B43: =$C$16*$J$16*($I$16/4) -> 70783.438 | C43: =$C$16*(1-$J$16) -> 32912.716 | D43: =B43+C43 -> 103696.15 | E43: =$C$16 -> 84391.581 | F43: =D43-E43 -> 19304.574 | G43: =F43*(1-$G$16) -> 15443.659 | H43: =$D$16-G43 -> 79937.71 | I43: =H43/$F$16 -> 7.3341997 | J43: =IFERROR(I43/$E$16-1,"") -> -0.1659229
A44: GOOGL | B44: =$C$17*$J$17*($I$17/4) -> 45018.435 | C44: =$C$17*(1-$J$17) -> 12862.41 | D44: =B44+C44 -> 57880.845 | E44: =$C$17 -> 42874.7 | F44: =D44-E44 -> 15006.145 | G44: =F44*(1-$G$17) -> 12605.162 | H44: =$D$17-G44 -> 162007.68 | I44: =H44/$F$17 -> 13.270003 | J44: =IFERROR(I44/$E$17-1,"") -> -0.064618259
A45: META | B45: =$C$18*$J$18*($I$18/4) -> 31076.375 | C45: =$C$18*(1-$J$18) -> 5919.3095 | D45: =B45+C45 -> 36995.684 | E45: =$C$18 -> 29596.548 | F45: =D45-E45 -> 7399.1369 | G45: =F45*(1-$G$18) -> 6437.2491 | H45: =$D$18-G45 -> 77323.718 | I45: =H45/$F$18 -> 30.181791 | J45: =IFERROR(I45/$E$18-1,"") -> -0.062681995
A46: ORCL | B46: =$C$19*$J$19*($I$19/4) -> 10513.665 | C46: =$C$19*(1-$J$19) -> 731.38536 | D46: =B46+C46 -> 11245.05 | E46: =$C$19 -> 9142.317 | F46: =D46-E46 -> 2102.7329 | G46: =F46*(1-$G$19) -> 1682.1863 | H46: =$D$19-G46 -> 15518.872 | I46: =H46/$F$19 -> 5.3142454 | J46: =IFERROR(I46/$E$19-1,"") -> -0.091331461
A48: IT Equipment Life = 3 Years (Buildings/Other Unchanged)
A49: Company | B49: IT New D&A ($mm) | C49: Building D&A ($mm) | D49: New Total D&A ($mm) | E49: Current D&A ($mm) | F49: Delta D&A ($mm) | G49: Delta After-Tax ($mm) | H49: Adj NI ($mm) | I49: Adj EPS ($) | J49: EPS Change %
...

Sheet IT_DA_Share_Derivation
A1: IT D&A Share Derivation
A2: Step-by-step calculation of 'IT Share of D&A' used in Sheet 5 sensitivity analysis
A4: METHODOLOGY:
A5: Step 1: Get Gross PP&E by category from 10-K Note (Property and Equipment)
A6: Step 2: Apply mid-point useful life to each category to get 'implied annual D&A'
A7: Step 3: Sum to get total implied D&A
A8: Step 4: Compare to reported total D&A; compute scale factor (typically 0.7-0.9, accounts for fully-depreciated assets)
A9: Step 5: Apply scale factor uniformly to all categories to match reported D&A
A10: Step 6: IT Share of D&A = (Scaled IT D&A) / (Reported Total D&A)
A13: AMZN — FY2025 (Dec 2025)
A14: Source: 10-K Note 3, Property and Equipment
A16: Category | B16: Gross PP&E ($M) | C16: Useful Life (yr) | D16: Implied D&A ($M) | E16: Step 2 Notes
A17: Land and Buildings (ex-land 15%) | B17: 131852.85 | C17: 35 | D17: =B17/C17 -> 3767.2243 | E17: Buildings 40yr per 10-K; assume 15% is land (non-depreciable)
A18: Servers and Networking [IT] | B18: 172492 | C18: 5.5 | D18: =B18/C18 -> 31362.182 | E18: 5-6 yr per 10-K; mid-point 5.5yr
A19: Heavy Equipment (logistics) | B19: 65545 | C19: 11.5 | D19: =B19/C19 -> 5699.5652 | E19: 10-13 yr per 10-K; mid-point 11.5yr
A20: Other Equipment | B20: 63376 | C20: 6.5 | D20: =B20/C20 -> 9750.1538 | E20: 3-10 yr range; mid-point 6.5yr
A21: Other Assets | B21: 5819 | C21: 7 | D21: =B21/C21 -> 831.28571 | E21: Misc internal-use, ~7yr
A22: Total Implied D&A | D22: =SUM(D17:D21) -> 51410.411
A23: Reported D&A (Bloomberg) | D23: 41900
A24: Scale Factor = Reported / Implied | D24: =D23/D22 -> 0.81501002
A25: Scaled IT D&A = Implied IT × Scale | D25: =D18*D24 -> 25560.492
A26: → IT Share of D&A = Scaled IT / Reported | D26: =D25/D23 -> 0.61003562
A31: GOOGL — FY2024 (Dec 2024)
A32: Source: 10-K — Information Technology Assets disclosure (not as granular as AMZN)
A34: Category | B34: Gross PP&E ($M) | C34: Useful Life (yr) | D34: Implied D&A ($M) | E34: Step 2 Notes
A35: Information Technology Assets | B35: 203700 | E35: Disclosed as single line; includes servers + DC buildings + cabling
A36: ↳ Estimated IT servers/networking [IT] | B36: 122220 | C36: 6 | D36: =B36/C36 -> 20370 | E36: 60% of IT assets are servers (est from earnings commentary); 6yr life
A37: ↳ Estimated DC buildings + other | B37: 81480 | C37: 25 | D37: =B37/C37 -> 3259.2 | E37: 40% is DC buildings + cabling; 25yr life (this is an assumptions)
A38: Land and Buildings (office) | B38: 33000 | C38: 28 | D38: =B38/C38 -> 1178.5714 | E38: 28yr blended for office buildings
A39: Other | B39: 29800 | C39: 7 | D39: =B39/C39 -> 4257.1429 | E39: Office equipment etc
